Workbook

Sheet Varsayımlar
B3: Birleştir | C3: Firma | D3: GTIN Kodu | E3: PRODUCT NAME / ÜRÜN ADI | F3: AMBALAJ | G3: CİNSİ | H3: Koli İçi | I3: ÇAP | J3: FORMÜL | K3: PAKET İÇİ | L3: KOLİ İÇİ | M3: PAKET GRAMAJI | N3: TARİH | O3: SKT/AY | P3: KOLİ / TARİH | Q3: AÇIKLAMALAR | R3: PALET KOLİ SAYISI | S3: PALET ÖLÇÜ | T3: AMBALAJ ETİKETİ
B4: =IF(C4="","",CONCATENATE(C4,E4)) -> LLC TRİTONMUTLUKAL WHEAT TORTILLA | C4: LLC TRİTON | D4: 8698829380698 | E4: MUTLUKAL WHEAT TORTILLA | F4: TORTİLLAS 25 CM 4 PCS 260G | G4: SADE | H4: 30 | I4: 25 | J4: SOFT | K4: 4 | L4: 30 | M4: 260 | N4: YURTDIŞI | O4: 6 | P4: TRİTON -SKT ATILACAK | Q4: 24-26 CM | R4: 84
B5: =IF(C5="","",CONCATENATE(C5,E5)) -> GERMESHANAMİ GERMES 25CM SADE 250G | C5: GERMES | D5: 8698829380698 | E5: HANAMİ GERMES 25CM SADE 250G | F5: HANAMİ 25 CM SADE (081) | G5: SADE | H5: 30 | I5: 25 | J5: IRAK SOFT | K5: 4 | L5: 30 | M5: 250 | N5: YURTDIŞI | O5: 9 | P5: HANAMİ MAVİ - ÜRETİM ATILACAK | Q5: 24-26 CM | R5: 84 | T5: Ambalaj kaç aylık kontrol?
B6: =IF(C6="","",CONCATENATE(C6,E6)) -> GERMESKırmızı Tortillas-Germes-25cm 375g | C6: GERMES | D6: 8698829380698 | E6: Kırmızı Tortillas-Germes-25cm 375g | F6: KIRMIZI TORTİLLAS 25 CM | G6: SADE | H6: 18 | I6: 25 | J6: IRAK SOFT | K6: 6 | L6: 18 | M6: 375 | N6: YURTDIŞI | O6: 9 | P6: KIRMIZI - ÜRETİM TARİHLİ ETİKET | Q6: 24-26 CM | R6: 84 | T6: BARKOD ETİKETİ
B7: =IF(C7="","",CONCATENATE(C7,E7)) -> LLC KOTORMANETKA PEYNİRLİ 25CM | C7: LLC KOTOR | D7: 8698829380698 | E7: MANETKA PEYNİRLİ 25CM | F7: MANETKA PEYNİRLİ 25 CM | G7: PEYNİRLİ | H7: 30 | I7: 25 | J7: SOFT-AT | K7: 4 | L7: 30 | M7: 250 | N7: YURTDIŞI | O7: 6 | P7: KIRMIZI KOLİ-TARİHLİ KOLİ ETİKETİ | Q7: 24-26 CM | R7: 78
B8: =IF(C8="","",CONCATENATE(C8,E8)) -> MAGNİTMAGNİT MAVİ AMBALAJ 25 CM 260G | C8: MAGNİT | D8: 8698829380698 | E8: MAGNİT MAVİ AMBALAJ 25 CM 260G | F8: MAGNİT MAVİ AMBALAJ 25CM | G8: SADE | H8: 30 | I8: 25 | J8: SOFT | K8: 4 | L8: 30 | M8: 260 | N8: YURTDIŞI | O8: 9 | P8: 25CM TURUNCU KOLİ-SOL ÜST DİKDÖRTGENE ÜRETİM TARİHİ BASILACAK | Q8: 24-26 CM | R8: 84
B9: =IF(C9="","",CONCATENATE(C9,E9)) -> GERMESHANAMİ PEYNİRLİ 25 CM 250G | C9: GERMES | D9: 8698829380698 | E9: HANAMİ PEYNİRLİ 25 CM 250G | F9: HANAMİ PEYNİRLİ 25CM AMBALAJ (098) | G9: PEYNİRLİ | H9: 30 | I9: 25 | J9: IRAK SOFT-AT | K9: 4 | L9: 30 | M9: 250 | N9: YURTDIŞI | O9: 9 | P9: HANAMİ SARI KOLİ-ÜRETİM TARİHİ BASILACAK | Q9: 24-26 CM | R9: 84 | T9: Ambalaj kaç aylık kontrol?
B10: =IF(C10="","",CONCATENATE(C10,E10)) -> SMART LLCTORTİLLAS SAMAKAT 20CM 166G | C10: SMART LLC | D10: 8698829380698 | E10: TORTİLLAS SAMAKAT 20CM 166G | F10: TORTİLLAS 20CM (SAMAKAT BİLGİLERİ EKLİ) | G10: SADE | H10: 14 | I10: 20 | J10: IRAK SOFT | K10: 4 | L10: 14 | M10: 166 | N10: YURTDIŞI | O10: 9 | P10: SİYAH KARE KOLİ- Üretim Tarihi Etiketli | Q10: 19-21 CM | R10: 225
B11: =IF(C11="","",CONCATENATE(C11,E11)) -> LLC KOTORMANETKA SADE 20CM 166G | C11: LLC KOTOR | D11: 8698829380698 | E11: MANETKA SADE 20CM 166G | F11: MANETKA SADE 20CM 166G | G11: SADE | H11: 14 | I11: 20 | J11: IRAK SOFT | K11: 4 | L11: 14 | M11: 166 | N11: YURTDIŞI | O11: 6 | P11: SİYAH KARE KOLİ-ÜRETİM TARİHLİ ETİKET | Q11: 19-21 CM | R11: 225
B12: =IF(C12="","",CONCATENATE(C12,E12)) -> Maydonoz DönerMutlukal Tortillas 15cm 250g | C12: Maydonoz Döner | D12: 8698829380698 | E12: Mutlukal Tortillas 15cm 250g | F12: Mutlukal Tortillas 15cm | G12: SADE | H12: 10 | I12: 12 | J12: IRAK SOFT | K12: 10 | L12: 12 | M12: 250 | N12: YURTİÇİ | O12: 6 | P12: 15CM KOLİ | Q12: KESME-33-35G BEZE, KESİLMEMİŞ 16-18CM, 320-330G- KESİLMİŞ 245-250G | R12: 96
B13: =IF(C13="","",CONCATENATE(C13,E13)) -> Şok MarketTaco 15 cm 6 lı 150 g | C13: Şok Market | D13: 8698829380698 | E13: Taco 15 cm 6 lı 150 g | F13: Taco 15 cm | G13: SADE | H13: 18 | I13: 15 | J13: SOFT-PA3 | K13: 6 | L13: 18 | M13: 250 | N13: YURTİÇİ | O13: 6 | P13: 15 CM KOLİ | Q13: 14-16 CM | R13: 60
B14: =IF(C14="","",CONCATENATE(C14,E14)) -> Aylin KartonHappylla 25 cm 10 lu 650g | C14: Aylin Karton | D14: 8698829380698 | E14: Happylla 25 cm 10 lu 650g | F14: Happylla 25cm (060) | G14: SADE | H14: 12 | I14: 25 | J14: Irak soft | K14: 10 | L14: 12 | M14: 650 | N14: Yurtiçi | O14: 6 | P14: Kırmızı Koli-Etiketli | Q14: 24-26 cm | R14: 50
B15: =IF(C15="","",CONCATENATE(C15,E15)) -> SMART LLCKırmızı tortillas 25cm 4 lü 250g | C15: SMART LLC | D15: 8698829380698 | E15: Kırmızı tortillas 25cm 4 lü 250g | F15: Kırmızı Tortillas 25 cm | G15: SADE | H15: 30 | I15: 25 | J15: Soft | K15: 4 | L15: 30 | M15: 250 | N15: Yurtdışı | O15: 9 | P15: Kırmızı Koli- Üretim Tarihi Etiketli | Q15: 24-26 CM | R15: 84
B16: =IF(C16="","",CONCATENATE(C16,E16)) -> Şok MarketBisto 25 cm 12 pcs 840g | C16: Şok Market | D16: 8698829380698 | E16: Bisto 25 cm 12 pcs 840g | F16: Bisto 25 cm | G16: SADE | H16: 12 | I16: 25 | J16: Standart | K16: 12 | L16: 12 | M16: 840 | N16: Yurtiçi | O16: 6 | P16: Bisto Kolisi | Q16: 24-26 Cm | R16: 48
B17: =IF(C17="","",CONCATENATE(C17,E17)) -> A101Nimet 25cm 12 pcs 840g | C17: A101 | D17: 8698829380698 | E17: Nimet 25cm 12 pcs 840g | F17: Nimet 25 cm | G17: SADE | H17: 12 | I17: 25 | J17: Standart | K17: 12 | L17: 12 | M17: 840 | N17: YURTİÇİ | O17: 5 | P17: Nimet Kolisi | Q17: 24-26 CM | R17: 50
B18: =IF(C18="","",CONCATENATE(C18,E18)) -> SultanoğluTortillove 25 cm 8pcs 520g | C18: Sultanoğlu | D18: 8698829380698 | E18: Tortillove 25 cm 8pcs 520g | F18: Tortillove 25 cm | G18: SADE | H18: 14 | I18: 25 | J18: Irak Soft | K18: 8 | L18: 14 | M18: 520 | N18: YURTİÇİ | O18: 6 | P18: Kırmızı Koli | Q18: 24-26 cm
B19: =IF(C19="","",CONCATENATE(C19,E19)) -> KopuzMutlukal Tortillas 30cm 950g | C19: Kopuz | D19: 8698829380698 | E19: Mutlukal Tortillas 30cm 950g | F19: Mutlukal tortillas 30cm | G19: SADE | H19: 12 | I19: 30 | J19: Irak Soft | K19: 10 | L19: 12 | M19: 950 | N19: Yurtiçi | O19: 6 | P19: Mavi Koli | Q19: 29-31 Cm
B20: =IF(C20="","",CONCATENATE(C20,E20)) -> GERMESHanami 20cm sade 4pcs 166g | C20: GERMES | D20: 8698829380698 | E20: Hanami 20cm sade 4pcs 166g | F20: Hanami 20cm Sade 4 pcs 166g (067) | G20: SADE | H20: 30 | I20: 20 | J20: Irak Soft | K20: 4 | L20: 30 | M20: 166 | N20: Yurtdışı | O20: 9 | P20: Hanami Mavi Koli -Üretim Tarihi+9 AYI KAPATACAK ETİKETLİ | Q20: 19-21 cm | R20: 140 | T20: Ambalaj kaç aylık kontrol?
B21: =IF(C21="","",CONCATENATE(C21,E21)) -> GERMESTortillas 20cm 4 lü 166g | C21: GERMES | D21: 8698829380698 | E21: Tortillas 20cm 4 lü 166g | F21: Tortillas 20cm (Etiketli) | G21: SADE | H21: 30 | I21: 20 | J21: Irak soft | K21: 4 | L21: 30 | M21: 166 | N21: Yurtdışı | O21: 9 | P21: 20cm Koli-Üretim Tarihli Etiket | Q21: 19-21 cm | R21: 140 | T21: Etiketli
B22: =IF(C22="","",CONCATENATE(C22,E22)) -> GERMESHanami Peynirli 20cm 4 lü 166g | C22: GERMES | D22: 8698829380698 | E22: Hanami Peynirli 20cm 4 lü 166g | F22: Hanami Peynirli 20cm (050) | G22: PEYNİRLİ | H22: 30 | I22: 20 | J22: Irak Soft-AT | K22: 4 | L22: 30 | M22: 166 | N22: YURTDIŞI | O22: 9 | P22: HANAMİ SARI KOLİ-ÜRETİM TARİHİ BASILACAK | Q22: 19-21 CM | R22: 140 | T22: Ambalaj kaç aylık kontrol?
B23: =IF(C23="","",CONCATENATE(C23,E23)) -> LLC KOTORManetka 20cm 4 pcs 166g | C23: LLC KOTOR | D23: 8698829380698 | E23: Manetka 20cm 4 pcs 166g | F23: Manetka 20cm | G23: SADE | H23: 14 | I23: 20 | J23: Irak Soft | K23: 4 | L23: 14 | M23: 166 | N23: YURTDIŞI | O23: 6 | P23: Kare Koli-Üretim Tarihli Etiket | Q23: 19-21 cm | R23: 225
B24: =IF(C24="","",CONCATENATE(C24,E24)) -> SMART LLCTortillas 20cm Peynirli 4pcs 166g | C24: SMART LLC | D24: 8698829380698 | E24: Tortillas 20cm Peynirli 4pcs 166g | F24: Tortillas 20cm (Samakat Bilgileri Ekli) | G24: PEYNİRLİ | H24: 14 | I24: 20 | J24: IRAK SOFT-AT | K24: 4 | L24: 14 | M24: 166 | N24: YURTDIŞI | O24: 9 | P24: Kare Koli-Üretim Tarihli Etiket | Q24: 19-21 cm | R24: 225
B25: =IF(C25="","",CONCATENATE(C25,E25)) -> EYALRimini 20 cm 8 pcs 360g | C25: EYAL | D25: 8698829380698 | E25: Rimini 20 cm 8 pcs 360g | F25: Rimini 20cm | G25: SADE | H25: 14 | I25: 20 | J25: Irak soft | K25: 8 | L25: 14 | M25: 360 | N25: YURTDIŞI | P25: 20cm koli-İbranice Etiket | Q25: 19-21 cm | R25: 120
B26: =IF(C26="","",CONCATENATE(C26,E26)) -> ALDİ - KOSOVATortillove 30cm 10pcs 900g | C26: ALDİ - KOSOVA | D26: 8698829380698 | E26: Tortillove 30cm 10pcs 900g | F26: Tortillove 30cm | G26: SADE | H26: 12 | I26: 30 | J26: Irak Soft | K26: 10 | L26: 12 | M26: 900 | N26: Yurtdışı | O26: 12 | P26: 30cm Koli - Tortillove 900g Etiketli | Q26: 29-31 cm | R26: 50 | T26: Arka kısma Arnavutça içerik-Tortillove
B27: =IF(C27="","",CONCATENATE(C27,E27)) -> ALDİ - KOSOVATortillas 30cm 10pcs 900g | C27: ALDİ - KOSOVA | D27: 8698829380698 | E27: Tortillas 30cm 10pcs 900g | F27: Tortillas 30cm | G27: SADE | H27: 12 | I27: 30 | J27: Irak Soft | K27: 10 | L27: 12 | M27: 900 | N27: Yurtdışı | O27: 12 | P27: 30cm Koli - Tortillas 900g Etiketli | Q27: 29-31 cm | R27: 50 | T27: Arka kısma Arnavutça içerik-Tortillas
B28: =IF(C28="","",CONCATENATE(C28,E28)) -> ALDİ - KOSOVATortillove 25cm 6pcs 390g | C28: ALDİ - KOSOVA | D28: 8698829380698 | E28: Tortillove 25cm 6pcs 390g | F28: Tortillove 25cm | G28: SADE | H28: 18 | I28: 25 | J28: Irak Soft | K28: 6 | L28: 18 | M28: 390 | N28: Yurtdışı | O28: 12 | P28: 25cm Koli - Tortillove 390g Etiketli | Q28: 24-26 cm | R28: 84 | T28: Barkod üzerine Arnavutça içerik+Barkod-Tortillove
B29: =IF(C29="","",CONCATENATE(C29,E29)) -> ALDİ - KOSOVATortillas 25cm 6pcs 390g | C29: ALDİ - KOSOVA | D29: 8698829380698 | E29: Tortillas 25cm 6pcs 390g | F29: Tortillas 25cm | G29: SADE | H29: 18 | I29: 25 | J29: Irak Soft | K29: 6 | L29: 18 | M29: 390 | N29: Yurtdışı | O29: 12 | P29: 25cm Koli - Tortillas 390g Etiketli | Q29: 24-26 cm | R29: 84 | T29: Barkod üzerine Arnavutça içerik+Barkod-Tortillas
B30: =IF(C30="","",CONCATENATE(C30,E30)) -> ALDİ - KOSOVATortillove 25cm TB 6pcs 390g | C30: ALDİ - KOSOVA | D30: 8698829380698 | E30: Tortillove 25cm TB 6pcs 390g | F30: Tortillove Tam Buğday 25cm | G30: Tam Buğdaylı | H30: 18 | I30: 25 | J30: Irak Soft | K30: 6 | L30: 18 | M30: 390 | N30: Yurtdışı | O30: 12 | P30: 25cm Koli - Tortillove 390g TB Etiketli | Q30: 24-26 cm | R30: 84 | T30: Barkod üzerine Arnavutça TB içerik+Barkod-Tortillove
B31: =IF(C31="","",CONCATENATE(C31,E31)) -> ALDİ - KOSOVATortillas 25cm TB 6pcs 390g | C31: ALDİ - KOSOVA | D31: 8698829380698 | E31: Tortillas 25cm TB 6pcs 390g | F31: Tortillas Tam Buğday 25cm | G31: Tam Buğdaylı | H31: 18 | I31: 25 | J31: Irak Soft | K31: 6 | L31: 18 | M31: 390 | N31: Yurtdışı | O31: 12 | P31: 25cm Koli - Tortillas 390g TB Etiketli | Q31: 24-26 cm | R31: 84 | T31: Barkod üzerine Arnavutça TB içerik+Barkod-Tortillas
B32: =IF(C32="","",CONCATENATE(C32,E32)) -> ALDİ - KOSOVATortillove 25cm 10pcs 650g | C32: ALDİ - KOSOVA | D32: 8698829380698 | E32: Tortillove 25cm 10pcs 650g | F32: Tortillove 25cm | G32: SADE | H32: 12 | I32: 25 | J32: Irak Soft | K32: 10 | L32: 12 | M32: 650 | N32: Yurtdışı | O32: 12 | P32: 25cm Koli - Tortillove 650g Etiketli | Q32: 24-26 cm | R32: 84 | T32: Arka kısma Arnavutça içerik-Tortillove
B33: =IF(C33="","",CONCATENATE(C33,E33)) -> ALDİ - KOSOVATortillas 25cm 10pcs 650g | C33: ALDİ - KOSOVA | D33: 8698829380698 | E33: Tortillas 25cm 10pcs 650g | F33: Tortillas 25cm | G33: SADE | H33: 12 | I33: 25 | J33: Irak Soft | K33: 10 | L33: 12 | M33: 650 | N33: Yurtdışı | O33: 12 | P33: 25cm Koli - Tortillas 650g Etiketli | Q33: 24-26 cm | R33: 84 | T33: Arka kısma Arnavutça içerik-Tortillas
B34: =IF(C34="","",CONCATENATE(C34,E34)) -> ALDİ - KOSOVAPizza-6 26cm 4pcs 480g | C34: ALDİ - KOSOVA | D34: 8698829380698 | E34: Pizza-6 26cm 4pcs 480g | F34: Pizza-6 26 cm | G34: SADE | H34: 6 | I34: 26 | J34: Irak Soft | K34: 4 | L34: 6 | M34: 480 | N34: YURTDIŞI | O34: 12 | P34: Pizza kolisi | Q34: 26 cm kesme -Beze 145-150g, Kesilmmeiş çap 27-28cm, Kesilmemiş ağı: 520-540g, Kesilmiş:475-485g | R34: 120 | T34: Arka kısma Arnavutça içerik-Pizza 6
B35: =IF(C35="","",CONCATENATE(C35,E35)) -> TASTE LAND-BULGARİSTANTortillas 30cm Sade 18pcs 1620g | C35: TASTE LAND-BULGARİSTAN | D35: 8698829380698 | E35: Tortillas 30cm Sade 18pcs 1620g | F35: Tortillas 30cm Sade | G35: SADE | H35: 6 | I35: 30 | J35: Irak Soft | K35: 18 | L35: 6 | M35: 1620 | N35: Yurtdışı | O35: 9 | P35: 30cm Lacivert Koli- Bulgarca Etiket | Q35: 29-31 cm | R35: 60 | S35: 95x130cm | T35: Barkod üzerine-Bulgarca Barkodlu içerik etiketi (012)
B36: =IF(C36="","",CONCATENATE(C36,E36)) -> TASTE LAND-BULGARİSTANTortillas 30cm Tam Buğday 18pcs 1620g | C36: TASTE LAND-BULGARİSTAN | D36: 8698829380698 | E36: Tortillas 30cm Tam Buğday 18pcs 1620g | F36: Tortillas 30cm Tam Buğday | G36: Tam Buğdaylı | H36: 6 | I36: 30 | J36: Irak Soft | K36: 18 | L36: 6 | M36: 1620 | N36: Yurtdışı | O36: 9 | P36: 30cm Lacivert Koli- Bulgarca TB Etiket | Q36: 29-31 cm | R36: 60 | S36: 95x130cm | T36: Barkod üzerine-Bulgarca Barkodlu TB içerik etiketi (029)
B37: =IF(C37="","",CONCATENATE(C37,E37)) -> TASTE LAND-BULGARİSTANTortillas 25cm Sade 10pcs 650g | C37: TASTE LAND-BULGARİSTAN | D37: 8698829380698 | E37: Tortillas 25cm Sade 10pcs 650g | F37: Tortillas Avrupa 25cm (698) | G37: SADE | H37: 8 | I37: 25 | J37: Irak Soft | K37: 10 | L37: 8 | M37: 650 | N37: Yurtdışı | O37: 9 | P37: 25cm Perforeli-Bulgarca etiket | Q37: 24-26 cm | R37: 120 | S37: 80x120cm -Epal+Epal
B38: =IF(C38="","",CONCATENATE(C38,E38)) -> TASTE LAND-BULGARİSTANTortillas 25cm Tam Buğday 10pcs 650g | C38: TASTE LAND-BULGARİSTAN | D38: 8698829380698 | E38: Tortillas 25cm Tam Buğday 10pcs 650g | F38: Tortillas Avrupa 25cm Tam Buğday (711) | G38: Tam Buğdaylı | H38: 8 | I38: 25 | J38: Irak Soft | K38: 10 | L38: 8 | M38: 650 | N38: Yurtdışı | O38: 9 | P38: 25cm Perforeli-Bulgarca TB etiket | Q38: 24-26 cm | R38: 120 | S38: 80x120cm -Epal+Epal
B39: =IF(C39="","",CONCATENATE(C39,E39)) -> TASTE LAND-BULGARİSTANTortillas 25cm Domatesli 6pcs 390g | C39: TASTE LAND-BULGARİSTAN | D39: 8698829380698 | E39: Tortillas 25cm Domatesli 6pcs 390g | F39: Tortillas Avrupa 25cm Domatesli (074) | G39: Domatesli | H39: 12 | I39: 25 | J39: Irak Soft | K39: 6 | L39: 12 | M39: 390 | N39: Yurtdışı | O39: 9 | P39: 25cm Perforeli-Bulgarca Domatesli etiket | Q39: 24-26 cm | R39: 120 | S39: 80x120cm -Epal+Epal
B40: =IF(C40="","",CONCATENATE(C40,E40)) -> TASTE LAND-BULGARİSTANTortillas 25cm Ispanaklı 6pcs 390g | C40: TASTE LAND-BULGARİSTAN | D40: 8698829380698 | E40: Tortillas 25cm Ispanaklı 6pcs 390g | F40: Tortillas Avrupa 25cm Ispanaklı (081) | G40: Ispanaklı | H40: 12 | I40: 25 | J40: Irak Soft | K40: 6 | L40: 12 | M40: 390 | N40: Yurtdışı | O40: 9 | P40: 25cm Perforeli-Bulgarca Ispanaklı etiket | Q40: 24-26 cm | R40: 120 | S40: 80x120cm -Epal+Epal
B41: =IF(C41="","",CONCATENATE(C41,E41)) -> TASTE LAND-BULGARİSTANTortillas 25cm Peynirli 6pcs 390g | C41: TASTE LAND-BULGARİSTAN | D41: 8698829380698 | E41: Tortillas 25cm Peynirli 6pcs 390g | F41: Tortillas Avrupa 25cm Peynirli (098) | G41: Peynirli | H41: 12 | I41: 25 | J41: Irak Soft-AT | K41: 6 | L41: 12 | M41: 390 | N41: Yurtdışı | O41: 9 | P41: 25cm Perforeli-Bulgarca Peynirli etiket | Q41: 24-26 cm | R41: 120 | S41: 80x120cm -Epal+Epal
B42: =IF(C42="","",CONCATENATE(C42,E42)) -> TASTE LAND-BULGARİSTANTortillas Pizza 26cm 4pcs 480g | C42: TASTE LAND-BULGARİSTAN | D42: 8698829380698 | E42: Tortillas Pizza 26cm 4pcs 480g | F42: Tortillas Avrupa Pizza 26cm (742) | G42: SADE | H42: 8 | I42: 26 | J42: Irak Soft | K42: 4 | L42: 8 | M42: 480 | N42: Yurtdışı | O42: 9 | P42: 26cm Pizza Perforeli-Bulgarca Etiket | Q42: 26 cm kesme -Beze 145-150g, Kesilmmeiş çap 27-28cm, Kesilmemiş ağı: 520-540g, Kesilmiş:475-485g | R42: 120 | S42: 80x120cm -Epal+Epal
...

Sheet Data
A1: MUTLUKAL İŞ EMRİ
A2: MAKİNE 1 | Z2: 46174 | AA2: 0.71875
A3: SIRA | B3: FİRMA | C3: GTIN KODU | D3: PRODUCT NAME / ÜRÜN ADI | E3: ORDER NUMBER / SİPARİŞ NUMARASI | F3: KAREKOD DOSYA ADI | G3: AMBALAJ | H3: AMBALAJ ETİKETİ | I3: CİNSİ | J3: ÜRETİLECEK MİKTAR/ KOLİ | K3: DEPO STOK / KOLİ | L3: ÜRETİLECEK MİKTAR/ PALET | M3: PALET KOLİ SAYISI | N3: PALET ÖLÇÜ | O3: AMBALAJ MİKTAR | P3: ÇAP | Q3: FORMÜL | R3: PAKET İÇİ | S3: KOLİ İÇİ | T3: PAKET GRAMAJI | U3: TARİH | V3: SKT/AY | W3: ÜRT/PRD | X3: TETT/EXP | Y3: PRT/LOT | Z3: KOLİ / TARİH | AA3: AÇIKLAMALAR | AB3: Birleştir
A4: 1. | B4: LLC TRİTON | C4: =IF(B4="","",VLOOKUP(AB4,Varsayımlar!$B:$Q,3,0)) -> 8698829380698 | D4: MUTLUKAL WHEAT TORTILLA | E4: KB-006336 | F4: ZPT-008462 | G4: =IF(B4="","",VLOOKUP(AB4,Varsayımlar!$B:$Q,5,0)) -> TORTİLLAS 25 CM 4 PCS 260G | I4: =IF(B4="","",VLOOKUP(AB4,Varsayımlar!$B:$Q,6,0)) -> SADE | J4: 588 | L4: 7 | O4: =IF(B4="","",VLOOKUP(AB4,Varsayımlar!$B:$Q,7,0)*J4) -> 17640 | P4: =IF(B4="","",VLOOKUP(AB4,Varsayımlar!$B:$Q,8,0)) -> 25 | Q4: =IF(B4="","",VLOOKUP(AB4,Varsayımlar!$B:$Q,9,0)) -> SOFT | R4: =IF(B4="","",VLOOKUP(AB4,Varsayımlar!$B:$Q,10,0)) -> 4 | S4: =IF(B4="","",VLOOKUP(AB4,Varsayımlar!$B:$Q,11,0)) -> 30 | T4: =IF(B4="","",VLOOKUP(AB4,Varsayımlar!$B:$Q,12,0)) -> 260 | U4: =IF(B4="","",VLOOKUP(AB4,Varsayımlar!$B:$Q,13,0)) -> YURTDIŞI | V4: =IF(B4="","",VLOOKUP(AB4,Varsayımlar!$B:$Q,14,0)) -> 6 | W4: 46175 | X4: 46358 | Y4: 26060225-1 | Z4: =IF(B4="","",VLOOKUP(AB4,Varsayımlar!$B:$Q,15,0)) -> TRİTON -SKT ATILACAK | AA4: =IF(B4="","",VLOOKUP(AB4,Varsayımlar!$B:$Q,16,0)) -> 24-26 CM | AB4: =IF(B4="","",CONCATENATE(B4,D4)) -> LLC TRİTONMUTLUKAL WHEAT TORTILLA | AC4: BİTTİ
A5: 2. | B5: LLC TRİTON | C5: =IF(B5="","",VLOOKUP(AB5,Varsayımlar!$B:$Q,3,0)) -> 8698829380698 | D5: MUTLUKAL WHEAT TORTILLA | E5: KB-006336 | F5: ZPO-019211 | G5: =IF(B5="","",VLOOKUP(AB5,Varsayımlar!$B:$Q,5,0)) -> TORTİLLAS 25 CM 4 PCS 260G | I5: =IF(B5="","",VLOOKUP(AB5,Varsayımlar!$B:$Q,6,0)) -> SADE | J5: 1848 | L5: 22 | O5: =IF(B5="","",VLOOKUP(AB5,Varsayımlar!$B:$Q,7,0)*J5) -> 55440 | P5: =IF(B5="","",VLOOKUP(AB5,Varsayımlar!$B:$Q,8,0)) -> 25 | Q5: =IF(B5="","",VLOOKUP(AB5,Varsayımlar!$B:$Q,9,0)) -> SOFT | R5: =IF(B5="","",VLOOKUP(AB5,Varsayımlar!$B:$Q,10,0)) -> 4 | S5: =IF(B5="","",VLOOKUP(AB5,Varsayımlar!$B:$Q,11,0)) -> 30 | T5: =IF(B5="","",VLOOKUP(AB5,Varsayımlar!$B:$Q,12,0)) -> 260 | U5: =IF(B5="","",VLOOKUP(AB5,Varsayımlar!$B:$Q,13,0)) -> YURTDIŞI | V5: =IF(B5="","",VLOOKUP(AB5,Varsayımlar!$B:$Q,14,0)) -> 6 | W5: 46175 | X5: 46358 | Y5: 26060225-1 | Z5: =IF(B5="","",VLOOKUP(AB5,Varsayımlar!$B:$Q,15,0)) -> TRİTON -SKT ATILACAK | AA5: =IF(B5="","",VLOOKUP(AB5,Varsayımlar!$B:$Q,16,0)) -> 24-26 CM | AB5: =IF(B5="","",CONCATENATE(B5,D5)) -> LLC TRİTONMUTLUKAL WHEAT TORTILLA
A6: 3. | B6: LLC TRİTON | C6: =IF(B6="","",VLOOKUP(AB6,Varsayımlar!$B:$Q,3,0)) -> 8698829380698 | D6: MUTLUKAL WHEAT TORTILLA | E6: KB-006321 | F6: ZP6-17971 | G6: =IF(B6="","",VLOOKUP(AB6,Varsayımlar!$B:$Q,5,0)) -> TORTİLLAS 25 CM 4 PCS 260G | I6: =IF(B6="","",VLOOKUP(AB6,Varsayımlar!$B:$Q,6,0)) -> SADE | J6: 1680 | L6: 20 | O6: =IF(B6="","",VLOOKUP(AB6,Varsayımlar!$B:$Q,7,0)*J6) -> 50400 | P6: =IF(B6="","",VLOOKUP(AB6,Varsayımlar!$B:$Q,8,0)) -> 25 | Q6: =IF(B6="","",VLOOKUP(AB6,Varsayımlar!$B:$Q,9,0)) -> SOFT | R6: =IF(B6="","",VLOOKUP(AB6,Varsayımlar!$B:$Q,10,0)) -> 4 | S6: =IF(B6="","",VLOOKUP(AB6,Varsayımlar!$B:$Q,11,0)) -> 30 | T6: =IF(B6="","",VLOOKUP(AB6,Varsayımlar!$B:$Q,12,0)) -> 260 | U6: =IF(B6="","",VLOOKUP(AB6,Varsayımlar!$B:$Q,13,0)) -> YURTDIŞI | V6: =IF(B6="","",VLOOKUP(AB6,Varsayımlar!$B:$Q,14,0)) -> 6 | W6: 46176 | X6: 46359 | Y6: 26060325-1 | Z6: =IF(B6="","",VLOOKUP(AB6,Varsayımlar!$B:$Q,15,0)) -> TRİTON -SKT ATILACAK | AA6: =IF(B6="","",VLOOKUP(AB6,Varsayımlar!$B:$Q,16,0)) -> 24-26 CM | AB6: =IF(B6="","",CONCATENATE(B6,D6)) -> LLC TRİTONMUTLUKAL WHEAT TORTILLA
A7: 4. | B7: LLC TRİTON | C7: =IF(B7="","",VLOOKUP(AB7,Varsayımlar!$B:$Q,3,0)) -> 8698829380698 | D7: MUTLUKAL WHEAT TORTILLA | E7: KB-006321 | F7: Z210006314 | G7: =IF(B7="","",VLOOKUP(AB7,Varsayımlar!$B:$Q,5,0)) -> TORTİLLAS 25 CM 4 PCS 260G | I7: =IF(B7="","",VLOOKUP(AB7,Varsayımlar!$B:$Q,6,0)) -> SADE | J7: 420 | L7: =J7/84 -> 5 | O7: =IF(B7="","",VLOOKUP(AB7,Varsayımlar!$B:$Q,7,0)*J7) -> 12600 | P7: =IF(B7="","",VLOOKUP(AB7,Varsayımlar!$B:$Q,8,0)) -> 25 | Q7: =IF(B7="","",VLOOKUP(AB7,Varsayımlar!$B:$Q,9,0)) -> SOFT | R7: =IF(B7="","",VLOOKUP(AB7,Varsayımlar!$B:$Q,10,0)) -> 4 | S7: =IF(B7="","",VLOOKUP(AB7,Varsayımlar!$B:$Q,11,0)) -> 30 | T7: =IF(B7="","",VLOOKUP(AB7,Varsayımlar!$B:$Q,12,0)) -> 260 | U7: =IF(B7="","",VLOOKUP(AB7,Varsayımlar!$B:$Q,13,0)) -> YURTDIŞI | V7: =IF(B7="","",VLOOKUP(AB7,Varsayımlar!$B:$Q,14,0)) -> 6 | W7: 46176 | X7: 46359 | Y7: 26060325-1 | Z7: =IF(B7="","",VLOOKUP(AB7,Varsayımlar!$B:$Q,15,0)) -> TRİTON -SKT ATILACAK | AA7: =IF(B7="","",VLOOKUP(AB7,Varsayımlar!$B:$Q,16,0)) -> 24-26 CM | AB7: =IF(B7="","",CONCATENATE(B7,D7)) -> LLC TRİTONMUTLUKAL WHEAT TORTILLA
A8: 5. | B8: LLC TRİTON | C8: =IF(B8="","",VLOOKUP(AB8,Varsayımlar!$B:$Q,3,0)) -> 8698829380698 | D8: MUTLUKAL WHEAT TORTILLA | E8: KB-006321 | F8: ZP3-012107 | G8: =IF(B8="","",VLOOKUP(AB8,Varsayımlar!$B:$Q,5,0)) -> TORTİLLAS 25 CM 4 PCS 260G | I8: =IF(B8="","",VLOOKUP(AB8,Varsayımlar!$B:$Q,6,0)) -> SADE | J8: 336 | L8: =J8/84 -> 4 | O8: =IF(B8="","",VLOOKUP(AB8,Varsayımlar!$B:$Q,7,0)*J8) -> 10080 | P8: =IF(B8="","",VLOOKUP(AB8,Varsayımlar!$B:$Q,8,0)) -> 25 | Q8: =IF(B8="","",VLOOKUP(AB8,Varsayımlar!$B:$Q,9,0)) -> SOFT | R8: =IF(B8="","",VLOOKUP(AB8,Varsayımlar!$B:$Q,10,0)) -> 4 | S8: =IF(B8="","",VLOOKUP(AB8,Varsayımlar!$B:$Q,11,0)) -> 30 | T8: =IF(B8="","",VLOOKUP(AB8,Varsayımlar!$B:$Q,12,0)) -> 260 | U8: =IF(B8="","",VLOOKUP(AB8,Varsayımlar!$B:$Q,13,0)) -> YURTDIŞI | V8: =IF(B8="","",VLOOKUP(AB8,Varsayımlar!$B:$Q,14,0)) -> 6 | W8: 46176 | X8: 46359 | Y8: 26060325-1 | Z8: =IF(B8="","",VLOOKUP(AB8,Varsayımlar!$B:$Q,15,0)) -> TRİTON -SKT ATILACAK | AA8: =IF(B8="","",VLOOKUP(AB8,Varsayımlar!$B:$Q,16,0)) -> 24-26 CM | AB8: =IF(B8="","",CONCATENATE(B8,D8)) -> LLC TRİTONMUTLUKAL WHEAT TORTILLA
A9: 6. | B9: LLC TRİTON | C9: =IF(B9="","",VLOOKUP(AB9,Varsayımlar!$B:$Q,3,0)) -> 8698829380698 | D9: MUTLUKAL WHEAT TORTILLA | E9: KB-006567 | F9: ZPD-012226 | G9: =IF(B9="","",VLOOKUP(AB9,Varsayımlar!$B:$Q,5,0)) -> TORTİLLAS 25 CM 4 PCS 260G | I9: =IF(B9="","",VLOOKUP(AB9,Varsayımlar!$B:$Q,6,0)) -> SADE | J9: 1680 | L9: =J9/84 -> 20 | O9: =IF(B9="","",VLOOKUP(AB9,Varsayımlar!$B:$Q,7,0)*J9) -> 50400 | P9: =IF(B9="","",VLOOKUP(AB9,Varsayımlar!$B:$Q,8,0)) -> 25 | Q9: =IF(B9="","",VLOOKUP(AB9,Varsayımlar!$B:$Q,9,0)) -> SOFT | R9: =IF(B9="","",VLOOKUP(AB9,Varsayımlar!$B:$Q,10,0)) -> 4 | S9: =IF(B9="","",VLOOKUP(AB9,Varsayımlar!$B:$Q,11,0)) -> 30 | T9: =IF(B9="","",VLOOKUP(AB9,Varsayımlar!$B:$Q,12,0)) -> 260 | U9: =IF(B9="","",VLOOKUP(AB9,Varsayımlar!$B:$Q,13,0)) -> YURTDIŞI | V9: =IF(B9="","",VLOOKUP(AB9,Varsayımlar!$B:$Q,14,0)) -> 6 | W9: 46176 | X9: 46359 | Y9: 26060325-3 | Z9: =IF(B9="","",VLOOKUP(AB9,Varsayımlar!$B:$Q,15,0)) -> TRİTON -SKT ATILACAK | AA9: =IF(B9="","",VLOOKUP(AB9,Varsayımlar!$B:$Q,16,0)) -> 24-26 CM | AB9: =IF(B9="","",CONCATENATE(B9,D9)) -> LLC TRİTONMUTLUKAL WHEAT TORTILLA
A10: 7. | B10: LLC TRİTON | C10: =IF(B10="","",VLOOKUP(AB10,Varsayımlar!$B:$Q,3,0)) -> 8698829380698 | D10: MUTLUKAL WHEAT TORTILLA | E10: KB-006567 | F10: Z190009938 | G10: =IF(B10="","",VLOOKUP(AB10,Varsayımlar!$B:$Q,5,0)) -> TORTİLLAS 25 CM 4 PCS 260G | I10: =IF(B10="","",VLOOKUP(AB10,Varsayımlar!$B:$Q,6,0)) -> SADE | J10: 756 | L10: =J10/84 -> 9 | O10: =IF(B10="","",VLOOKUP(AB10,Varsayımlar!$B:$Q,7,0)*J10) -> 22680 | P10: =IF(B10="","",VLOOKUP(AB10,Varsayımlar!$B:$Q,8,0)) -> 25 | Q10: =IF(B10="","",VLOOKUP(AB10,Varsayımlar!$B:$Q,9,0)) -> SOFT | R10: =IF(B10="","",VLOOKUP(AB10,Varsayımlar!$B:$Q,10,0)) -> 4 | S10: =IF(B10="","",VLOOKUP(AB10,Varsayımlar!$B:$Q,11,0)) -> 30 | T10: =IF(B10="","",VLOOKUP(AB10,Varsayımlar!$B:$Q,12,0)) -> 260 | U10: =IF(B10="","",VLOOKUP(AB10,Varsayımlar!$B:$Q,13,0)) -> YURTDIŞI | V10: =IF(B10="","",VLOOKUP(AB10,Varsayımlar!$B:$Q,14,0)) -> 6 | W10: 46176 | X10: 46359 | Y10: 26060325-3 | Z10: =IF(B10="","",VLOOKUP(AB10,Varsayımlar!$B:$Q,15,0)) -> TRİTON -SKT ATILACAK | AA10: =IF(B10="","",VLOOKUP(AB10,Varsayımlar!$B:$Q,16,0)) -> 24-26 CM | AB10: =IF(B10="","",CONCATENATE(B10,D10)) -> LLC TRİTONMUTLUKAL WHEAT TORTILLA
A11: 8. | B11: GERMES | C11: =IF(B11="","",VLOOKUP(AB11,Varsayımlar!$B:$Q,3,0)) -> 8698829380698 | D11: HANAMİ GERMES 25CM SADE 250G | E11: 46 | F11: 46-HANAMİ GERMES 25CM SADE 250G | G11: =IF(B11="","",VLOOKUP(AB11,Varsayımlar!$B:$Q,5,0)) -> HANAMİ 25 CM SADE (081) | I11: =IF(B11="","",VLOOKUP(AB11,Varsayımlar!$B:$Q,6,0)) -> SADE | J11: 588 | L11: 7 | O11: =IF(B11="","",VLOOKUP(AB11,Varsayımlar!$B:$Q,7,0)*J11) -> 17640 | P11: =IF(B11="","",VLOOKUP(AB11,Varsayımlar!$B:$Q,8,0)) -> 25 | Q11: =IF(B11="","",VLOOKUP(AB11,Varsayımlar!$B:$Q,9,0)) -> IRAK SOFT | R11: =IF(B11="","",VLOOKUP(AB11,Varsayımlar!$B:$Q,10,0)) -> 4 | S11: =IF(B11="","",VLOOKUP(AB11,Varsayımlar!$B:$Q,11,0)) -> 30 | T11: =IF(B11="","",VLOOKUP(AB11,Varsayımlar!$B:$Q,12,0)) -> 250 | U11: =IF(B11="","",VLOOKUP(AB11,Varsayımlar!$B:$Q,13,0)) -> YURTDIŞI | V11: =IF(B11="","",VLOOKUP(AB11,Varsayımlar!$B:$Q,14,0)) -> 9 | W11: 46181 | X11: 46454 | Y11: 26060825 | Z11: =IF(B11="","",VLOOKUP(AB11,Varsayımlar!$B:$Q,15,0)) -> HANAMİ MAVİ - ÜRETİM ATILACAK | AA11: =IF(B11="","",VLOOKUP(AB11,Varsayımlar!$B:$Q,16,0)) -> 24-26 CM | AB11: =IF(B11="","",CONCATENATE(B11,D11)) -> GERMESHANAMİ GERMES 25CM SADE 250G
A12: 9. | B12: GERMES | C12: =IF(B12="","",VLOOKUP(AB12,Varsayımlar!$B:$Q,3,0)) -> 8698829380698 | D12: Kırmızı Tortillas-Germes-25cm 375g | E12: 46 | F12: 46-Kırmızı Tortillas-Germes-25cm 375g | G12: =IF(B12="","",VLOOKUP(AB12,Varsayımlar!$B:$Q,5,0)) -> KIRMIZI TORTİLLAS 25 CM | H12: BARKOD ETİKETİ | I12: =IF(B12="","",VLOOKUP(AB12,Varsayımlar!$B:$Q,6,0)) -> SADE | J12: 84 | L12: 1 | O12: =IF(B12="","",VLOOKUP(AB12,Varsayımlar!$B:$Q,7,0)*J12) -> 1512 | P12: =IF(B12="","",VLOOKUP(AB12,Varsayımlar!$B:$Q,8,0)) -> 25 | Q12: =IF(B12="","",VLOOKUP(AB12,Varsayımlar!$B:$Q,9,0)) -> IRAK SOFT | R12: =IF(B12="","",VLOOKUP(AB12,Varsayımlar!$B:$Q,10,0)) -> 6 | S12: =IF(B12="","",VLOOKUP(AB12,Varsayımlar!$B:$Q,11,0)) -> 18 | T12: =IF(B12="","",VLOOKUP(AB12,Varsayımlar!$B:$Q,12,0)) -> 375 | U12: =IF(B12="","",VLOOKUP(AB12,Varsayımlar!$B:$Q,13,0)) -> YURTDIŞI | V12: =IF(B12="","",VLOOKUP(AB12,Varsayımlar!$B:$Q,14,0)) -> 9 | W12: 46181 | X12: 46454 | Y12: 26060825 | Z12: =IF(B12="","",VLOOKUP(AB12,Varsayımlar!$B:$Q,15,0)) -> KIRMIZI - ÜRETİM TARİHLİ ETİKET | AA12: =IF(B12="","",VLOOKUP(AB12,Varsayımlar!$B:$Q,16,0)) -> 24-26 CM | AB12: =IF(B12="","",CONCATENATE(B12,D12)) -> GERMESKırmızı Tortillas-Germes-25cm 375g
A13: 10. | B13: LLC TRİTON | C13: =IF(B13="","",VLOOKUP(AB13,Varsayımlar!$B:$Q,3,0)) -> 8698829380698 | D13: MUTLUKAL WHEAT TORTILLA | E13: KB-006500 | F13: ZP4-021324 | G13: =IF(B13="","",VLOOKUP(AB13,Varsayımlar!$B:$Q,5,0)) -> TORTİLLAS 25 CM 4 PCS 260G | I13: =IF(B13="","",VLOOKUP(AB13,Varsayımlar!$B:$Q,6,0)) -> SADE | J13: 2436 | L13: =J13/84 -> 29 | O13: =IF(B13="","",VLOOKUP(AB13,Varsayımlar!$B:$Q,7,0)*J13) -> 73080 | P13: =IF(B13="","",VLOOKUP(AB13,Varsayımlar!$B:$Q,8,0)) -> 25 | Q13: =IF(B13="","",VLOOKUP(AB13,Varsayımlar!$B:$Q,9,0)) -> SOFT | R13: =IF(B13="","",VLOOKUP(AB13,Varsayımlar!$B:$Q,10,0)) -> 4 | S13: =IF(B13="","",VLOOKUP(AB13,Varsayımlar!$B:$Q,11,0)) -> 30 | T13: =IF(B13="","",VLOOKUP(AB13,Varsayımlar!$B:$Q,12,0)) -> 260 | U13: =IF(B13="","",VLOOKUP(AB13,Varsayımlar!$B:$Q,13,0)) -> YURTDIŞI | V13: =IF(B13="","",VLOOKUP(AB13,Varsayımlar!$B:$Q,14,0)) -> 6 | W13: 46177 | X13: 46360 | Y13: 26060425-1 | Z13: =IF(B13="","",VLOOKUP(AB13,Varsayımlar!$B:$Q,15,0)) -> TRİTON -SKT ATILACAK | AA13: =IF(B13="","",VLOOKUP(AB13,Varsayımlar!$B:$Q,16,0)) -> 24-26 CM | AB13: =IF(B13="","",CONCATENATE(B13,D13)) -> LLC TRİTONMUTLUKAL WHEAT TORTILLA
A14: 11. | B14: LLC TRİTON | C14: =IF(B14="","",VLOOKUP(AB14,Varsayımlar!$B:$Q,3,0)) -> 8698829380698 | D14: MUTLUKAL WHEAT TORTILLA | E14: KB-006502 | F14: ZPL-015636 | G14: =IF(B14="","",VLOOKUP(AB14,Varsayımlar!$B:$Q,5,0)) -> TORTİLLAS 25 CM 4 PCS 260G | I14: =IF(B14="","",VLOOKUP(AB14,Varsayımlar!$B:$Q,6,0)) -> SADE | J14: 1344 | L14: =J14/84 -> 16 | O14: =IF(B14="","",VLOOKUP(AB14,Varsayımlar!$B:$Q,7,0)*J14) -> 40320 | P14: =IF(B14="","",VLOOKUP(AB14,Varsayımlar!$B:$Q,8,0)) -> 25 | Q14: =IF(B14="","",VLOOKUP(AB14,Varsayımlar!$B:$Q,9,0)) -> SOFT | R14: =IF(B14="","",VLOOKUP(AB14,Varsayımlar!$B:$Q,10,0)) -> 4 | S14: =IF(B14="","",VLOOKUP(AB14,Varsayımlar!$B:$Q,11,0)) -> 30 | T14: =IF(B14="","",VLOOKUP(AB14,Varsayımlar!$B:$Q,12,0)) -> 260 | U14: =IF(B14="","",VLOOKUP(AB14,Varsayımlar!$B:$Q,13,0)) -> YURTDIŞI | V14: =IF(B14="","",VLOOKUP(AB14,Varsayımlar!$B:$Q,14,0)) -> 6 | W14: 46177 | X14: 46360 | Y14: 26060425-2 | Z14: =IF(B14="","",VLOOKUP(AB14,Varsayımlar!$B:$Q,15,0)) -> TRİTON -SKT ATILACAK | AA14: =IF(B14="","",VLOOKUP(AB14,Varsayımlar!$B:$Q,16,0)) -> 24-26 CM | AB14: =IF(B14="","",CONCATENATE(B14,D14)) -> LLC TRİTONMUTLUKAL WHEAT TORTILLA
A15: 12. | B15: LLC TRİTON | C15: =IF(B15="","",VLOOKUP(AB15,Varsayımlar!$B:$Q,3,0)) -> 8698829380698 | D15: MUTLUKAL WHEAT TORTILLA | E15: KB-006502 | F15: ZPK-013503 | G15: =IF(B15="","",VLOOKUP(AB15,Varsayımlar!$B:$Q,5,0)) -> TORTİLLAS 25 CM 4 PCS 260G | I15: =IF(B15="","",VLOOKUP(AB15,Varsayımlar!$B:$Q,6,0)) -> SADE | J15: 1092 | L15: =J15/84 -> 13 | O15: =IF(B15="","",VLOOKUP(AB15,Varsayımlar!$B:$Q,7,0)*J15) -> 32760 | P15: =IF(B15="","",VLOOKUP(AB15,Varsayımlar!$B:$Q,8,0)) -> 25 | Q15: =IF(B15="","",VLOOKUP(AB15,Varsayımlar!$B:$Q,9,0)) -> SOFT | R15: =IF(B15="","",VLOOKUP(AB15,Varsayımlar!$B:$Q,10,0)) -> 4 | S15: =IF(B15="","",VLOOKUP(AB15,Varsayımlar!$B:$Q,11,0)) -> 30 | T15: =IF(B15="","",VLOOKUP(AB15,Varsayımlar!$B:$Q,12,0)) -> 260 | U15: =IF(B15="","",VLOOKUP(AB15,Varsayımlar!$B:$Q,13,0)) -> YURTDIŞI | V15: =IF(B15="","",VLOOKUP(AB15,Varsayımlar!$B:$Q,14,0)) -> 6 | W15: 46177 | X15: 46360 | Y15: 26060425-2 | Z15: =IF(B15="","",VLOOKUP(AB15,Varsayımlar!$B:$Q,15,0)) -> TRİTON -SKT ATILACAK | AA15: =IF(B15="","",VLOOKUP(AB15,Varsayımlar!$B:$Q,16,0)) -> 24-26 CM | AB15: =IF(B15="","",CONCATENATE(B15,D15)) -> LLC TRİTONMUTLUKAL WHEAT TORTILLA
A16: 13. | B16: LLC TRİTON | C16: =IF(B16="","",VLOOKUP(AB16,Varsayımlar!$B:$Q,3,0)) -> 8698829380698 | D16: MUTLUKAL WHEAT TORTILLA | E16: KB-006497 | F16: Z180014794 | G16: =IF(B16="","",VLOOKUP(AB16,Varsayımlar!$B:$Q,5,0)) -> TORTİLLAS 25 CM 4 PCS 260G | I16: =IF(B16="","",VLOOKUP(AB16,Varsayımlar!$B:$Q,6,0)) -> SADE | J16: 1092 | L16: =J16/84 -> 13 | O16: =IF(B16="","",VLOOKUP(AB16,Varsayımlar!$B:$Q,7,0)*J16) -> 32760 | P16: =IF(B16="","",VLOOKUP(AB16,Varsayımlar!$B:$Q,8,0)) -> 25 | Q16: =IF(B16="","",VLOOKUP(AB16,Varsayımlar!$B:$Q,9,0)) -> SOFT | R16: =IF(B16="","",VLOOKUP(AB16,Varsayımlar!$B:$Q,10,0)) -> 4 | S16: =IF(B16="","",VLOOKUP(AB16,Varsayımlar!$B:$Q,11,0)) -> 30 | T16: =IF(B16="","",VLOOKUP(AB16,Varsayımlar!$B:$Q,12,0)) -> 260 | U16: =IF(B16="","",VLOOKUP(AB16,Varsayımlar!$B:$Q,13,0)) -> YURTDIŞI | V16: =IF(B16="","",VLOOKUP(AB16,Varsayımlar!$B:$Q,14,0)) -> 6 | W16: 46177 | X16: 46360 | Y16: 26060425-3 | Z16: =IF(B16="","",VLOOKUP(AB16,Varsayımlar!$B:$Q,15,0)) -> TRİTON -SKT ATILACAK | AA16: =IF(B16="","",VLOOKUP(AB16,Varsayımlar!$B:$Q,16,0)) -> 24-26 CM | AB16: =IF(B16="","",CONCATENATE(B16,D16)) -> LLC TRİTONMUTLUKAL WHEAT TORTILLA
A17: 14. | B17: LLC TRİTON | C17: =IF(B17="","",VLOOKUP(AB17,Varsayımlar!$B:$Q,3,0)) -> 8698829380698 | D17: MUTLUKAL WHEAT TORTILLA | E17: KB-006497 | F17: ZP8-015844 | G17: =IF(B17="","",VLOOKUP(AB17,Varsayımlar!$B:$Q,5,0)) -> TORTİLLAS 25 CM 4 PCS 260G | I17: =IF(B17="","",VLOOKUP(AB17,Varsayımlar!$B:$Q,6,0)) -> SADE | J17: 1344 | L17: =J17/84 -> 16 | O17: =IF(B17="","",VLOOKUP(AB17,Varsayımlar!$B:$Q,7,0)*J17) -> 40320 | P17: =IF(B17="","",VLOOKUP(AB17,Varsayımlar!$B:$Q,8,0)) -> 25 | Q17: =IF(B17="","",VLOOKUP(AB17,Varsayımlar!$B:$Q,9,0)) -> SOFT | R17: =IF(B17="","",VLOOKUP(AB17,Varsayımlar!$B:$Q,10,0)) -> 4 | S17: =IF(B17="","",VLOOKUP(AB17,Varsayımlar!$B:$Q,11,0)) -> 30 | T17: =IF(B17="","",VLOOKUP(AB17,Varsayımlar!$B:$Q,12,0)) -> 260 | U17: =IF(B17="","",VLOOKUP(AB17,Varsayımlar!$B:$Q,13,0)) -> YURTDIŞI | V17: =IF(B17="","",VLOOKUP(AB17,Varsayımlar!$B:$Q,14,0)) -> 6 | W17: 46177 | X17: 46360 | Y17: 26060425-3 | Z17: =IF(B17="","",VLOOKUP(AB17,Varsayımlar!$B:$Q,15,0)) -> TRİTON -SKT ATILACAK | AA17: =IF(B17="","",VLOOKUP(AB17,Varsayımlar!$B:$Q,16,0)) -> 24-26 CM | AB17: =IF(B17="","",CONCATENATE(B17,D17)) -> LLC TRİTONMUTLUKAL WHEAT TORTILLA
A18: 15. | B18: LLC TRİTON | C18: =IF(B18="","",VLOOKUP(AB18,Varsayımlar!$B:$Q,3,0)) -> 8698829380698 | D18: MUTLUKAL WHEAT TORTILLA | E18: KB-006582 | F18: ZPT-008984 | G18: =IF(B18="","",VLOOKUP(AB18,Varsayımlar!$B:$Q,5,0)) -> TORTİLLAS 25 CM 4 PCS 260G | I18: =IF(B18="","",VLOOKUP(AB18,Varsayımlar!$B:$Q,6,0)) -> SADE | J18: 588 | L18: =J18/84 -> 7 | O18: =IF(B18="","",VLOOKUP(AB18,Varsayımlar!$B:$Q,7,0)*J18) -> 17640 | P18: =IF(B18="","",VLOOKUP(AB18,Varsayımlar!$B:$Q,8,0)) -> 25 | Q18: =IF(B18="","",VLOOKUP(AB18,Varsayımlar!$B:$Q,9,0)) -> SOFT | R18: =IF(B18="","",VLOOKUP(AB18,Varsayımlar!$B:$Q,10,0)) -> 4 | S18: =IF(B18="","",VLOOKUP(AB18,Varsayımlar!$B:$Q,11,0)) -> 30 | T18: =IF(B18="","",VLOOKUP(AB18,Varsayımlar!$B:$Q,12,0)) -> 260 | U18: =IF(B18="","",VLOOKUP(AB18,Varsayımlar!$B:$Q,13,0)) -> YURTDIŞI | V18: =IF(B18="","",VLOOKUP(AB18,Varsayımlar!$B:$Q,14,0)) -> 6 | W18: 46178 | X18: 46361 | Y18: 26060525 | Z18: =IF(B18="","",VLOOKUP(AB18,Varsayımlar!$B:$Q,15,0)) -> TRİTON -SKT ATILACAK | AA18: =IF(B18="","",VLOOKUP(AB18,Varsayımlar!$B:$Q,16,0)) -> 24-26 CM | AB18: =IF(B18="","",CONCATENATE(B18,D18)) -> LLC TRİTONMUTLUKAL WHEAT TORTILLA
A19: 16. | B19: LLC TRİTON | C19: =IF(B19="","",VLOOKUP(AB19,Varsayımlar!$B:$Q,3,0)) -> 8698829380698 | D19: MUTLUKAL WHEAT TORTILLA | E19: KB-006582 | F19: ZPO-020470 | G19: =IF(B19="","",VLOOKUP(AB19,Varsayımlar!$B:$Q,5,0)) -> TORTİLLAS 25 CM 4 PCS 260G | I19: =IF(B19="","",VLOOKUP(AB19,Varsayımlar!$B:$Q,6,0)) -> SADE | J19: 1848 | L19: =J19/84 -> 22 | O19: =IF(B19="","",VLOOKUP(AB19,Varsayımlar!$B:$Q,7,0)*J19) -> 55440 | P19: =IF(B19="","",VLOOKUP(AB19,Varsayımlar!$B:$Q,8,0)) -> 25 | Q19: =IF(B19="","",VLOOKUP(AB19,Varsayımlar!$B:$Q,9,0)) -> SOFT | R19: =IF(B19="","",VLOOKUP(AB19,Varsayımlar!$B:$Q,10,0)) -> 4 | S19: =IF(B19="","",VLOOKUP(AB19,Varsayımlar!$B:$Q,11,0)) -> 30 | T19: =IF(B19="","",VLOOKUP(AB19,Varsayımlar!$B:$Q,12,0)) -> 260 | U19: =IF(B19="","",VLOOKUP(AB19,Varsayımlar!$B:$Q,13,0)) -> YURTDIŞI | V19: =IF(B19="","",VLOOKUP(AB19,Varsayımlar!$B:$Q,14,0)) -> 6 | W19: 46178 | X19: 46361 | Y19: 26060525 | Z19: =IF(B19="","",VLOOKUP(AB19,Varsayımlar!$B:$Q,15,0)) -> TRİTON -SKT ATILACAK | AA19: =IF(B19="","",VLOOKUP(AB19,Varsayımlar!$B:$Q,16,0)) -> 24-26 CM | AB19: =IF(B19="","",CONCATENATE(B19,D19)) -> LLC TRİTONMUTLUKAL WHEAT TORTILLA
C20: =IF(B20="","",VLOOKUP(AB20,Varsayımlar!$B:$Q,3,0)) | G20: =IF(B20="","",VLOOKUP(AB20,Varsayımlar!$B:$Q,5,0)) | I20: =IF(B20="","",VLOOKUP(AB20,Varsayımlar!$B:$Q,6,0)) | O20: =IF(B20="","",VLOOKUP(AB20,Varsayımlar!$B:$Q,7,0)*J20) | P20: =IF(B20="","",VLOOKUP(AB20,Varsayımlar!$B:$Q,8,0)) | Q20: =IF(B20="","",VLOOKUP(AB20,Varsayımlar!$B:$Q,9,0)) | R20: =IF(B20="","",VLOOKUP(AB20,Varsayımlar!$B:$Q,10,0)) | S20: =IF(B20="","",VLOOKUP(AB20,Varsayımlar!$B:$Q,11,0)) | T20: =IF(B20="","",VLOOKUP(AB20,Varsayımlar!$B:$Q,12,0)) | U20: =IF(B20="","",VLOOKUP(AB20,Varsayımlar!$B:$Q,13,0)) | V20: =IF(B20="","",VLOOKUP(AB20,Varsayımlar!$B:$Q,14,0)) | Z20: =IF(B20="","",VLOOKUP(AB20,Varsayımlar!$B:$Q,15,0)) | AA20: =IF(B20="","",VLOOKUP(AB20,Varsayımlar!$B:$Q,16,0)) | AB20: =IF(B20="","",CONCATENATE(B20,D20))
A21: 9. | B21: MAYDONOZ DÖNER | C21: =IF(B21="","",VLOOKUP(AB21,Varsayımlar!$B:$Q,3,0)) -> 8698829380698 | D21: Mutlukal Tortillas 15cm 250g | G21: =IF(B21="","",VLOOKUP(AB21,Varsayımlar!$B:$Q,5,0)) -> Mutlukal Tortillas 15cm | I21: =IF(B21="","",VLOOKUP(AB21,Varsayımlar!$B:$Q,6,0)) -> SADE | J21: 3168 | L21: =J21/96 -> 33 | O21: =IF(B21="","",VLOOKUP(AB21,Varsayımlar!$B:$Q,7,0)*J21) -> 31680 | P21: =IF(B21="","",VLOOKUP(AB21,Varsayımlar!$B:$Q,8,0)) -> 12 | Q21: =IF(B21="","",VLOOKUP(AB21,Varsayımlar!$B:$Q,9,0)) -> IRAK SOFT | R21: =IF(B21="","",VLOOKUP(AB21,Varsayımlar!$B:$Q,10,0)) -> 10 | S21: =IF(B21="","",VLOOKUP(AB21,Varsayımlar!$B:$Q,11,0)) -> 12 | T21: =IF(B21="","",VLOOKUP(AB21,Varsayımlar!$B:$Q,12,0)) -> 250 | U21: =IF(B21="","",VLOOKUP(AB21,Varsayımlar!$B:$Q,13,0)) -> YURTİÇİ | V21: =IF(B21="","",VLOOKUP(AB21,Varsayımlar!$B:$Q,14,0)) -> 6 | Z21: =IF(B21="","",VLOOKUP(AB21,Varsayımlar!$B:$Q,15,0)) -> 15CM KOLİ | AA21: =IF(B21="","",VLOOKUP(AB21,Varsayımlar!$B:$Q,16,0)) -> KESME-33-35G BEZE, KESİLMEMİŞ 16-18CM, 320-330G- KESİLMİŞ 245-250G | AB21: =IF(B21="","",CONCATENATE(B21,D21)) -> MAYDONOZ DÖNERMutlukal Tortillas 15cm 250g
A22: 9. | B22: MAYDONOZ DÖNER | C22: =IF(B22="","",VLOOKUP(AB22,Varsayımlar!$B:$Q,3,0)) -> 8698829380698 | D22: Mutlukal Tortillas 15cm 250g | G22: =IF(B22="","",VLOOKUP(AB22,Varsayımlar!$B:$Q,5,0)) -> Mutlukal Tortillas 15cm | I22: =IF(B22="","",VLOOKUP(AB22,Varsayımlar!$B:$Q,6,0)) -> SADE | J22: 3168 | L22: =J22/96 -> 33 | O22: =IF(B22="","",VLOOKUP(AB22,Varsayımlar!$B:$Q,7,0)*J22) -> 31680 | P22: =IF(B22="","",VLOOKUP(AB22,Varsayımlar!$B:$Q,8,0)) -> 12 | Q22: =IF(B22="","",VLOOKUP(AB22,Varsayımlar!$B:$Q,9,0)) -> IRAK SOFT | R22: =IF(B22="","",VLOOKUP(AB22,Varsayımlar!$B:$Q,10,0)) -> 10 | S22: =IF(B22="","",VLOOKUP(AB22,Varsayımlar!$B:$Q,11,0)) -> 12 | T22: =IF(B22="","",VLOOKUP(AB22,Varsayımlar!$B:$Q,12,0)) -> 250 | U22: =IF(B22="","",VLOOKUP(AB22,Varsayımlar!$B:$Q,13,0)) -> YURTİÇİ | V22: =IF(B22="","",VLOOKUP(AB22,Varsayımlar!$B:$Q,14,0)) -> 6 | Z22: =IF(B22="","",VLOOKUP(AB22,Varsayımlar!$B:$Q,15,0)) -> 15CM KOLİ | AA22: =IF(B22="","",VLOOKUP(AB22,Varsayımlar!$B:$Q,16,0)) -> KESME-33-35G BEZE, KESİLMEMİŞ 16-18CM, 320-330G- KESİLMİŞ 245-250G | AB22: =IF(B22="","",CONCATENATE(B22,D22)) -> MAYDONOZ DÖNERMutlukal Tortillas 15cm 250g
A23: MAKİNE 5
A24: SIRA | B24: FİRMA | C24: GTIN KODU | D24: PRODUCT NAME / ÜRÜN ADI | E24: ORDER NUMBER / SİPARİŞ NUMARASI | F24: KAREKOD DOSYA ADI | G24: AMBALAJ | H24: AMBALAJ ETİKETİ | I24: CİNSİ | J24: ÜRETİLECEK MİKTAR/ KOLİ | K24: DEPO STOK / KOLİ | L24: ÜRETİLECEK MİKTAR/ PALET | O24: AMBALAJ MİKTAR | P24: ÇAP | Q24: FORMÜL | R24: PAKET İÇİ | S24: KOLİ İÇİ | T24: PAKET GRAMAJI | U24: TARİH | V24: SKT/AY | W24: ÜRT/PRD | X24: TETT/EXP | Y24: PRT/LOT | Z24: KOLİ / TARİH | AA24: AÇIKLAMALAR | AB24: Birleştir
A25: 1. | B25: LLC TRİTON | C25: =IF(B25="","",VLOOKUP(AB25,Varsayımlar!$B:$Q,3,0)) -> 8698829380698 | D25: MUTLUKAL WHEAT TORTILLA | E25: KB-006496 | F25: Z180013769 | G25: =IF(B25="","",VLOOKUP(AB25,Varsayımlar!$B:$Q,5,0)) -> TORTİLLAS 25 CM 4 PCS 260G | I25: =IF(B25="","",VLOOKUP(AB25,Varsayımlar!$B:$Q,6,0)) -> SADE | J25: 1092 | K25: 504 | L25: =J25/84 -> 13 | O25: =IF(B25="","",VLOOKUP(AB25,Varsayımlar!$B:$Q,7,0)*J25) -> 32760 | P25: =IF(B25="","",VLOOKUP(AB25,Varsayımlar!$B:$Q,8,0)) -> 25 | Q25: =IF(B25="","",VLOOKUP(AB25,Varsayımlar!$B:$Q,9,0)) -> SOFT | R25: =IF(B25="","",VLOOKUP(AB25,Varsayımlar!$B:$Q,10,0)) -> 4 | S25: =IF(B25="","",VLOOKUP(AB25,Varsayımlar!$B:$Q,11,0)) -> 30 | T25: =IF(B25="","",VLOOKUP(AB25,Varsayımlar!$B:$Q,12,0)) -> 260 | U25: =IF(B25="","",VLOOKUP(AB25,Varsayımlar!$B:$Q,13,0)) -> YURTDIŞI | V25: =IF(B25="","",VLOOKUP(AB25,Varsayımlar!$B:$Q,14,0)) -> 6 | W25: 46175 | X25: 46358 | Y25: 26060225-2 | Z25: =IF(B25="","",VLOOKUP(AB25,Varsayımlar!$B:$Q,15,0)) -> TRİTON -SKT ATILACAK | AA25: =IF(B25="","",VLOOKUP(AB25,Varsayımlar!$B:$Q,16,0)) -> 24-26 CM | AB25: =IF(B25="","",CONCATENATE(B25,D25)) -> LLC TRİTONMUTLUKAL WHEAT TORTILLA
A26: 2. | B26: LLC TRİTON | C26: =IF(B26="","",VLOOKUP(AB26,Varsayımlar!$B:$Q,3,0)) -> 8698829380698 | D26: MUTLUKAL WHEAT TORTILLA | E26: KB-006496 | F26: ZP8-014855 | G26: =IF(B26="","",VLOOKUP(AB26,Varsayımlar!$B:$Q,5,0)) -> TORTİLLAS 25 CM 4 PCS 260G | I26: =IF(B26="","",VLOOKUP(AB26,Varsayımlar!$B:$Q,6,0)) -> SADE | J26: 1344 | K26: 683 | L26: =J26/84 -> 16 | O26: =IF(B26="","",VLOOKUP(AB26,Varsayımlar!$B:$Q,7,0)*J26) -> 40320 | P26: =IF(B26="","",VLOOKUP(AB26,Varsayımlar!$B:$Q,8,0)) -> 25 | Q26: =IF(B26="","",VLOOKUP(AB26,Varsayımlar!$B:$Q,9,0)) -> SOFT | R26: =IF(B26="","",VLOOKUP(AB26,Varsayımlar!$B:$Q,10,0)) -> 4 | S26: =IF(B26="","",VLOOKUP(AB26,Varsayımlar!$B:$Q,11,0)) -> 30 | T26: =IF(B26="","",VLOOKUP(AB26,Varsayımlar!$B:$Q,12,0)) -> 260 | U26: =IF(B26="","",VLOOKUP(AB26,Varsayımlar!$B:$Q,13,0)) -> YURTDIŞI | V26: =IF(B26="","",VLOOKUP(AB26,Varsayımlar!$B:$Q,14,0)) -> 6 | W26: 46175 | X26: 46358 | Y26: 26060225-2 | Z26: =IF(B26="","",VLOOKUP(AB26,Varsayımlar!$B:$Q,15,0)) -> TRİTON -SKT ATILACAK | AA26: =IF(B26="","",VLOOKUP(AB26,Varsayımlar!$B:$Q,16,0)) -> 24-26 CM | AB26: =IF(B26="","",CONCATENATE(B26,D26)) -> LLC TRİTONMUTLUKAL WHEAT TORTILLA
A27: 3. | B27: LLC KOTOR | C27: =IF(B27="","",VLOOKUP(AB27,Varsayımlar!$B:$Q,3,0)) -> 8698829380698 | D27: MANETKA PEYNİRLİ 25CM | E27: 04620478612503 (76377) | F27: 04620478612503 (76377) PEYNİRLİ 25CM | G27: =IF(B27="","",VLOOKUP(AB27,Varsayımlar!$B:$Q,5,0)) -> MANETKA PEYNİRLİ 25 CM | I27: =IF(B27="","",VLOOKUP(AB27,Varsayımlar!$B:$Q,6,0)) -> PEYNİRLİ | J27: 2496 | L27: =J27/78 -> 32 | O27: =IF(B27="","",VLOOKUP(AB27,Varsayımlar!$B:$Q,7,0)*J27) -> 74880 | P27: =IF(B27="","",VLOOKUP(AB27,Varsayımlar!$B:$Q,8,0)) -> 25 | Q27: =IF(B27="","",VLOOKUP(AB27,Varsayımlar!$B:$Q,9,0)) -> SOFT-AT | R27: =IF(B27="","",VLOOKUP(AB27,Varsayımlar!$B:$Q,10,0)) -> 4 | S27: =IF(B27="","",VLOOKUP(AB27,Varsayımlar!$B:$Q,11,0)) -> 30 | T27: =IF(B27="","",VLOOKUP(AB27,Varsayımlar!$B:$Q,12,0)) -> 250 | U27: =IF(B27="","",VLOOKUP(AB27,Varsayımlar!$B:$Q,13,0)) -> YURTDIŞI | V27: =IF(B27="","",VLOOKUP(AB27,Varsayımlar!$B:$Q,14,0)) -> 6 | W27: 46182 | X27: 46365 | Y27: 26060925P | Z27: =IF(B27="","",VLOOKUP(AB27,Varsayımlar!$B:$Q,15,0)) -> KIRMIZI KOLİ-TARİHLİ KOLİ ETİKETİ | AA27: =IF(B27="","",VLOOKUP(AB27,Varsayımlar!$B:$Q,16,0)) -> 24-26 CM | AB27: =IF(B27="","",CONCATENATE(B27,D27)) -> LLC KOTORMANETKA PEYNİRLİ 25CM
A28: 4. | B28: MAGNİT | C28: =IF(B28="","",VLOOKUP(AB28,Varsayımlar!$B:$Q,3,0)) -> 8698829380698 | D28: MAGNİT MAVİ AMBALAJ 25 CM 260G | G28: =IF(B28="","",VLOOKUP(AB28,Varsayımlar!$B:$Q,5,0)) -> MAGNİT MAVİ AMBALAJ 25CM | I28: =IF(B28="","",VLOOKUP(AB28,Varsayımlar!$B:$Q,6,0)) -> SADE | J28: 2016 | L28: =2016/84 -> 24 | O28: =IF(B28="","",VLOOKUP(AB28,Varsayımlar!$B:$Q,7,0)*J28) -> 60480 | P28: =IF(B28="","",VLOOKUP(AB28,Varsayımlar!$B:$Q,8,0)) -> 25 | Q28: =IF(B28="","",VLOOKUP(AB28,Varsayımlar!$B:$Q,9,0)) -> SOFT | R28: =IF(B28="","",VLOOKUP(AB28,Varsayımlar!$B:$Q,10,0)) -> 4 | S28: =IF(B28="","",VLOOKUP(AB28,Varsayımlar!$B:$Q,11,0)) -> 30 | T28: =IF(B28="","",VLOOKUP(AB28,Varsayımlar!$B:$Q,12,0)) -> 260 | U28: =IF(B28="","",VLOOKUP(AB28,Varsayımlar!$B:$Q,13,0)) -> YURTDIŞI | V28: =IF(B28="","",VLOOKUP(AB28,Varsayımlar!$B:$Q,14,0)) -> 9 | Z28: =IF(B28="","",VLOOKUP(AB28,Varsayımlar!$B:$Q,15,0)) -> 25CM TURUNCU KOLİ-SOL ÜST DİKDÖRTGENE ÜRETİM TARİHİ BASILACAK | AA28: =IF(B28="","",VLOOKUP(AB28,Varsayımlar!$B:$Q,16,0)) -> 24-26 CM | AB28: =IF(B28="","",CONCATENATE(B28,D28)) -> MAGNİTMAGNİT MAVİ AMBALAJ 25 CM 260G
C29: =IF(B29="","",VLOOKUP(AB29,Varsayımlar!$B:$Q,3,0)) | G29: =IF(B29="","",VLOOKUP(AB29,Varsayımlar!$B:$Q,5,0)) | I29: =IF(B29="","",VLOOKUP(AB29,Varsayımlar!$B:$Q,6,0)) | O29: =IF(B29="","",VLOOKUP(AB29,Varsayımlar!$B:$Q,7,0)*J29) | P29: =IF(B29="","",VLOOKUP(AB29,Varsayımlar!$B:$Q,8,0)) | Q29: =IF(B29="","",VLOOKUP(AB29,Varsayımlar!$B:$Q,9,0)) | R29: =IF(B29="","",VLOOKUP(AB29,Varsayımlar!$B:$Q,10,0)) | S29: =IF(B29="","",VLOOKUP(AB29,Varsayımlar!$B:$Q,11,0)) | T29: =IF(B29="","",VLOOKUP(AB29,Varsayımlar!$B:$Q,12,0)) | U29: =IF(B29="","",VLOOKUP(AB29,Varsayımlar!$B:$Q,13,0)) | V29: =IF(B29="","",VLOOKUP(AB29,Varsayımlar!$B:$Q,14,0)) | Z29: =IF(B29="","",VLOOKUP(AB29,Varsayımlar!$B:$Q,15,0)) | AA29: =IF(B29="","",VLOOKUP(AB29,Varsayımlar!$B:$Q,16,0)) | AB29: =IF(B29="","",CONCATENATE(B29,D29))
A30: MAKİNE 6
A31: SIRA | B31: FİRMA | C31: GTIN KODU | D31: PRODUCT NAME / ÜRÜN ADI | E31: ORDER NUMBER / SİPARİŞ NUMARASI | F31: KAREKOD DOSYA ADI | G31: AMBALAJ | H31: AMBALAJ ETİKETİ | I31: CİNSİ | J31: ÜRETİLECEK MİKTAR/ KOLİ | K31: DEPO STOK / KOLİ | L31: ÜRETİLECEK MİKTAR/ PALET | O31: AMBALAJ MİKTAR | P31: ÇAP | Q31: FORMÜL | R31: PAKET İÇİ | S31: KOLİ İÇİ | T31: PAKET GRAMAJI | U31: TARİH | V31: SKT/AY | W31: ÜRT/PRD | X31: TETT/EXP | Y31: PRT/LOT | Z31: KOLİ / TARİH | AA31: AÇIKLAMALAR | AB31: Birleştir
A32: 1. | B32: GERMES | C32: =IF(B32="","",VLOOKUP(AB32,Varsayımlar!$B:$Q,3,0)) -> 8698829380698 | D32: HANAMİ PEYNİRLİ 25 CM 250G | E32: 46 | F32: 46-HANAMİ GERMES PEYNİRLİ 25CM 250G | G32: =IF(B32="","",VLOOKUP(AB32,Varsayımlar!$B:$Q,5,0)) -> HANAMİ PEYNİRLİ 25CM AMBALAJ (098) | I32: =IF(B32="","",VLOOKUP(AB32,Varsayımlar!$B:$Q,6,0)) -> PEYNİRLİ | J32: 504 | L32: =J32/84 -> 6 | O32: =IF(B32="","",VLOOKUP(AB32,Varsayımlar!$B:$Q,7,0)*J32) -> 15120 | P32: =IF(B32="","",VLOOKUP(AB32,Varsayımlar!$B:$Q,8,0)) -> 25 | Q32: =IF(B32="","",VLOOKUP(AB32,Varsayımlar!$B:$Q,9,0)) -> IRAK SOFT-AT | R32: =IF(B32="","",VLOOKUP(AB32,Varsayımlar!$B:$Q,10,0)) -> 4 | S32: =IF(B32="","",VLOOKUP(AB32,Varsayımlar!$B:$Q,11,0)) -> 30 | T32: =IF(B32="","",VLOOKUP(AB32,Varsayımlar!$B:$Q,12,0)) -> 250 | U32: =IF(B32="","",VLOOKUP(AB32,Varsayımlar!$B:$Q,13,0)) -> YURTDIŞI | V32: =IF(B32="","",VLOOKUP(AB32,Varsayımlar!$B:$Q,14,0)) -> 9 | W32: 46181 | X32: 46454 | Y32: 26060825P | Z32: =IF(B32="","",VLOOKUP(AB32,Varsayımlar!$B:$Q,15,0)) -> HANAMİ SARI KOLİ-ÜRETİM TARİHİ BASILACAK | AA32: =IF(B32="","",VLOOKUP(AB32,Varsayımlar!$B:$Q,16,0)) -> 24-26 CM | AB32: =IF(B32="","",CONCATENATE(B32,D32)) -> GERMESHANAMİ PEYNİRLİ 25 CM 250G | AC32: BİTTİ
A33: 2. | B33: GERMES | C33: =IF(B33="","",VLOOKUP(AB33,Varsayımlar!$B:$Q,3,0)) -> 8698829380698 | D33: HANAMİ GERMES 25CM SADE 250G | E33: 45 | F33: 45-HANAMİ GERMES 25CM 250G | G33: =IF(B33="","",VLOOKUP(AB33,Varsayımlar!$B:$Q,5,0)) -> HANAMİ 25 CM SADE (081) | I33: =IF(B33="","",VLOOKUP(AB33,Varsayımlar!$B:$Q,6,0)) -> SADE | J33: 756 | L33: =J33/84 -> 9 | O33: =IF(B33="","",VLOOKUP(AB33,Varsayımlar!$B:$Q,7,0)*J33) -> 22680 | P33: =IF(B33="","",VLOOKUP(AB33,Varsayımlar!$B:$Q,8,0)) -> 25 | Q33: =IF(B33="","",VLOOKUP(AB33,Varsayımlar!$B:$Q,9,0)) -> IRAK SOFT | R33: =IF(B33="","",VLOOKUP(AB33,Varsayımlar!$B:$Q,10,0)) -> 4 | S33: =IF(B33="","",VLOOKUP(AB33,Varsayımlar!$B:$Q,11,0)) -> 30 | T33: =IF(B33="","",VLOOKUP(AB33,Varsayımlar!$B:$Q,12,0)) -> 250 | U33: =IF(B33="","",VLOOKUP(AB33,Varsayımlar!$B:$Q,13,0)) -> YURTDIŞI | V33: =IF(B33="","",VLOOKUP(AB33,Varsayımlar!$B:$Q,14,0)) -> 9 | W33: 46174 | X33: 46447 | Y33: 26060125 | Z33: =IF(B33="","",VLOOKUP(AB33,Varsayımlar!$B:$Q,15,0)) -> HANAMİ MAVİ - ÜRETİM ATILACAK | AA33: =IF(B33="","",VLOOKUP(AB33,Varsayımlar!$B:$Q,16,0)) -> 24-26 CM | AB33: =IF(B33="","",CONCATENATE(B33,D33)) -> GERMESHANAMİ GERMES 25CM SADE 250G
A34: 3. | B34: GERMES | C34: =IF(B34="","",VLOOKUP(AB34,Varsayımlar!$B:$Q,3,0)) -> 8698829380698 | D34: Kırmızı Tortillas-Germes-25cm 375g | E34: 45 | F34: 45-Kırmızı Tortillas-Germes-25cm 375g | G34: =IF(B34="","",VLOOKUP(AB34,Varsayımlar!$B:$Q,5,0)) -> KIRMIZI TORTİLLAS 25 CM | I34: =IF(B34="","",VLOOKUP(AB34,Varsayımlar!$B:$Q,6,0)) -> SADE | J34: 84 | L34: =J34/84 -> 1 | O34: =IF(B34="","",VLOOKUP(AB34,Varsayımlar!$B:$Q,7,0)*J34) -> 1512 | P34: =IF(B34="","",VLOOKUP(AB34,Varsayımlar!$B:$Q,8,0)) -> 25 | Q34: =IF(B34="","",VLOOKUP(AB34,Varsayımlar!$B:$Q,9,0)) -> IRAK SOFT | R34: =IF(B34="","",VLOOKUP(AB34,Varsayımlar!$B:$Q,10,0)) -> 6 | S34: =IF(B34="","",VLOOKUP(AB34,Varsayımlar!$B:$Q,11,0)) -> 18 | T34: =IF(B34="","",VLOOKUP(AB34,Varsayımlar!$B:$Q,12,0)) -> 375 | U34: =IF(B34="","",VLOOKUP(AB34,Varsayımlar!$B:$Q,13,0)) -> YURTDIŞI | V34: =IF(B34="","",VLOOKUP(AB34,Varsayımlar!$B:$Q,14,0)) -> 9 | W34: 46174 | X34: 46447 | Y34: 26060125 | Z34: =IF(B34="","",VLOOKUP(AB34,Varsayımlar!$B:$Q,15,0)) -> KIRMIZI - ÜRETİM TARİHLİ ETİKET | AA34: =IF(B34="","",VLOOKUP(AB34,Varsayımlar!$B:$Q,16,0)) -> 24-26 CM | AB34: =IF(B34="","",CONCATENATE(B34,D34)) -> GERMESKırmızı Tortillas-Germes-25cm 375g
A35: 4. | B35: SMART LLC | C35: =IF(B35="","",VLOOKUP(AB35,Varsayımlar!$B:$Q,3,0)) -> 8698829380698 | D35: TORTİLLAS SAMAKAT 20CM 166G | F35: KAREKODSUZ ÜRETİLECEK | G35: =IF(B35="","",VLOOKUP(AB35,Varsayımlar!$B:$Q,5,0)) -> TORTİLLAS 20CM (SAMAKAT BİLGİLERİ EKLİ) | I35: =IF(B35="","",VLOOKUP(AB35,Varsayımlar!$B:$Q,6,0)) -> SADE | J35: 2475 | L35: =J35/225 -> 11 | O35: =IF(B35="","",VLOOKUP(AB35,Varsayımlar!$B:$Q,7,0)*J35) -> 34650 | P35: =IF(B35="","",VLOOKUP(AB35,Varsayımlar!$B:$Q,8,0)) -> 20 | Q35: =IF(B35="","",VLOOKUP(AB35,Varsayımlar!$B:$Q,9,0)) -> IRAK SOFT | R35: =IF(B35="","",VLOOKUP(AB35,Varsayımlar!$B:$Q,10,0)) -> 4 | S35: =IF(B35="","",VLOOKUP(AB35,Varsayımlar!$B:$Q,11,0)) -> 14 | T35: =IF(B35="","",VLOOKUP(AB35,Varsayımlar!$B:$Q,12,0)) -> 166 | U35: =IF(B35="","",VLOOKUP(AB35,Varsayımlar!$B:$Q,13,0)) -> YURTDIŞI | V35: =IF(B35="","",VLOOKUP(AB35,Varsayımlar!$B:$Q,14,0)) -> 9 | W35: 46174 | X35: 46447 | Y35: 26060120 | Z35: =IF(B35="","",VLOOKUP(AB35,Varsayımlar!$B:$Q,15,0)) -> SİYAH KARE KOLİ- Üretim Tarihi Etiketli | AA35: =IF(B35="","",VLOOKUP(AB35,Varsayımlar!$B:$Q,16,0)) -> 19-21 CM | AB35: =IF(B35="","",CONCATENATE(B35,D35)) -> SMART LLCTORTİLLAS SAMAKAT 20CM 166G
A36: 5. | B36: LLC TRİTON | C36: =IF(B36="","",VLOOKUP(AB36,Varsayımlar!$B:$Q,3,0)) -> 8698829380698 | D36: MUTLUKAL WHEAT TORTILLA | E36: KB-006501 | F36: ZPM-015047 | G36: =IF(B36="","",VLOOKUP(AB36,Varsayımlar!$B:$Q,5,0)) -> TORTİLLAS 25 CM 4 PCS 260G | I36: =IF(B36="","",VLOOKUP(AB36,Varsayımlar!$B:$Q,6,0)) -> SADE | J36: 2016 | L36: =J36/84 -> 24 | O36: =IF(B36="","",VLOOKUP(AB36,Varsayımlar!$B:$Q,7,0)*J36) -> 60480 | P36: =IF(B36="","",VLOOKUP(AB36,Varsayımlar!$B:$Q,8,0)) -> 25 | Q36: =IF(B36="","",VLOOKUP(AB36,Varsayımlar!$B:$Q,9,0)) -> SOFT | R36: =IF(B36="","",VLOOKUP(AB36,Varsayımlar!$B:$Q,10,0)) -> 4 | S36: =IF(B36="","",VLOOKUP(AB36,Varsayımlar!$B:$Q,11,0)) -> 30 | T36: =IF(B36="","",VLOOKUP(AB36,Varsayımlar!$B:$Q,12,0)) -> 260 | U36: =IF(B36="","",VLOOKUP(AB36,Varsayımlar!$B:$Q,13,0)) -> YURTDIŞI | V36: =IF(B36="","",VLOOKUP(AB36,Varsayımlar!$B:$Q,14,0)) -> 6 | W36: 46176 | X36: 46359 | Y36: 26060325-2 | Z36: =IF(B36="","",VLOOKUP(AB36,Varsayımlar!$B:$Q,15,0)) -> TRİTON -SKT ATILACAK | AA36: =IF(B36="","",VLOOKUP(AB36,Varsayımlar!$B:$Q,16,0)) -> 24-26 CM | AB36: =IF(B36="","",CONCATENATE(B36,D36)) -> LLC TRİTONMUTLUKAL WHEAT TORTILLA
A37: 6. | B37: LLC TRİTON | C37: =IF(B37="","",VLOOKUP(AB37,Varsayımlar!$B:$Q,3,0)) -> 8698829380698 | D37: MUTLUKAL WHEAT TORTILLA | E37: KB-006501 | F37: Z13-007146 | G37: =IF(B37="","",VLOOKUP(AB37,Varsayımlar!$B:$Q,5,0)) -> TORTİLLAS 25 CM 4 PCS 260G | I37: =IF(B37="","",VLOOKUP(AB37,Varsayımlar!$B:$Q,6,0)) -> SADE | J37: 420 | L37: =J37/84 -> 5 | O37: =IF(B37="","",VLOOKUP(AB37,Varsayımlar!$B:$Q,7,0)*J37) -> 12600 | P37: =IF(B37="","",VLOOKUP(AB37,Varsayımlar!$B:$Q,8,0)) -> 25 | Q37: =IF(B37="","",VLOOKUP(AB37,Varsayımlar!$B:$Q,9,0)) -> SOFT | R37: =IF(B37="","",VLOOKUP(AB37,Varsayımlar!$B:$Q,10,0)) -> 4 | S37: =IF(B37="","",VLOOKUP(AB37,Varsayımlar!$B:$Q,11,0)) -> 30 | T37: =IF(B37="","",VLOOKUP(AB37,Varsayımlar!$B:$Q,12,0)) -> 260 | U37: =IF(B37="","",VLOOKUP(AB37,Varsayımlar!$B:$Q,13,0)) -> YURTDIŞI | V37: =IF(B37="","",VLOOKUP(AB37,Varsayımlar!$B:$Q,14,0)) -> 6 | W37: 46176 | X37: 46359 | Y37: 26060325-2 | Z37: =IF(B37="","",VLOOKUP(AB37,Varsayımlar!$B:$Q,15,0)) -> TRİTON -SKT ATILACAK | AA37: =IF(B37="","",VLOOKUP(AB37,Varsayımlar!$B:$Q,16,0)) -> 24-26 CM | AB37: =IF(B37="","",CONCATENATE(B37,D37)) -> LLC TRİTONMUTLUKAL WHEAT TORTILLA
A38: 7. | B38: SMART LLC | C38: =IF(B38="","",VLOOKUP(AB38,Varsayımlar!$B:$Q,3,0)) -> 8698829380698 | D38: TORTİLLAS SAMAKAT 20CM 166G | F38: KAREKODSUZ ÜRETİLECEK | G38: =IF(B38="","",VLOOKUP(AB38,Varsayımlar!$B:$Q,5,0)) -> TORTİLLAS 20CM (SAMAKAT BİLGİLERİ EKLİ) | I38: =IF(B38="","",VLOOKUP(AB38,Varsayımlar!$B:$Q,6,0)) -> SADE | J38: 2475 | L38: =J38/225 -> 11 | O38: =IF(B38="","",VLOOKUP(AB38,Varsayımlar!$B:$Q,7,0)*J38) -> 34650 | P38: =IF(B38="","",VLOOKUP(AB38,Varsayımlar!$B:$Q,8,0)) -> 20 | Q38: =IF(B38="","",VLOOKUP(AB38,Varsayımlar!$B:$Q,9,0)) -> IRAK SOFT | R38: =IF(B38="","",VLOOKUP(AB38,Varsayımlar!$B:$Q,10,0)) -> 4 | S38: =IF(B38="","",VLOOKUP(AB38,Varsayımlar!$B:$Q,11,0)) -> 14 | T38: =IF(B38="","",VLOOKUP(AB38,Varsayımlar!$B:$Q,12,0)) -> 166 | U38: =IF(B38="","",VLOOKUP(AB38,Varsayımlar!$B:$Q,13,0)) -> YURTDIŞI | V38: =IF(B38="","",VLOOKUP(AB38,Varsayımlar!$B:$Q,14,0)) -> 9 | W38: 46181 | X38: 46454 | Y38: 26060820 | Z38: =IF(B38="","",VLOOKUP(AB38,Varsayımlar!$B:$Q,15,0)) -> SİYAH KARE KOLİ- Üretim Tarihi Etiketli | AA38: =IF(B38="","",VLOOKUP(AB38,Varsayımlar!$B:$Q,16,0)) -> 19-21 CM | AB38: =IF(B38="","",CONCATENATE(B38,D38)) -> SMART LLCTORTİLLAS SAMAKAT 20CM 166G
A39: 8. | B39: LLC KOTOR | C39: =IF(B39="","",VLOOKUP(AB39,Varsayımlar!$B:$Q,3,0)) -> 8698829380698 | D39: MANETKA SADE 20CM 166G | E39: 04620478612497-1 | F39: 04620478612497-1 (100800) SADE 20CM | G39: =IF(B39="","",VLOOKUP(AB39,Varsayımlar!$B:$Q,5,0)) -> MANETKA SADE 20CM 166G | I39: =IF(B39="","",VLOOKUP(AB39,Varsayımlar!$B:$Q,6,0)) -> SADE | J39: 7200 | L39: =J39/225 -> 32 | O39: =IF(B39="","",VLOOKUP(AB39,Varsayımlar!$B:$Q,7,0)*J39) -> 100800 | P39: =IF(B39="","",VLOOKUP(AB39,Varsayımlar!$B:$Q,8,0)) -> 20 | Q39: =IF(B39="","",VLOOKUP(AB39,Varsayımlar!$B:$Q,9,0)) -> IRAK SOFT | R39: =IF(B39="","",VLOOKUP(AB39,Varsayımlar!$B:$Q,10,0)) -> 4 | S39: =IF(B39="","",VLOOKUP(AB39,Varsayımlar!$B:$Q,11,0)) -> 14 | T39: =IF(B39="","",VLOOKUP(AB39,Varsayımlar!$B:$Q,12,0)) -> 166 | U39: =IF(B39="","",VLOOKUP(AB39,Varsayımlar!$B:$Q,13,0)) -> YURTDIŞI | V39: =IF(B39="","",VLOOKUP(AB39,Varsayımlar!$B:$Q,14,0)) -> 6 | W39: 46182 | X39: 46365 | Y39: 26060920 | Z39: =IF(B39="","",VLOOKUP(AB39,Varsayımlar!$B:$Q,15,0)) -> SİYAH KARE KOLİ-ÜRETİM TARİHLİ ETİKET | AA39: =IF(B39="","",VLOOKUP(AB39,Varsayımlar!$B:$Q,16,0)) -> 19-21 CM | AB39: =IF(B39="","",CONCATENATE(B39,D39)) -> LLC KOTORMANETKA SADE 20CM 166G
A40: 9. | B40: MAYDONOZ DÖNER | C40: =IF(B40="","",VLOOKUP(AB40,Varsayımlar!$B:$Q,3,0)) -> 8698829380698 | D40: Mutlukal Tortillas 15cm 250g | G40: =IF(B40="","",VLOOKUP(AB40,Varsayımlar!$B:$Q,5,0)) -> Mutlukal Tortillas 15cm | I40: =IF(B40="","",VLOOKUP(AB40,Varsayımlar!$B:$Q,6,0)) -> SADE | J40: 3168 | L40: =J40/96 -> 33 | O40: =IF(B40="","",VLOOKUP(AB40,Varsayımlar!$B:$Q,7,0)*J40) -> 31680 | P40: =IF(B40="","",VLOOKUP(AB40,Varsayımlar!$B:$Q,8,0)) -> 12 | Q40: =IF(B40="","",VLOOKUP(AB40,Varsayımlar!$B:$Q,9,0)) -> IRAK SOFT | R40: =IF(B40="","",VLOOKUP(AB40,Varsayımlar!$B:$Q,10,0)) -> 10 | S40: =IF(B40="","",VLOOKUP(AB40,Varsayımlar!$B:$Q,11,0)) -> 12 | T40: =IF(B40="","",VLOOKUP(AB40,Varsayımlar!$B:$Q,12,0)) -> 250 | U40: =IF(B40="","",VLOOKUP(AB40,Varsayımlar!$B:$Q,13,0)) -> YURTİÇİ | V40: =IF(B40="","",VLOOKUP(AB40,Varsayımlar!$B:$Q,14,0)) -> 6 | Z40: =IF(B40="","",VLOOKUP(AB40,Varsayımlar!$B:$Q,15,0)) -> 15CM KOLİ | AA40: =IF(B40="","",VLOOKUP(AB40,Varsayımlar!$B:$Q,16,0)) -> KESME-33-35G BEZE, KESİLMEMİŞ 16-18CM, 320-330G- KESİLMİŞ 245-250G | AB40: =IF(B40="","",CONCATENATE(B40,D40)) -> MAYDONOZ DÖNERMutlukal Tortillas 15cm 250g
...

Sheet Sayfa1
A1: MUTLUKAL İŞ EMRİ
A2: MAKİNE 1 | AA2: 46175 | AB2: 0.55208333
A3: SIRA | B3: FİRMA | C3: GTIN KODU | D3: ARAÇ SAYISI | E3: PRODUCT NAME / ÜRÜN ADI | F3: ORDER NUMBER / SİPARİŞ NUMARASI | G3: KAREKOD DOSYA ADI | H3: AMBALAJ | I3: AMBALAJ ETİKETİ | J3: CİNSİ | K3: ÜRETİLECEK MİKTAR/ KOLİ | L3: DEPO STOK / KOLİ | M3: ÜRETİLECEK MİKTAR/ PALET | N3: PALET/KOLİ | O3: SÜRE | P3: AMBALAJ MİKTAR | Q3: ÇAP | R3: FORMÜL | S3: PAKET İÇİ | T3: KOLİ İÇİ | U3: PAKET GRAMAJI | V3: TARİH | W3: SKT/AY | X3: ÜRT/PRD | Y3: TETT/EXP | Z3: PRT/LOT | AA3: KOLİ / TARİH | AB3: AÇIKLAMALAR | AC3: Birleştir
A4: 1. | B4: LLC TRİTON | C4: =IF(B4="","",VLOOKUP(AC4,Varsayımlar!$B:$Q,3,0)) -> 8698829380698 | E4: MUTLUKAL WHEAT TORTILLA | F4: KB-006321 | G4: ZP6-17971 | H4: =IF(B4="","",VLOOKUP(AC4,Varsayımlar!$B:$Q,5,0)) -> TORTİLLAS 25 CM 4 PCS 260G | J4: =IF(B4="","",VLOOKUP(AC4,Varsayımlar!$B:$Q,6,0)) -> SADE | K4: 1680 | M4: 20 | N4: 84 | P4: =IF(B4="","",VLOOKUP(AC4,Varsayımlar!$B:$Q,7,0)*K4) -> 50400 | Q4: =IF(B4="","",VLOOKUP(AC4,Varsayımlar!$B:$Q,8,0)) -> 25 | R4: =IF(B4="","",VLOOKUP(AC4,Varsayımlar!$B:$Q,9,0)) -> SOFT | S4: =IF(B4="","",VLOOKUP(AC4,Varsayımlar!$B:$Q,10,0)) -> 4 | T4: =IF(B4="","",VLOOKUP(AC4,Varsayımlar!$B:$Q,11,0)) -> 30 | U4: =IF(B4="","",VLOOKUP(AC4,Varsayımlar!$B:$Q,12,0)) -> 260 | V4: =IF(B4="","",VLOOKUP(AC4,Varsayımlar!$B:$Q,13,0)) -> YURTDIŞI | W4: =IF(B4="","",VLOOKUP(AC4,Varsayımlar!$B:$Q,14,0)) -> 6 | X4: 46176 | Y4: 46359 | Z4: 26060325-1 | AA4: =IF(B4="","",VLOOKUP(AC4,Varsayımlar!$B:$Q,15,0)) -> TRİTON -SKT ATILACAK | AB4: =IF(B4="","",VLOOKUP(AC4,Varsayımlar!$B:$Q,16,0)) -> 24-26 CM | AC4: =IF(B4="","",CONCATENATE(B4,E4)) -> LLC TRİTONMUTLUKAL WHEAT TORTILLA
A5: 2. | B5: LLC TRİTON | C5: =IF(B5="","",VLOOKUP(AC5,Varsayımlar!$B:$Q,3,0)) -> 8698829380698 | E5: MUTLUKAL WHEAT TORTILLA | F5: KB-006321 | G5: Z210006314 | H5: =IF(B5="","",VLOOKUP(AC5,Varsayımlar!$B:$Q,5,0)) -> TORTİLLAS 25 CM 4 PCS 260G | J5: =IF(B5="","",VLOOKUP(AC5,Varsayımlar!$B:$Q,6,0)) -> SADE | K5: 420 | M5: =K5/84 -> 5 | N5: 84 | P5: =IF(B5="","",VLOOKUP(AC5,Varsayımlar!$B:$Q,7,0)*K5) -> 12600 | Q5: =IF(B5="","",VLOOKUP(AC5,Varsayımlar!$B:$Q,8,0)) -> 25 | R5: =IF(B5="","",VLOOKUP(AC5,Varsayımlar!$B:$Q,9,0)) -> SOFT | S5: =IF(B5="","",VLOOKUP(AC5,Varsayımlar!$B:$Q,10,0)) -> 4 | T5: =IF(B5="","",VLOOKUP(AC5,Varsayımlar!$B:$Q,11,0)) -> 30 | U5: =IF(B5="","",VLOOKUP(AC5,Varsayımlar!$B:$Q,12,0)) -> 260 | V5: =IF(B5="","",VLOOKUP(AC5,Varsayımlar!$B:$Q,13,0)) -> YURTDIŞI | W5: =IF(B5="","",VLOOKUP(AC5,Varsayımlar!$B:$Q,14,0)) -> 6 | X5: 46176 | Y5: 46359 | Z5: 26060325-1 | AA5: =IF(B5="","",VLOOKUP(AC5,Varsayımlar!$B:$Q,15,0)) -> TRİTON -SKT ATILACAK | AB5: =IF(B5="","",VLOOKUP(AC5,Varsayımlar!$B:$Q,16,0)) -> 24-26 CM | AC5: =IF(B5="","",CONCATENATE(B5,E5)) -> LLC TRİTONMUTLUKAL WHEAT TORTILLA
A6: 3. | B6: LLC TRİTON | C6: =IF(B6="","",VLOOKUP(AC6,Varsayımlar!$B:$Q,3,0)) -> 8698829380698 | E6: MUTLUKAL WHEAT TORTILLA | F6: KB-006321 | G6: ZP3-012107 | H6: =IF(B6="","",VLOOKUP(AC6,Varsayımlar!$B:$Q,5,0)) -> TORTİLLAS 25 CM 4 PCS 260G | J6: =IF(B6="","",VLOOKUP(AC6,Varsayımlar!$B:$Q,6,0)) -> SADE | K6: 336 | M6: =K6/84 -> 4 | N6: 84 | P6: =IF(B6="","",VLOOKUP(AC6,Varsayımlar!$B:$Q,7,0)*K6) -> 10080 | Q6: =IF(B6="","",VLOOKUP(AC6,Varsayımlar!$B:$Q,8,0)) -> 25 | R6: =IF(B6="","",VLOOKUP(AC6,Varsayımlar!$B:$Q,9,0)) -> SOFT | S6: =IF(B6="","",VLOOKUP(AC6,Varsayımlar!$B:$Q,10,0)) -> 4 | T6: =IF(B6="","",VLOOKUP(AC6,Varsayımlar!$B:$Q,11,0)) -> 30 | U6: =IF(B6="","",VLOOKUP(AC6,Varsayımlar!$B:$Q,12,0)) -> 260 | V6: =IF(B6="","",VLOOKUP(AC6,Varsayımlar!$B:$Q,13,0)) -> YURTDIŞI | W6: =IF(B6="","",VLOOKUP(AC6,Varsayımlar!$B:$Q,14,0)) -> 6 | X6: 46176 | Y6: 46359 | Z6: 26060325-1 | AA6: =IF(B6="","",VLOOKUP(AC6,Varsayımlar!$B:$Q,15,0)) -> TRİTON -SKT ATILACAK | AB6: =IF(B6="","",VLOOKUP(AC6,Varsayımlar!$B:$Q,16,0)) -> 24-26 CM | AC6: =IF(B6="","",CONCATENATE(B6,E6)) -> LLC TRİTONMUTLUKAL WHEAT TORTILLA
A7: 4. | B7: LLC TRİTON | C7: =IF(B7="","",VLOOKUP(AC7,Varsayımlar!$B:$Q,3,0)) -> 8698829380698 | E7: MUTLUKAL WHEAT TORTILLA | F7: KB-006567 | G7: ZPD-012226 | H7: =IF(B7="","",VLOOKUP(AC7,Varsayımlar!$B:$Q,5,0)) -> TORTİLLAS 25 CM 4 PCS 260G | J7: =IF(B7="","",VLOOKUP(AC7,Varsayımlar!$B:$Q,6,0)) -> SADE | K7: 1680 | M7: =K7/84 -> 20 | N7: 84 | P7: =IF(B7="","",VLOOKUP(AC7,Varsayımlar!$B:$Q,7,0)*K7) -> 50400 | Q7: =IF(B7="","",VLOOKUP(AC7,Varsayımlar!$B:$Q,8,0)) -> 25 | R7: =IF(B7="","",VLOOKUP(AC7,Varsayımlar!$B:$Q,9,0)) -> SOFT | S7: =IF(B7="","",VLOOKUP(AC7,Varsayımlar!$B:$Q,10,0)) -> 4 | T7: =IF(B7="","",VLOOKUP(AC7,Varsayımlar!$B:$Q,11,0)) -> 30 | U7: =IF(B7="","",VLOOKUP(AC7,Varsayımlar!$B:$Q,12,0)) -> 260 | V7: =IF(B7="","",VLOOKUP(AC7,Varsayımlar!$B:$Q,13,0)) -> YURTDIŞI | W7: =IF(B7="","",VLOOKUP(AC7,Varsayımlar!$B:$Q,14,0)) -> 6 | X7: 46176 | Y7: 46359 | Z7: 26060325-3 | AA7: =IF(B7="","",VLOOKUP(AC7,Varsayımlar!$B:$Q,15,0)) -> TRİTON -SKT ATILACAK | AB7: =IF(B7="","",VLOOKUP(AC7,Varsayımlar!$B:$Q,16,0)) -> 24-26 CM | AC7: =IF(B7="","",CONCATENATE(B7,E7)) -> LLC TRİTONMUTLUKAL WHEAT TORTILLA
