Workbook

Sheet Varsayımlar
B3: Birleştir | C3: Firma | D3: GTIN Kodu | E3: PRODUCT NAME / ÜRÜN ADI | F3: AMBALAJ | G3: CİNSİ | H3: Koli İçi | I3: ÇAP | J3: FORMÜL | K3: PAKET İÇİ | L3: KOLİ İÇİ | M3: PAKET GRAMAJI | N3: TARİH | O3: SKT/AY | P3: KOLİ / TARİH | Q3: AÇIKLAMALAR | R3: PALET KOLİ SAYISI | S3: PALET ÖLÇÜ | T3: AMBALAJ ETİKETİ
B4: =IF(C4="","",CONCATENATE(C4,E4)) -> LLC TRİTONMUTLUKAL WHEAT TORTILLA | C4: LLC TRİTON | D4: 8698829380698 | E4: MUTLUKAL WHEAT TORTILLA | F4: TORTİLLAS 25 CM 4 PCS 260G | G4: SADE | H4: 30 | I4: 25 | J4: SOFT | K4: 4 | L4: 30 | M4: 260 | N4: YURTDIŞI | O4: 6 | P4: TRİTON -SKT ATILACAK | Q4: 24-26 CM | R4: 84
B5: =IF(C5="","",CONCATENATE(C5,E5)) -> GERMESHANAMİ GERMES 25CM SADE 250G | C5: GERMES | D5: 8698829380698 | E5: HANAMİ GERMES 25CM SADE 250G | F5: HANAMİ 25 CM SADE (081) | G5: SADE | H5: 30 | I5: 25 | J5: IRAK SOFT | K5: 4 | L5: 30 | M5: 250 | N5: YURTDIŞI | O5: 9 | P5: HANAMİ MAVİ - ÜRETİM ATILACAK | Q5: 24-26 CM | R5: 84 | T5: Ambalaj kaç aylık kontrol?
B6: =IF(C6="","",CONCATENATE(C6,E6)) -> GERMESKırmızı Tortillas-Germes-25cm 375g | C6: GERMES | D6: 8698829380698 | E6: Kırmızı Tortillas-Germes-25cm 375g | F6: KIRMIZI TORTİLLAS 25 CM | G6: SADE | H6: 18 | I6: 25 | J6: IRAK SOFT | K6: 6 | L6: 18 | M6: 375 | N6: YURTDIŞI | O6: 9 | P6: KIRMIZI - ÜRETİM TARİHLİ ETİKET | Q6: 24-26 CM | R6: 84 | T6: BARKOD ETİKETİ
B7: =IF(C7="","",CONCATENATE(C7,E7)) -> LLC KOTORMANETKA PEYNİRLİ 25CM | C7: LLC KOTOR | D7: 8698829380698 | E7: MANETKA PEYNİRLİ 25CM | F7: MANETKA PEYNİRLİ 25 CM | G7: PEYNİRLİ | H7: 30 | I7: 25 | J7: SOFT-AT | K7: 4 | L7: 30 | M7: 250 | N7: YURTDIŞI | O7: 6 | P7: KIRMIZI KOLİ-TARİHLİ KOLİ ETİKETİ | Q7: 24-26 CM | R7: 78
B8: =IF(C8="","",CONCATENATE(C8,E8)) -> MAGNİTMAGNİT MAVİ AMBALAJ 25 CM 260G | C8: MAGNİT | D8: 8698829380698 | E8: MAGNİT MAVİ AMBALAJ 25 CM 260G | F8: MAGNİT MAVİ AMBALAJ 25CM | G8: SADE | H8: 30 | I8: 25 | J8: SOFT | K8: 4 | L8: 30 | M8: 260 | N8: YURTDIŞI | O8: 9 | P8: 25CM TURUNCU KOLİ-SOL ÜST DİKDÖRTGENE ÜRETİM TARİHİ BASILACAK | Q8: 24-26 CM | R8: 84
B9: =IF(C9="","",CONCATENATE(C9,E9)) -> GERMESHANAMİ PEYNİRLİ 25 CM 250G | C9: GERMES | D9: 8698829380698 | E9: HANAMİ PEYNİRLİ 25 CM 250G | F9: HANAMİ PEYNİRLİ 25CM AMBALAJ (098) | G9: PEYNİRLİ | H9: 30 | I9: 25 | J9: IRAK SOFT-AT | K9: 4 | L9: 30 | M9: 250 | N9: YURTDIŞI | O9: 9 | P9: HANAMİ SARI KOLİ-ÜRETİM TARİHİ BASILACAK | Q9: 24-26 CM | R9: 84 | T9: Ambalaj kaç aylık kontrol?
B10: =IF(C10="","",CONCATENATE(C10,E10)) -> SMART LLCTORTİLLAS SAMAKAT 20CM 166G | C10: SMART LLC | D10: 8698829380698 | E10: TORTİLLAS SAMAKAT 20CM 166G | F10: TORTİLLAS 20CM (SAMAKAT BİLGİLERİ EKLİ) | G10: SADE | H10: 14 | I10: 20 | J10: IRAK SOFT | K10: 4 | L10: 14 | M10: 166 | N10: YURTDIŞI | O10: 9 | P10: SİYAH KARE KOLİ- Üretim Tarihi Etiketli | Q10: 19-21 CM | R10: 225
B11: =IF(C11="","",CONCATENATE(C11,E11)) -> LLC KOTORMANETKA SADE 20CM 166G | C11: LLC KOTOR | D11: 8698829380698 | E11: MANETKA SADE 20CM 166G | F11: MANETKA SADE 20CM 166G | G11: SADE | H11: 14 | I11: 20 | J11: IRAK SOFT | K11: 4 | L11: 14 | M11: 166 | N11: YURTDIŞI | O11: 6 | P11: SİYAH KARE KOLİ-ÜRETİM TARİHLİ ETİKET | Q11: 19-21 CM | R11: 225
B12: =IF(C12="","",CONCATENATE(C12,E12)) -> Maydonoz DönerMutlukal Tortillas 15cm 250g | C12: Maydonoz Döner | D12: 8698829380698 | E12: Mutlukal Tortillas 15cm 250g | F12: Mutlukal Tortillas 15cm | G12: SADE | H12: 10 | I12: 12 | J12: IRAK SOFT | K12: 10 | L12: 12 | M12: 250 | N12: YURTİÇİ | O12: 6 | P12: 15CM KOLİ | Q12: KESME-33-35G BEZE, KESİLMEMİŞ 16-18CM, 320-330G- KESİLMİŞ 245-250G | R12: 96
B13: =IF(C13="","",CONCATENATE(C13,E13)) -> Şok MarketTaco 15 cm 6 lı 150 g | C13: Şok Market | D13: 8698829380698 | E13: Taco 15 cm 6 lı 150 g | F13: Taco 15 cm | G13: SADE | H13: 18 | I13: 15 | J13: SOFT-PA3 | K13: 6 | L13: 18 | M13: 250 | N13: YURTİÇİ | O13: 6 | P13: 15 CM KOLİ | Q13: 14-16 CM | R13: 60
B14: =IF(C14="","",CONCATENATE(C14,E14)) -> Aylin KartonHappylla 25 cm 10 lu 650g | C14: Aylin Karton | D14: 8698829380698 | E14: Happylla 25 cm 10 lu 650g | F14: Happylla 25cm (060) | G14: SADE | H14: 12 | I14: 25 | J14: Irak soft | K14: 10 | L14: 12 | M14: 650 | N14: Yurtiçi | O14: 6 | P14: Kırmızı Koli-Etiketli | Q14: 24-26 cm | R14: 50
B15: =IF(C15="","",CONCATENATE(C15,E15)) -> SMART LLCKırmızı tortillas 25cm 4 lü 250g | C15: SMART LLC | D15: 8698829380698 | E15: Kırmızı tortillas 25cm 4 lü 250g | F15: Kırmızı Tortillas 25 cm | G15: SADE | H15: 30 | I15: 25 | J15: Soft | K15: 4 | L15: 30 | M15: 250 | N15: Yurtdışı | O15: 9 | P15: Kırmızı Koli- Üretim Tarihi Etiketli | Q15: 24-26 CM | R15: 84
B16: =IF(C16="","",CONCATENATE(C16,E16)) -> Şok MarketBisto 25 cm 12 pcs 840g | C16: Şok Market | D16: 8698829380698 | E16: Bisto 25 cm 12 pcs 840g | F16: Bisto 25 cm | G16: SADE | H16: 12 | I16: 25 | J16: Standart | K16: 12 | L16: 12 | M16: 840 | N16: Yurtiçi | O16: 6 | P16: Bisto Kolisi | Q16: 24-26 Cm | R16: 48
B17: =IF(C17="","",CONCATENATE(C17,E17)) -> A101Nimet 25cm 12 pcs 840g | C17: A101 | D17: 8698829380698 | E17: Nimet 25cm 12 pcs 840g | F17: Nimet 25 cm | G17: SADE | H17: 12 | I17: 25 | J17: Standart | K17: 12 | L17: 12 | M17: 840 | N17: YURTİÇİ | O17: 5 | P17: Nimet Kolisi | Q17: 24-26 CM | R17: 50
B18: =IF(C18="","",CONCATENATE(C18,E18)) -> SultanoğluTortillove 25 cm 8pcs 520g | C18: Sultanoğlu | D18: 8698829380698 | E18: Tortillove 25 cm 8pcs 520g | F18: Tortillove 25 cm | G18: SADE | H18: 14 | I18: 25 | J18: Irak Soft | K18: 8 | L18: 14 | M18: 520 | N18: YURTİÇİ | O18: 6 | P18: Kırmızı Koli | Q18: 24-26 cm
B19: =IF(C19="","",CONCATENATE(C19,E19)) -> KopuzMutlukal Tortillas 30cm 950g | C19: Kopuz | D19: 8698829380698 | E19: Mutlukal Tortillas 30cm 950g | F19: Mutlukal tortillas 30cm | G19: SADE | H19: 12 | I19: 30 | J19: Irak Soft | K19: 10 | L19: 12 | M19: 950 | N19: Yurtiçi | O19: 6 | P19: Mavi Koli | Q19: 29-31 Cm
B20: =IF(C20="","",CONCATENATE(C20,E20)) -> GERMESHanami 20cm sade 4pcs 166g | C20: GERMES | D20: 8698829380698 | E20: Hanami 20cm sade 4pcs 166g | F20: Hanami 20cm Sade 4 pcs 166g (067) | G20: SADE | H20: 30 | I20: 20 | J20: Irak Soft | K20: 4 | L20: 30 | M20: 166 | N20: Yurtdışı | O20: 9 | P20: Hanami Mavi Koli -Üretim Tarihi+9 AYI KAPATACAK ETİKETLİ | Q20: 19-21 cm | R20: 140 | T20: Ambalaj kaç aylık kontrol?
B21: =IF(C21="","",CONCATENATE(C21,E21)) -> GERMESTortillas 20cm 4 lü 166g | C21: GERMES | D21: 8698829380698 | E21: Tortillas 20cm 4 lü 166g | F21: Tortillas 20cm (Etiketli) | G21: SADE | H21: 30 | I21: 20 | J21: Irak soft | K21: 4 | L21: 30 | M21: 166 | N21: Yurtdışı | O21: 9 | P21: 20cm Koli-Üretim Tarihli Etiket | Q21: 19-21 cm | R21: 140 | T21: Etiketli
B22: =IF(C22="","",CONCATENATE(C22,E22)) -> GERMESHanami Peynirli 20cm 4 lü 166g | C22: GERMES | D22: 8698829380698 | E22: Hanami Peynirli 20cm 4 lü 166g | F22: Hanami Peynirli 20cm (050) | G22: PEYNİRLİ | H22: 30 | I22: 20 | J22: Irak Soft-AT | K22: 4 | L22: 30 | M22: 166 | N22: YURTDIŞI | O22: 9 | P22: HANAMİ SARI KOLİ-ÜRETİM TARİHİ BASILACAK | Q22: 19-21 CM | R22: 140 | T22: Ambalaj kaç aylık kontrol?
B23: =IF(C23="","",CONCATENATE(C23,E23)) -> LLC KOTORManetka 20cm 4 pcs 166g | C23: LLC KOTOR | D23: 8698829380698 | E23: Manetka 20cm 4 pcs 166g | F23: Manetka 20cm | G23: SADE | H23: 14 | I23: 20 | J23: Irak Soft | K23: 4 | L23: 14 | M23: 166 | N23: YURTDIŞI | O23: 6 | P23: Kare Koli-Üretim Tarihli Etiket | Q23: 19-21 cm | R23: 225
B24: =IF(C24="","",CONCATENATE(C24,E24)) -> SMART LLCTortillas 20cm Peynirli 4pcs 166g | C24: SMART LLC | D24: 8698829380698 | E24: Tortillas 20cm Peynirli 4pcs 166g | F24: Tortillas 20cm (Samakat Bilgileri Ekli) | G24: PEYNİRLİ | H24: 14 | I24: 20 | J24: IRAK SOFT-AT | K24: 4 | L24: 14 | M24: 166 | N24: YURTDIŞI | O24: 9 | P24: Kare Koli-Üretim Tarihli Etiket | Q24: 19-21 cm | R24: 225
B25: =IF(C25="","",CONCATENATE(C25,E25)) -> EYALRimini 20 cm 8 pcs 360g | C25: EYAL | D25: 8698829380698 | E25: Rimini 20 cm 8 pcs 360g | F25: Rimini 20cm | G25: SADE | H25: 14 | I25: 20 | J25: Irak soft | K25: 8 | L25: 14 | M25: 360 | N25: YURTDIŞI | P25: 20cm koli-İbranice Etiket | Q25: 19-21 cm | R25: 120
B26: =IF(C26="","",CONCATENATE(C26,E26)) -> ALDİ - KOSOVATortillove 30cm 10pcs 900g | C26: ALDİ - KOSOVA | D26: 8698829380698 | E26: Tortillove 30cm 10pcs 900g | F26: Tortillove 30cm | G26: SADE | H26: 12 | I26: 30 | J26: Irak Soft | K26: 10 | L26: 12 | M26: 900 | N26: Yurtdışı | O26: 12 | P26: 30cm Koli - Tortillove 900g Etiketli | Q26: 29-31 cm | R26: 50 | T26: Arka kısma Arnavutça içerik-Tortillove
B27: =IF(C27="","",CONCATENATE(C27,E27)) -> ALDİ - KOSOVATortillas 30cm 10pcs 900g | C27: ALDİ - KOSOVA | D27: 8698829380698 | E27: Tortillas 30cm 10pcs 900g | F27: Tortillas 30cm | G27: SADE | H27: 12 | I27: 30 | J27: Irak Soft | K27: 10 | L27: 12 | M27: 900 | N27: Yurtdışı | O27: 12 | P27: 30cm Koli - Tortillas 900g Etiketli | Q27: 29-31 cm | R27: 50 | T27: Arka kısma Arnavutça içerik-Tortillas
B28: =IF(C28="","",CONCATENATE(C28,E28)) -> ALDİ - KOSOVATortillove 25cm 6pcs 390g | C28: ALDİ - KOSOVA | D28: 8698829380698 | E28: Tortillove 25cm 6pcs 390g | F28: Tortillove 25cm | G28: SADE | H28: 18 | I28: 25 | J28: Irak Soft | K28: 6 | L28: 18 | M28: 390 | N28: Yurtdışı | O28: 12 | P28: 25cm Koli - Tortillove 390g Etiketli | Q28: 24-26 cm | R28: 84 | T28: Barkod üzerine Arnavutça içerik+Barkod-Tortillove
B29: =IF(C29="","",CONCATENATE(C29,E29)) -> ALDİ - KOSOVATortillas 25cm 6pcs 390g | C29: ALDİ - KOSOVA | D29: 8698829380698 | E29: Tortillas 25cm 6pcs 390g | F29: Tortillas 25cm | G29: SADE | H29: 18 | I29: 25 | J29: Irak Soft | K29: 6 | L29: 18 | M29: 390 | N29: Yurtdışı | O29: 12 | P29: 25cm Koli - Tortillas 390g Etiketli | Q29: 24-26 cm | R29: 84 | T29: Barkod üzerine Arnavutça içerik+Barkod-Tortillas
B30: =IF(C30="","",CONCATENATE(C30,E30)) -> ALDİ - KOSOVATortillove 25cm TB 6pcs 390g | C30: ALDİ - KOSOVA | D30: 8698829380698 | E30: Tortillove 25cm TB 6pcs 390g | F30: Tortillove Tam Buğday 25cm | G30: Tam Buğdaylı | H30: 18 | I30: 25 | J30: Irak Soft | K30: 6 | L30: 18 | M30: 390 | N30: Yurtdışı | O30: 12 | P30: 25cm Koli - Tortillove 390g TB Etiketli | Q30: 24-26 cm | R30: 84 | T30: Barkod üzerine Arnavutça TB içerik+Barkod-Tortillove
B31: =IF(C31="","",CONCATENATE(C31,E31)) -> ALDİ - KOSOVATortillas 25cm TB 6pcs 390g | C31: ALDİ - KOSOVA | D31: 8698829380698 | E31: Tortillas 25cm TB 6pcs 390g | F31: Tortillas Tam Buğday 25cm | G31: Tam Buğdaylı | H31: 18 | I31: 25 | J31: Irak Soft | K31: 6 | L31: 18 | M31: 390 | N31: Yurtdışı | O31: 12 | P31: 25cm Koli - Tortillas 390g TB Etiketli | Q31: 24-26 cm | R31: 84 | T31: Barkod üzerine Arnavutça TB içerik+Barkod-Tortillas
B32: =IF(C32="","",CONCATENATE(C32,E32)) -> ALDİ - KOSOVATortillove 25cm 10pcs 650g | C32: ALDİ - KOSOVA | D32: 8698829380698 | E32: Tortillove 25cm 10pcs 650g | F32: Tortillove 25cm | G32: SADE | H32: 12 | I32: 25 | J32: Irak Soft | K32: 10 | L32: 12 | M32: 650 | N32: Yurtdışı | O32: 12 | P32: 25cm Koli - Tortillove 650g Etiketli | Q32: 24-26 cm | R32: 84 | T32: Arka kısma Arnavutça içerik-Tortillove
B33: =IF(C33="","",CONCATENATE(C33,E33)) -> ALDİ - KOSOVATortillas 25cm 10pcs 650g | C33: ALDİ - KOSOVA | D33: 8698829380698 | E33: Tortillas 25cm 10pcs 650g | F33: Tortillas 25cm | G33: SADE | H33: 12 | I33: 25 | J33: Irak Soft | K33: 10 | L33: 12 | M33: 650 | N33: Yurtdışı | O33: 12 | P33: 25cm Koli - Tortillas 650g Etiketli | Q33: 24-26 cm | R33: 84 | T33: Arka kısma Arnavutça içerik-Tortillas
B34: =IF(C34="","",CONCATENATE(C34,E34)) -> ALDİ - KOSOVAPizza-6 26cm 4pcs 480g | C34: ALDİ - KOSOVA | D34: 8698829380698 | E34: Pizza-6 26cm 4pcs 480g | F34: Pizza-6 26 cm | G34: SADE | H34: 6 | I34: 26 | J34: Irak Soft | K34: 4 | L34: 6 | M34: 480 | N34: YURTDIŞI | O34: 12 | P34: Pizza kolisi | Q34: 26 cm kesme -Beze 145-150g, Kesilmmeiş çap 27-28cm, Kesilmemiş ağı: 520-540g, Kesilmiş:475-485g | R34: 120 | T34: Arka kısma Arnavutça içerik-Pizza 6
B35: =IF(C35="","",CONCATENATE(C35,E35)) -> TASTE LAND-BULGARİSTANTortillas 30cm Sade 18pcs 1620g | C35: TASTE LAND-BULGARİSTAN | D35: 8698829380698 | E35: Tortillas 30cm Sade 18pcs 1620g | F35: Tortillas 30cm Sade | G35: SADE | H35: 6 | I35: 30 | J35: Irak Soft | K35: 18 | L35: 6 | M35: 1620 | N35: Yurtdışı | O35: 9 | P35: 30cm Lacivert Koli- Bulgarca Etiket | Q35: 29-31 cm | R35: 60 | S35: 95x130cm | T35: Barkod üzerine-Bulgarca Barkodlu içerik etiketi (012)
B36: =IF(C36="","",CONCATENATE(C36,E36)) -> TASTE LAND-BULGARİSTANTortillas 30cm Tam Buğday 18pcs 1620g | C36: TASTE LAND-BULGARİSTAN | D36: 8698829380698 | E36: Tortillas 30cm Tam Buğday 18pcs 1620g | F36: Tortillas 30cm Tam Buğday | G36: Tam Buğdaylı | H36: 6 | I36: 30 | J36: Irak Soft | K36: 18 | L36: 6 | M36: 1620 | N36: Yurtdışı | O36: 9 | P36: 30cm Lacivert Koli- Bulgarca TB Etiket | Q36: 29-31 cm | R36: 60 | S36: 95x130cm | T36: Barkod üzerine-Bulgarca Barkodlu TB içerik etiketi (029)
B37: =IF(C37="","",CONCATENATE(C37,E37)) -> TASTE LAND-BULGARİSTANTortillas 25cm Sade 10pcs 650g | C37: TASTE LAND-BULGARİSTAN | D37: 8698829380698 | E37: Tortillas 25cm Sade 10pcs 650g | F37: Tortillas Avrupa 25cm (698) | G37: SADE | H37: 8 | I37: 25 | J37: Irak Soft | K37: 10 | L37: 8 | M37: 650 | N37: Yurtdışı | O37: 9 | P37: 25cm Perforeli-Bulgarca etiket | Q37: 24-26 cm | R37: 120 | S37: 80x120cm -Epal+Epal
B38: =IF(C38="","",CONCATENATE(C38,E38)) -> TASTE LAND-BULGARİSTANTortillas 25cm Tam Buğday 10pcs 650g | C38: TASTE LAND-BULGARİSTAN | D38: 8698829380698 | E38: Tortillas 25cm Tam Buğday 10pcs 650g | F38: Tortillas Avrupa 25cm Tam Buğday (711) | G38: Tam Buğdaylı | H38: 8 | I38: 25 | J38: Irak Soft | K38: 10 | L38: 8 | M38: 650 | N38: Yurtdışı | O38: 9 | P38: 25cm Perforeli-Bulgarca TB etiket | Q38: 24-26 cm | R38: 120 | S38: 80x120cm -Epal+Epal
B39: =IF(C39="","",CONCATENATE(C39,E39)) -> TASTE LAND-BULGARİSTANTortillas 25cm Domatesli 6pcs 390g | C39: TASTE LAND-BULGARİSTAN | D39: 8698829380698 | E39: Tortillas 25cm Domatesli 6pcs 390g | F39: Tortillas Avrupa 25cm Domatesli (074) | G39: Domatesli | H39: 12 | I39: 25 | J39: Irak Soft | K39: 6 | L39: 12 | M39: 390 | N39: Yurtdışı | O39: 9 | P39: 25cm Perforeli-Bulgarca Domatesli etiket | Q39: 24-26 cm | R39: 120 | S39: 80x120cm -Epal+Epal
B40: =IF(C40="","",CONCATENATE(C40,E40)) -> TASTE LAND-BULGARİSTANTortillas 25cm Ispanaklı 6pcs 390g | C40: TASTE LAND-BULGARİSTAN | D40: 8698829380698 | E40: Tortillas 25cm Ispanaklı 6pcs 390g | F40: Tortillas Avrupa 25cm Ispanaklı (081) | G40: Ispanaklı | H40: 12 | I40: 25 | J40: Irak Soft | K40: 6 | L40: 12 | M40: 390 | N40: Yurtdışı | O40: 9 | P40: 25cm Perforeli-Bulgarca Ispanaklı etiket | Q40: 24-26 cm | R40: 120 | S40: 80x120cm -Epal+Epal
B41: =IF(C41="","",CONCATENATE(C41,E41)) -> TASTE LAND-BULGARİSTANTortillas 25cm Peynirli 6pcs 390g | C41: TASTE LAND-BULGARİSTAN | D41: 8698829380698 | E41: Tortillas 25cm Peynirli 6pcs 390g | F41: Tortillas Avrupa 25cm Peynirli (098) | G41: Peynirli | H41: 12 | I41: 25 | J41: Irak Soft-AT | K41: 6 | L41: 12 | M41: 390 | N41: Yurtdışı | O41: 9 | P41: 25cm Perforeli-Bulgarca Peynirli etiket | Q41: 24-26 cm | R41: 120 | S41: 80x120cm -Epal+Epal
B42: =IF(C42="","",CONCATENATE(C42,E42)) -> TASTE LAND-BULGARİSTANTortillas Pizza 26cm 4pcs 480g | C42: TASTE LAND-BULGARİSTAN | D42: 8698829380698 | E42: Tortillas Pizza 26cm 4pcs 480g | F42: Tortillas Avrupa Pizza 26cm (742) | G42: SADE | H42: 8 | I42: 26 | J42: Irak Soft | K42: 4 | L42: 8 | M42: 480 | N42: Yurtdışı | O42: 9 | P42: 26cm Pizza Perforeli-Bulgarca Etiket | Q42: 26 cm kesme -Beze 145-150g, Kesilmmeiş çap 27-28cm, Kesilmemiş ağı: 520-540g, Kesilmiş:475-485g | R42: 120 | S42: 80x120cm -Epal+Epal
...

Sheet Sayfa1
A1: MUTLUKAL-EK BİNA İŞ EMRİ
A2: MAKİNE 1 | AA2: 46176 | AB2: 0.5625
A3: SIRA | B3: FİRMA | C3: GTIN KODU | D3: ARAÇ SAYISI | E3: PRODUCT NAME / ÜRÜN ADI | F3: ORDER NUMBER / SİPARİŞ NUMARASI | G3: KAREKOD DOSYA ADI | H3: AMBALAJ | I3: AMBALAJ ETİKETİ | J3: CİNSİ | K3: ÜRETİLECEK MİKTAR/ KOLİ | L3: DEPO STOK / KOLİ | M3: ÜRETİLECEK MİKTAR/ PALET | N3: PALET/KOLİ | O3: SÜRE | P3: AMBALAJ MİKTAR | Q3: ÇAP | R3: FORMÜL | S3: PAKET İÇİ | T3: KOLİ İÇİ | U3: PAKET GRAMAJI | V3: TARİH | W3: SKT/AY | X3: ÜRT/PRD | Y3: TETT/EXP | Z3: PRT/LOT | AA3: KOLİ / TARİH | AB3: AÇIKLAMALAR | AC3: Palet Ölçüsü | AD3: Birleştir
A4: 1. | B4: LLC TRİTON | C4: =IF(B4="","",VLOOKUP(AD4,Varsayımlar!$B:$Q,3,0)) -> 8698829380698 | E4: MUTLUKAL WHEAT TORTILLA | F4: KB-006500 | G4: ZP4-021324 | H4: =IF(B4="","",VLOOKUP(AD4,Varsayımlar!$B:$Q,5,0)) -> TORTİLLAS 25 CM 4 PCS 260G | I4: =IF(B4="","",VLOOKUP(AD4,Varsayımlar!B:T,19,0)) -> 0 | J4: =IF(B4="","",VLOOKUP(AD4,Varsayımlar!$B:$Q,6,0)) -> SADE | K4: 2436 | L4: 1372 | M4: =IFERROR(IF(B4="","",K4/VLOOKUP(AD4,Varsayımlar!B:R,17,0)),"") -> 29 | N4: 84 | P4: =IF(B4="","",VLOOKUP(AD4,Varsayımlar!$B:$Q,7,0)*K4) -> 73080 | Q4: =IF(B4="","",VLOOKUP(AD4,Varsayımlar!$B:$Q,8,0)) -> 25 | R4: =IF(B4="","",VLOOKUP(AD4,Varsayımlar!$B:$Q,9,0)) -> SOFT | S4: =IF(B4="","",VLOOKUP(AD4,Varsayımlar!$B:$Q,10,0)) -> 4 | T4: =IF(B4="","",VLOOKUP(AD4,Varsayımlar!$B:$Q,11,0)) -> 30 | U4: =IF(B4="","",VLOOKUP(AD4,Varsayımlar!$B:$Q,12,0)) -> 260 | V4: =IF(B4="","",VLOOKUP(AD4,Varsayımlar!$B:$Q,13,0)) -> YURTDIŞI | W4: =IF(B4="","",VLOOKUP(AD4,Varsayımlar!$B:$Q,14,0)) -> 6 | X4: 46177 | Y4: 46360 | Z4: 26060425-1 | AA4: =IF(B4="","",VLOOKUP(AD4,Varsayımlar!$B:$Q,15,0)) -> TRİTON -SKT ATILACAK | AB4: =IF(B4="","",VLOOKUP(AD4,Varsayımlar!$B:$Q,16,0)) -> 24-26 CM | AC4: =IF(B4="","",VLOOKUP(Sayfa1!AD4,Varsayımlar!B:S,18,0)) -> 0 | AD4: =IF(B4="","",CONCATENATE(B4,E4)) -> LLC TRİTONMUTLUKAL WHEAT TORTILLA | AE4: BİTTİ
A5: 2. | B5: SMART LLC | C5: =IF(B5="","",VLOOKUP(AD5,Varsayımlar!$B:$Q,3,0)) -> 8698829380698 | E5: Tortillas 20cm Peynirli 4pcs 166g | G5: KAREKODSUZ ÜRETİLECEK | H5: =IF(B5="","",VLOOKUP(AD5,Varsayımlar!$B:$Q,5,0)) -> Tortillas 20cm (Samakat Bilgileri Ekli) | I5: =IF(B5="","",VLOOKUP(AD5,Varsayımlar!B:T,19,0)) -> 0 | J5: =IF(B5="","",VLOOKUP(AD5,Varsayımlar!$B:$Q,6,0)) -> PEYNİRLİ | K5: 7200 | M5: =IFERROR(IF(B5="","",K5/VLOOKUP(AD5,Varsayımlar!B:R,17,0)),"") -> 32 | N5: 225 | O5: 35 | P5: =IF(B5="","",VLOOKUP(AD5,Varsayımlar!$B:$Q,7,0)*K5) -> 100800 | Q5: =IF(B5="","",VLOOKUP(AD5,Varsayımlar!$B:$Q,8,0)) -> 20 | R5: =IF(B5="","",VLOOKUP(AD5,Varsayımlar!$B:$Q,9,0)) -> IRAK SOFT-AT | S5: =IF(B5="","",VLOOKUP(AD5,Varsayımlar!$B:$Q,10,0)) -> 4 | T5: =IF(B5="","",VLOOKUP(AD5,Varsayımlar!$B:$Q,11,0)) -> 14 | U5: =IF(B5="","",VLOOKUP(AD5,Varsayımlar!$B:$Q,12,0)) -> 166 | V5: =IF(B5="","",VLOOKUP(AD5,Varsayımlar!$B:$Q,13,0)) -> YURTDIŞI | W5: =IF(B5="","",VLOOKUP(AD5,Varsayımlar!$B:$Q,14,0)) -> 9 | X5: 46184 | Y5: 46457 | Z5: 26061120P | AA5: =IF(B5="","",VLOOKUP(AD5,Varsayımlar!$B:$Q,15,0)) -> Kare Koli-Üretim Tarihli Etiket | AB5: =IF(B5="","",VLOOKUP(AD5,Varsayımlar!$B:$Q,16,0)) -> 19-21 cm | AC5: =IF(B5="","",VLOOKUP(Sayfa1!AD5,Varsayımlar!B:S,18,0)) -> 0 | AD5: =IF(B5="","",CONCATENATE(B5,E5)) -> SMART LLCTortillas 20cm Peynirli 4pcs 166g
A6: 3. | B6: Sons Of Hanna | C6: =IF(B6="","",VLOOKUP(AD6,Varsayımlar!$B:$Q,3,0)) -> 8698829380698 | E6: Happylla 30cm Sade 6pcs 510g | H6: =IF(B6="","",VLOOKUP(AD6,Varsayımlar!$B:$Q,5,0)) -> Happylla 30cm | I6: =IF(B6="","",VLOOKUP(AD6,Varsayımlar!B:T,19,0)) -> 0 | J6: =IF(B6="","",VLOOKUP(AD6,Varsayımlar!$B:$Q,6,0)) -> SADE | K6: 1000 | M6: =IFERROR(IF(B6="","",K6/VLOOKUP(AD6,Varsayımlar!B:R,17,0)),"") | O6: 16 | P6: =IF(B6="","",VLOOKUP(AD6,Varsayımlar!$B:$Q,7,0)*K6) -> 18000 | Q6: =IF(B6="","",VLOOKUP(AD6,Varsayımlar!$B:$Q,8,0)) -> 30 | R6: =IF(B6="","",VLOOKUP(AD6,Varsayımlar!$B:$Q,9,0)) -> Irak Soft | S6: =IF(B6="","",VLOOKUP(AD6,Varsayımlar!$B:$Q,10,0)) -> 6 | T6: =IF(B6="","",VLOOKUP(AD6,Varsayımlar!$B:$Q,11,0)) -> 18 | U6: =IF(B6="","",VLOOKUP(AD6,Varsayımlar!$B:$Q,12,0)) -> 510 | V6: =IF(B6="","",VLOOKUP(AD6,Varsayımlar!$B:$Q,13,0)) -> Yurtdışı | W6: =IF(B6="","",VLOOKUP(AD6,Varsayımlar!$B:$Q,14,0)) -> 8 | AA6: =IF(B6="","",VLOOKUP(AD6,Varsayımlar!$B:$Q,15,0)) -> 30cm Koli | AB6: =IF(B6="","",VLOOKUP(AD6,Varsayımlar!$B:$Q,16,0)) -> 29-31 cm | AC6: =IF(B6="","",VLOOKUP(Sayfa1!AD6,Varsayımlar!B:S,18,0)) -> 0 | AD6: =IF(B6="","",CONCATENATE(B6,E6)) -> Sons Of HannaHappylla 30cm Sade 6pcs 510g
A7: 4. | B7: Sons Of Hanna | C7: =IF(B7="","",VLOOKUP(AD7,Varsayımlar!$B:$Q,3,0)) -> 8698829380698 | E7: Tortillas 30cm Tam Buğday6pcs 510g | H7: =IF(B7="","",VLOOKUP(AD7,Varsayımlar!$B:$Q,5,0)) -> Tortillas 30cm Tam Buğday | I7: =IF(B7="","",VLOOKUP(AD7,Varsayımlar!B:T,19,0)) -> 0 | J7: =IF(B7="","",VLOOKUP(AD7,Varsayımlar!$B:$Q,6,0)) -> Tam Buğdaylı | K7: 100 | M7: =IFERROR(IF(B7="","",K7/VLOOKUP(AD7,Varsayımlar!B:R,17,0)),"") | O7: 2 | P7: =IF(B7="","",VLOOKUP(AD7,Varsayımlar!$B:$Q,7,0)*K7) -> 1800 | Q7: =IF(B7="","",VLOOKUP(AD7,Varsayımlar!$B:$Q,8,0)) -> 30 | R7: =IF(B7="","",VLOOKUP(AD7,Varsayımlar!$B:$Q,9,0)) -> Irak Soft | S7: =IF(B7="","",VLOOKUP(AD7,Varsayımlar!$B:$Q,10,0)) -> 6 | T7: =IF(B7="","",VLOOKUP(AD7,Varsayımlar!$B:$Q,11,0)) -> 18 | U7: =IF(B7="","",VLOOKUP(AD7,Varsayımlar!$B:$Q,12,0)) -> 510 | V7: =IF(B7="","",VLOOKUP(AD7,Varsayımlar!$B:$Q,13,0)) -> Yurtdışı | W7: =IF(B7="","",VLOOKUP(AD7,Varsayımlar!$B:$Q,14,0)) -> 8 | AA7: =IF(B7="","",VLOOKUP(AD7,Varsayımlar!$B:$Q,15,0)) -> 30cm Koli - TB Etiketli | AB7: =IF(B7="","",VLOOKUP(AD7,Varsayımlar!$B:$Q,16,0)) -> 29-31 cm | AC7: =IF(B7="","",VLOOKUP(Sayfa1!AD7,Varsayımlar!B:S,18,0)) -> 0 | AD7: =IF(B7="","",CONCATENATE(B7,E7)) -> Sons Of HannaTortillas 30cm Tam Buğday6pcs 510g
A8: 5. | B8: SMART LLC | C8: =IF(B8="","",VLOOKUP(AD8,Varsayımlar!$B:$Q,3,0)) -> 8698829380698 | E8: Tortillas 20cm Çok Tahıllı 4pcs 166g | G8: KAREKODSUZ ÜRETİLECEK | H8: =IF(B8="","",VLOOKUP(AD8,Varsayımlar!$B:$Q,5,0)) -> Tortillas 20cm Çok Tahıllı | I8: =IF(B8="","",VLOOKUP(AD8,Varsayımlar!B:T,19,0)) -> 0 | J8: =IF(B8="","",VLOOKUP(AD8,Varsayımlar!$B:$Q,6,0)) -> Çok Tahıllı | K8: 5625 | M8: =IFERROR(IF(B8="","",K8/VLOOKUP(AD8,Varsayımlar!B:R,17,0)),"") -> 25 | N8: 225 | O8: 45 | P8: =IF(B8="","",VLOOKUP(AD8,Varsayımlar!$B:$Q,7,0)*K8) -> 78750 | Q8: =IF(B8="","",VLOOKUP(AD8,Varsayımlar!$B:$Q,8,0)) -> 20 | R8: =IF(B8="","",VLOOKUP(AD8,Varsayımlar!$B:$Q,9,0)) -> Irak Soft | S8: =IF(B8="","",VLOOKUP(AD8,Varsayımlar!$B:$Q,10,0)) -> 4 | T8: =IF(B8="","",VLOOKUP(AD8,Varsayımlar!$B:$Q,11,0)) -> 14 | U8: =IF(B8="","",VLOOKUP(AD8,Varsayımlar!$B:$Q,12,0)) -> 166 | V8: =IF(B8="","",VLOOKUP(AD8,Varsayımlar!$B:$Q,13,0)) -> Yurtdışı | W8: =IF(B8="","",VLOOKUP(AD8,Varsayımlar!$B:$Q,14,0)) -> 9 | X8: 46183 | Y8: 46456 | Z8: 26061020G | AA8: =IF(B8="","",VLOOKUP(AD8,Varsayımlar!$B:$Q,15,0)) -> SİYAH KARE KOLİ-Üretim Tarihi Etiketli | AB8: =IF(B8="","",VLOOKUP(AD8,Varsayımlar!$B:$Q,16,0)) -> 19-21 cm | AC8: =IF(B8="","",VLOOKUP(Sayfa1!AD8,Varsayımlar!B:S,18,0)) -> 0 | AD8: =IF(B8="","",CONCATENATE(B8,E8)) -> SMART LLCTortillas 20cm Çok Tahıllı 4pcs 166g
A9: 6. | B9: SMART LLC | C9: =IF(B9="","",VLOOKUP(AD9,Varsayımlar!$B:$Q,3,0)) -> 8698829380698 | E9: Tortillas 20cm Peynirli 4pcs 166g | G9: KAREKODSUZ ÜRETİLECEK | H9: =IF(B9="","",VLOOKUP(AD9,Varsayımlar!$B:$Q,5,0)) -> Tortillas 20cm (Samakat Bilgileri Ekli) | I9: =IF(B9="","",VLOOKUP(AD9,Varsayımlar!B:T,19,0)) -> 0 | J9: =IF(B9="","",VLOOKUP(AD9,Varsayımlar!$B:$Q,6,0)) -> PEYNİRLİ | K9: 1350 | M9: =IFERROR(IF(B9="","",K9/VLOOKUP(AD9,Varsayımlar!B:R,17,0)),"") -> 6 | N9: 225 | O9: 2 | P9: =IF(B9="","",VLOOKUP(AD9,Varsayımlar!$B:$Q,7,0)*K9) -> 18900 | Q9: =IF(B9="","",VLOOKUP(AD9,Varsayımlar!$B:$Q,8,0)) -> 20 | R9: =IF(B9="","",VLOOKUP(AD9,Varsayımlar!$B:$Q,9,0)) -> IRAK SOFT-AT | S9: =IF(B9="","",VLOOKUP(AD9,Varsayımlar!$B:$Q,10,0)) -> 4 | T9: =IF(B9="","",VLOOKUP(AD9,Varsayımlar!$B:$Q,11,0)) -> 14 | U9: =IF(B9="","",VLOOKUP(AD9,Varsayımlar!$B:$Q,12,0)) -> 166 | V9: =IF(B9="","",VLOOKUP(AD9,Varsayımlar!$B:$Q,13,0)) -> YURTDIŞI | W9: =IF(B9="","",VLOOKUP(AD9,Varsayımlar!$B:$Q,14,0)) -> 9 | X9: 46188 | Y9: 46461 | Z9: 26061520P | AA9: =IF(B9="","",VLOOKUP(AD9,Varsayımlar!$B:$Q,15,0)) -> Kare Koli-Üretim Tarihli Etiket | AB9: =IF(B9="","",VLOOKUP(AD9,Varsayımlar!$B:$Q,16,0)) -> 19-21 cm | AC9: =IF(B9="","",VLOOKUP(Sayfa1!AD9,Varsayımlar!B:S,18,0)) -> 0 | AD9: =IF(B9="","",CONCATENATE(B9,E9)) -> SMART LLCTortillas 20cm Peynirli 4pcs 166g
A10: 7. | B10: Ajjawi | C10: =IF(B10="","",VLOOKUP(AD10,Varsayımlar!$B:$Q,3,0)) -> 8698829380698 | E10: Lazeza 30 cm 6pcs 510g | H10: =IF(B10="","",VLOOKUP(AD10,Varsayımlar!$B:$Q,5,0)) -> Lazeza 30cm | I10: =IF(B10="","",VLOOKUP(AD10,Varsayımlar!B:T,19,0)) -> 0 | J10: =IF(B10="","",VLOOKUP(AD10,Varsayımlar!$B:$Q,6,0)) -> SADE | K10: 1700 | M10: =IFERROR(IF(B10="","",K10/VLOOKUP(AD10,Varsayımlar!B:R,17,0)),"") | O10: 25 | P10: =IF(B10="","",VLOOKUP(AD10,Varsayımlar!$B:$Q,7,0)*K10) -> 30600 | Q10: =IF(B10="","",VLOOKUP(AD10,Varsayımlar!$B:$Q,8,0)) -> 30 | R10: =IF(B10="","",VLOOKUP(AD10,Varsayımlar!$B:$Q,9,0)) -> Irak Soft | S10: =IF(B10="","",VLOOKUP(AD10,Varsayımlar!$B:$Q,10,0)) -> 6 | T10: =IF(B10="","",VLOOKUP(AD10,Varsayımlar!$B:$Q,11,0)) -> 18 | U10: =IF(B10="","",VLOOKUP(AD10,Varsayımlar!$B:$Q,12,0)) -> 510 | V10: =IF(B10="","",VLOOKUP(AD10,Varsayımlar!$B:$Q,13,0)) -> Yurtdışı | W10: =IF(B10="","",VLOOKUP(AD10,Varsayımlar!$B:$Q,14,0)) -> 6 | AA10: =IF(B10="","",VLOOKUP(AD10,Varsayımlar!$B:$Q,15,0)) -> Lazeza Kolisi | AB10: =IF(B10="","",VLOOKUP(AD10,Varsayımlar!$B:$Q,16,0)) -> 29-31 cm | AC10: =IF(B10="","",VLOOKUP(Sayfa1!AD10,Varsayımlar!B:S,18,0)) -> 0 | AD10: =IF(B10="","",CONCATENATE(B10,E10)) -> AjjawiLazeza 30 cm 6pcs 510g
A11: 8. | B11: TVK Import | C11: =IF(B11="","",VLOOKUP(AD11,Varsayımlar!$B:$Q,3,0)) -> 8698829380698 | E11: Baskısız 30cm 12pcs 1020g | G11: KAREKODSUZ ÜRETİLECEK | H11: =IF(B11="","",VLOOKUP(AD11,Varsayımlar!$B:$Q,5,0)) -> Baskısız 30cm | I11: =IF(B11="","",VLOOKUP(AD11,Varsayımlar!B:T,19,0)) -> Tüm Bilgiler Sade | J11: =IF(B11="","",VLOOKUP(AD11,Varsayımlar!$B:$Q,6,0)) -> SADE | K11: 792 | M11: =IFERROR(IF(B11="","",K11/VLOOKUP(AD11,Varsayımlar!B:R,17,0)),"") | O11: 13 | P11: =IF(B11="","",VLOOKUP(AD11,Varsayımlar!$B:$Q,7,0)*K11) -> 7920 | Q11: =IF(B11="","",VLOOKUP(AD11,Varsayımlar!$B:$Q,8,0)) -> 30 | R11: =IF(B11="","",VLOOKUP(AD11,Varsayımlar!$B:$Q,9,0)) -> Irak soft | S11: =IF(B11="","",VLOOKUP(AD11,Varsayımlar!$B:$Q,10,0)) -> 12 | T11: =IF(B11="","",VLOOKUP(AD11,Varsayımlar!$B:$Q,11,0)) -> 10 | U11: =IF(B11="","",VLOOKUP(AD11,Varsayımlar!$B:$Q,12,0)) -> 1020 | V11: =IF(B11="","",VLOOKUP(AD11,Varsayımlar!$B:$Q,13,0)) -> Yurtdışı | W11: =IF(B11="","",VLOOKUP(AD11,Varsayımlar!$B:$Q,14,0)) -> 6 | X11: 46190 | Y11: 46373 | Z11: 26061730 | AA11: =IF(B11="","",VLOOKUP(AD11,Varsayımlar!$B:$Q,15,0)) -> 30cm Kolisi | AB11: =IF(B11="","",VLOOKUP(AD11,Varsayımlar!$B:$Q,16,0)) -> 29-31 cm | AC11: =IF(B11="","",VLOOKUP(Sayfa1!AD11,Varsayımlar!B:S,18,0)) -> 0 | AD11: =IF(B11="","",CONCATENATE(B11,E11)) -> TVK ImportBaskısız 30cm 12pcs 1020g
A12: 9. | B12: TVK Import | C12: =IF(B12="","",VLOOKUP(AD12,Varsayımlar!$B:$Q,3,0)) -> 8698829380698 | E12: Baskısız 30cm TB 12pcs 1020g | G12: KAREKODSUZ ÜRETİLECEK | H12: =IF(B12="","",VLOOKUP(AD12,Varsayımlar!$B:$Q,5,0)) -> Baskısız 30cm | I12: =IF(B12="","",VLOOKUP(AD12,Varsayımlar!B:T,19,0)) -> Tüm Bilgiler TB | J12: =IF(B12="","",VLOOKUP(AD12,Varsayımlar!$B:$Q,6,0)) -> Tam Buğdaylı | K12: 576 | M12: =IFERROR(IF(B12="","",K12/VLOOKUP(AD12,Varsayımlar!B:R,17,0)),"") | O12: 10 | P12: =IF(B12="","",VLOOKUP(AD12,Varsayımlar!$B:$Q,7,0)*K12) -> 5760 | Q12: =IF(B12="","",VLOOKUP(AD12,Varsayımlar!$B:$Q,8,0)) -> 30 | R12: =IF(B12="","",VLOOKUP(AD12,Varsayımlar!$B:$Q,9,0)) -> Irak soft | S12: =IF(B12="","",VLOOKUP(AD12,Varsayımlar!$B:$Q,10,0)) -> 12 | T12: =IF(B12="","",VLOOKUP(AD12,Varsayımlar!$B:$Q,11,0)) -> 10 | U12: =IF(B12="","",VLOOKUP(AD12,Varsayımlar!$B:$Q,12,0)) -> 1020 | V12: =IF(B12="","",VLOOKUP(AD12,Varsayımlar!$B:$Q,13,0)) -> Yurtdışı | W12: =IF(B12="","",VLOOKUP(AD12,Varsayımlar!$B:$Q,14,0)) -> 6 | X12: 46190 | Y12: 46373 | Z12: 26061730T | AA12: =IF(B12="","",VLOOKUP(AD12,Varsayımlar!$B:$Q,15,0)) -> 30cm Kolisi-Etiketli | AB12: =IF(B12="","",VLOOKUP(AD12,Varsayımlar!$B:$Q,16,0)) -> 29-31 cm | AC12: =IF(B12="","",VLOOKUP(Sayfa1!AD12,Varsayımlar!B:S,18,0)) -> 0 | AD12: =IF(B12="","",CONCATENATE(B12,E12)) -> TVK ImportBaskısız 30cm TB 12pcs 1020g
A13: 10. | B13: TVK Import | C13: =IF(B13="","",VLOOKUP(AD13,Varsayımlar!$B:$Q,3,0)) -> 8698829380698 | E13: Baskısız 30cm Ispanaklı 12pcs 1020g | G13: KAREKODSUZ ÜRETİLECEK | H13: =IF(B13="","",VLOOKUP(AD13,Varsayımlar!$B:$Q,5,0)) -> Baskısız 30cm | I13: =IF(B13="","",VLOOKUP(AD13,Varsayımlar!B:T,19,0)) -> Tüm Bilgiler Ispanaklı | J13: =IF(B13="","",VLOOKUP(AD13,Varsayımlar!$B:$Q,6,0)) -> Ispanaklı | K13: 144 | M13: =IFERROR(IF(B13="","",K13/VLOOKUP(AD13,Varsayımlar!B:R,17,0)),"") | O13: 3 | P13: =IF(B13="","",VLOOKUP(AD13,Varsayımlar!$B:$Q,7,0)*K13) -> 1440 | Q13: =IF(B13="","",VLOOKUP(AD13,Varsayımlar!$B:$Q,8,0)) -> 30 | R13: =IF(B13="","",VLOOKUP(AD13,Varsayımlar!$B:$Q,9,0)) -> Irak soft | S13: =IF(B13="","",VLOOKUP(AD13,Varsayımlar!$B:$Q,10,0)) -> 12 | T13: =IF(B13="","",VLOOKUP(AD13,Varsayımlar!$B:$Q,11,0)) -> 10 | U13: =IF(B13="","",VLOOKUP(AD13,Varsayımlar!$B:$Q,12,0)) -> 1020 | V13: =IF(B13="","",VLOOKUP(AD13,Varsayımlar!$B:$Q,13,0)) -> Yurtdışı | W13: =IF(B13="","",VLOOKUP(AD13,Varsayımlar!$B:$Q,14,0)) -> 6 | X13: 46190 | Y13: 46373 | Z13: 26061730I | AA13: =IF(B13="","",VLOOKUP(AD13,Varsayımlar!$B:$Q,15,0)) -> 30cm Kolisi-Etiketli | AB13: =IF(B13="","",VLOOKUP(AD13,Varsayımlar!$B:$Q,16,0)) -> 29-31 cm | AC13: =IF(B13="","",VLOOKUP(Sayfa1!AD13,Varsayımlar!B:S,18,0)) -> 0 | AD13: =IF(B13="","",CONCATENATE(B13,E13)) -> TVK ImportBaskısız 30cm Ispanaklı 12pcs 1020g
A14: 11. | B14: SMART LLC | C14: =IF(B14="","",VLOOKUP(AD14,Varsayımlar!$B:$Q,3,0)) -> 8698829380698 | E14: Tortillas 20cm Çok Tahıllı 4pcs 166g | G14: KAREKODSUZ ÜRETİLECEK | H14: =IF(B14="","",VLOOKUP(AD14,Varsayımlar!$B:$Q,5,0)) -> Tortillas 20cm Çok Tahıllı | I14: =IF(B14="","",VLOOKUP(AD14,Varsayımlar!B:T,19,0)) -> 0 | J14: =IF(B14="","",VLOOKUP(AD14,Varsayımlar!$B:$Q,6,0)) -> Çok Tahıllı | K14: 225 | M14: =IFERROR(IF(B14="","",K14/VLOOKUP(AD14,Varsayımlar!B:R,17,0)),"") -> 1 | O14: 26 | P14: =IF(B14="","",VLOOKUP(AD14,Varsayımlar!$B:$Q,7,0)*K14) -> 3150 | Q14: =IF(B14="","",VLOOKUP(AD14,Varsayımlar!$B:$Q,8,0)) -> 20 | R14: =IF(B14="","",VLOOKUP(AD14,Varsayımlar!$B:$Q,9,0)) -> Irak Soft | S14: =IF(B14="","",VLOOKUP(AD14,Varsayımlar!$B:$Q,10,0)) -> 4 | T14: =IF(B14="","",VLOOKUP(AD14,Varsayımlar!$B:$Q,11,0)) -> 14 | U14: =IF(B14="","",VLOOKUP(AD14,Varsayımlar!$B:$Q,12,0)) -> 166 | V14: =IF(B14="","",VLOOKUP(AD14,Varsayımlar!$B:$Q,13,0)) -> Yurtdışı | W14: =IF(B14="","",VLOOKUP(AD14,Varsayımlar!$B:$Q,14,0)) -> 9 | X14: 46195 | Y14: 46468 | Z14: 26062220G | AA14: =IF(B14="","",VLOOKUP(AD14,Varsayımlar!$B:$Q,15,0)) -> SİYAH KARE KOLİ-Üretim Tarihi Etiketli | AB14: =IF(B14="","",VLOOKUP(AD14,Varsayımlar!$B:$Q,16,0)) -> 19-21 cm | AC14: =IF(B14="","",VLOOKUP(Sayfa1!AD14,Varsayımlar!B:S,18,0)) -> 0 | AD14: =IF(B14="","",CONCATENATE(B14,E14)) -> SMART LLCTortillas 20cm Çok Tahıllı 4pcs 166g
A15: 12. | B15: SMART LLC | C15: =IF(B15="","",VLOOKUP(AD15,Varsayımlar!$B:$Q,3,0)) -> 8698829380698 | E15: Tortillas 20cm Çok Tahıllı 4pcs 166g | G15: KAREKODSUZ ÜRETİLECEK | H15: =IF(B15="","",VLOOKUP(AD15,Varsayımlar!$B:$Q,5,0)) -> Tortillas 20cm Çok Tahıllı | I15: =IF(B15="","",VLOOKUP(AD15,Varsayımlar!B:T,19,0)) -> 0 | J15: =IF(B15="","",VLOOKUP(AD15,Varsayımlar!$B:$Q,6,0)) -> Çok Tahıllı | K15: 1800 | M15: =IFERROR(IF(B15="","",K15/VLOOKUP(AD15,Varsayımlar!B:R,17,0)),"") -> 8 | O15: 15 | P15: =IF(B15="","",VLOOKUP(AD15,Varsayımlar!$B:$Q,7,0)*K15) -> 25200 | Q15: =IF(B15="","",VLOOKUP(AD15,Varsayımlar!$B:$Q,8,0)) -> 20 | R15: =IF(B15="","",VLOOKUP(AD15,Varsayımlar!$B:$Q,9,0)) -> Irak Soft | S15: =IF(B15="","",VLOOKUP(AD15,Varsayımlar!$B:$Q,10,0)) -> 4 | T15: =IF(B15="","",VLOOKUP(AD15,Varsayımlar!$B:$Q,11,0)) -> 14 | U15: =IF(B15="","",VLOOKUP(AD15,Varsayımlar!$B:$Q,12,0)) -> 166 | V15: =IF(B15="","",VLOOKUP(AD15,Varsayımlar!$B:$Q,13,0)) -> Yurtdışı | W15: =IF(B15="","",VLOOKUP(AD15,Varsayımlar!$B:$Q,14,0)) -> 9 | X15: 46196 | Y15: 46469 | Z15: 26060320G | AA15: =IF(B15="","",VLOOKUP(AD15,Varsayımlar!$B:$Q,15,0)) -> SİYAH KARE KOLİ-Üretim Tarihi Etiketli | AB15: =IF(B15="","",VLOOKUP(AD15,Varsayımlar!$B:$Q,16,0)) -> 19-21 cm | AC15: =IF(B15="","",VLOOKUP(Sayfa1!AD15,Varsayımlar!B:S,18,0)) -> 0 | AD15: =IF(B15="","",CONCATENATE(B15,E15)) -> SMART LLCTortillas 20cm Çok Tahıllı 4pcs 166g
A16: 13. | B16: SMART LLC | C16: =IF(B16="","",VLOOKUP(AD16,Varsayımlar!$B:$Q,3,0)) -> 8698829380698 | E16: TORTİLLAS SAMAKAT 20CM 166G | G16: KAREKODSUZ ÜRETİLECEK | H16: =IF(B16="","",VLOOKUP(AD16,Varsayımlar!$B:$Q,5,0)) -> TORTİLLAS 20CM (SAMAKAT BİLGİLERİ EKLİ) | I16: =IF(B16="","",VLOOKUP(AD16,Varsayımlar!B:T,19,0)) -> 0 | J16: =IF(B16="","",VLOOKUP(AD16,Varsayımlar!$B:$Q,6,0)) -> SADE | K16: 6975 | M16: =IFERROR(IF(B16="","",K16/VLOOKUP(AD16,Varsayımlar!B:R,17,0)),"") -> 31 | O16: 56 | P16: =IF(B16="","",VLOOKUP(AD16,Varsayımlar!$B:$Q,7,0)*K16) -> 97650 | Q16: =IF(B16="","",VLOOKUP(AD16,Varsayımlar!$B:$Q,8,0)) -> 20 | R16: =IF(B16="","",VLOOKUP(AD16,Varsayımlar!$B:$Q,9,0)) -> IRAK SOFT | S16: =IF(B16="","",VLOOKUP(AD16,Varsayımlar!$B:$Q,10,0)) -> 4 | T16: =IF(B16="","",VLOOKUP(AD16,Varsayımlar!$B:$Q,11,0)) -> 14 | U16: =IF(B16="","",VLOOKUP(AD16,Varsayımlar!$B:$Q,12,0)) -> 166 | V16: =IF(B16="","",VLOOKUP(AD16,Varsayımlar!$B:$Q,13,0)) -> YURTDIŞI | W16: =IF(B16="","",VLOOKUP(AD16,Varsayımlar!$B:$Q,14,0)) -> 9 | X16: 46195 | Y16: 46468 | Z16: 26062220 | AA16: =IF(B16="","",VLOOKUP(AD16,Varsayımlar!$B:$Q,15,0)) -> SİYAH KARE KOLİ- Üretim Tarihi Etiketli | AB16: =IF(B16="","",VLOOKUP(AD16,Varsayımlar!$B:$Q,16,0)) -> 19-21 CM | AC16: =IF(B16="","",VLOOKUP(Sayfa1!AD16,Varsayımlar!B:S,18,0)) -> 0 | AD16: =IF(B16="","",CONCATENATE(B16,E16)) -> SMART LLCTORTİLLAS SAMAKAT 20CM 166G
A17: 14. | B17: SMART LLC | C17: =IF(B17="","",VLOOKUP(AD17,Varsayımlar!$B:$Q,3,0)) -> 8698829380698 | E17: Tortillas 20cm Peynirli 4pcs 166g | G17: KAREKODSUZ ÜRETİLECEK | H17: =IF(B17="","",VLOOKUP(AD17,Varsayımlar!$B:$Q,5,0)) -> Tortillas 20cm (Samakat Bilgileri Ekli) | I17: =IF(B17="","",VLOOKUP(AD17,Varsayımlar!B:T,19,0)) -> 0 | J17: =IF(B17="","",VLOOKUP(AD17,Varsayımlar!$B:$Q,6,0)) -> PEYNİRLİ | K17: 2925 | M17: =IFERROR(IF(B17="","",K17/VLOOKUP(AD17,Varsayımlar!B:R,17,0)),"") -> 13 | O17: 24 | P17: =IF(B17="","",VLOOKUP(AD17,Varsayımlar!$B:$Q,7,0)*K17) -> 40950 | Q17: =IF(B17="","",VLOOKUP(AD17,Varsayımlar!$B:$Q,8,0)) -> 20 | R17: =IF(B17="","",VLOOKUP(AD17,Varsayımlar!$B:$Q,9,0)) -> IRAK SOFT-AT | S17: =IF(B17="","",VLOOKUP(AD17,Varsayımlar!$B:$Q,10,0)) -> 4 | T17: =IF(B17="","",VLOOKUP(AD17,Varsayımlar!$B:$Q,11,0)) -> 14 | U17: =IF(B17="","",VLOOKUP(AD17,Varsayımlar!$B:$Q,12,0)) -> 166 | V17: =IF(B17="","",VLOOKUP(AD17,Varsayımlar!$B:$Q,13,0)) -> YURTDIŞI | W17: =IF(B17="","",VLOOKUP(AD17,Varsayımlar!$B:$Q,14,0)) -> 9 | X17: 46196 | Y17: 46469 | Z17: 26062320P | AA17: =IF(B17="","",VLOOKUP(AD17,Varsayımlar!$B:$Q,15,0)) -> Kare Koli-Üretim Tarihli Etiket | AB17: =IF(B17="","",VLOOKUP(AD17,Varsayımlar!$B:$Q,16,0)) -> 19-21 cm | AC17: =IF(B17="","",VLOOKUP(Sayfa1!AD17,Varsayımlar!B:S,18,0)) -> 0 | AD17: =IF(B17="","",CONCATENATE(B17,E17)) -> SMART LLCTortillas 20cm Peynirli 4pcs 166g
A18: 15. | B18: TASTE LAND-BULGARİSTAN | C18: =IF(B18="","",VLOOKUP(AD18,Varsayımlar!$B:$Q,3,0)) -> 8698829380698 | D18: 1. ARAÇ | E18: Tortillas 30cm Sade 18pcs 1620g | F18: 26042906 | H18: =IF(B18="","",VLOOKUP(AD18,Varsayımlar!$B:$Q,5,0)) -> Tortillas 30cm Sade | I18: =IF(B18="","",VLOOKUP(AD18,Varsayımlar!B:T,19,0)) -> Barkod üzerine-Bulgarca Barkodlu içerik etiketi (012) | J18: =IF(B18="","",VLOOKUP(AD18,Varsayımlar!$B:$Q,6,0)) -> SADE | K18: 120 | M18: =IFERROR(IF(B18="","",K18/VLOOKUP(AD18,Varsayımlar!B:R,17,0)),"") -> 2 | O18: 2 | P18: =IF(B18="","",VLOOKUP(AD18,Varsayımlar!$B:$Q,7,0)*K18) -> 720 | Q18: =IF(B18="","",VLOOKUP(AD18,Varsayımlar!$B:$Q,8,0)) -> 30 | R18: =IF(B18="","",VLOOKUP(AD18,Varsayımlar!$B:$Q,9,0)) -> Irak Soft | S18: =IF(B18="","",VLOOKUP(AD18,Varsayımlar!$B:$Q,10,0)) -> 18 | T18: =IF(B18="","",VLOOKUP(AD18,Varsayımlar!$B:$Q,11,0)) -> 6 | U18: =IF(B18="","",VLOOKUP(AD18,Varsayımlar!$B:$Q,12,0)) -> 1620 | V18: =IF(B18="","",VLOOKUP(AD18,Varsayımlar!$B:$Q,13,0)) -> Yurtdışı | W18: =IF(B18="","",VLOOKUP(AD18,Varsayımlar!$B:$Q,14,0)) -> 9 | AA18: =IF(B18="","",VLOOKUP(AD18,Varsayımlar!$B:$Q,15,0)) -> 30cm Lacivert Koli- Bulgarca Etiket | AB18: =IF(B18="","",VLOOKUP(AD18,Varsayımlar!$B:$Q,16,0)) -> 29-31 cm | AC18: =IF(B18="","",VLOOKUP(Sayfa1!AD18,Varsayımlar!B:S,18,0)) -> 95x130cm | AD18: =IF(B18="","",CONCATENATE(B18,E18)) -> TASTE LAND-BULGARİSTANTortillas 30cm Sade 18pcs 1620g
A19: 16. | B19: TASTE LAND-BULGARİSTAN | C19: =IF(B19="","",VLOOKUP(AD19,Varsayımlar!$B:$Q,3,0)) -> 8698829380698 | D19: 1. ARAÇ | E19: Tortillas 30cm Tam Buğday 18pcs 1620g | F19: 26042906 | H19: =IF(B19="","",VLOOKUP(AD19,Varsayımlar!$B:$Q,5,0)) -> Tortillas 30cm Tam Buğday | I19: =IF(B19="","",VLOOKUP(AD19,Varsayımlar!B:T,19,0)) -> Barkod üzerine-Bulgarca Barkodlu TB içerik etiketi (029) | J19: =IF(B19="","",VLOOKUP(AD19,Varsayımlar!$B:$Q,6,0)) -> Tam Buğdaylı | K19: 60 | M19: =IFERROR(IF(B19="","",K19/VLOOKUP(AD19,Varsayımlar!B:R,17,0)),"") -> 1 | O19: 1 | P19: =IF(B19="","",VLOOKUP(AD19,Varsayımlar!$B:$Q,7,0)*K19) -> 360 | Q19: =IF(B19="","",VLOOKUP(AD19,Varsayımlar!$B:$Q,8,0)) -> 30 | R19: =IF(B19="","",VLOOKUP(AD19,Varsayımlar!$B:$Q,9,0)) -> Irak Soft | S19: =IF(B19="","",VLOOKUP(AD19,Varsayımlar!$B:$Q,10,0)) -> 18 | T19: =IF(B19="","",VLOOKUP(AD19,Varsayımlar!$B:$Q,11,0)) -> 6 | U19: =IF(B19="","",VLOOKUP(AD19,Varsayımlar!$B:$Q,12,0)) -> 1620 | V19: =IF(B19="","",VLOOKUP(AD19,Varsayımlar!$B:$Q,13,0)) -> Yurtdışı | W19: =IF(B19="","",VLOOKUP(AD19,Varsayımlar!$B:$Q,14,0)) -> 9 | AA19: =IF(B19="","",VLOOKUP(AD19,Varsayımlar!$B:$Q,15,0)) -> 30cm Lacivert Koli- Bulgarca TB Etiket | AB19: =IF(B19="","",VLOOKUP(AD19,Varsayımlar!$B:$Q,16,0)) -> 29-31 cm | AC19: =IF(B19="","",VLOOKUP(Sayfa1!AD19,Varsayımlar!B:S,18,0)) -> 95x130cm | AD19: =IF(B19="","",CONCATENATE(B19,E19)) -> TASTE LAND-BULGARİSTANTortillas 30cm Tam Buğday 18pcs 1620g
A20: 17. | B20: TASTE LAND-BULGARİSTAN | C20: =IF(B20="","",VLOOKUP(AD20,Varsayımlar!$B:$Q,3,0)) -> 8698829380698 | D20: 3. ARAÇ | E20: Tortillas 30cm Tam Buğday 18pcs 1620g | F20: 26042908-2 | H20: =IF(B20="","",VLOOKUP(AD20,Varsayımlar!$B:$Q,5,0)) -> Tortillas 30cm Tam Buğday | I20: =IF(B20="","",VLOOKUP(AD20,Varsayımlar!B:T,19,0)) -> Barkod üzerine-Bulgarca Barkodlu TB içerik etiketi (029) | J20: =IF(B20="","",VLOOKUP(AD20,Varsayımlar!$B:$Q,6,0)) -> Tam Buğdaylı | K20: 60 | M20: =IFERROR(IF(B20="","",K20/VLOOKUP(AD20,Varsayımlar!B:R,17,0)),"") -> 1 | O20: 1 | P20: =IF(B20="","",VLOOKUP(AD20,Varsayımlar!$B:$Q,7,0)*K20) -> 360 | Q20: =IF(B20="","",VLOOKUP(AD20,Varsayımlar!$B:$Q,8,0)) -> 30 | R20: =IF(B20="","",VLOOKUP(AD20,Varsayımlar!$B:$Q,9,0)) -> Irak Soft | S20: =IF(B20="","",VLOOKUP(AD20,Varsayımlar!$B:$Q,10,0)) -> 18 | T20: =IF(B20="","",VLOOKUP(AD20,Varsayımlar!$B:$Q,11,0)) -> 6 | U20: =IF(B20="","",VLOOKUP(AD20,Varsayımlar!$B:$Q,12,0)) -> 1620 | V20: =IF(B20="","",VLOOKUP(AD20,Varsayımlar!$B:$Q,13,0)) -> Yurtdışı | W20: =IF(B20="","",VLOOKUP(AD20,Varsayımlar!$B:$Q,14,0)) -> 9 | AA20: =IF(B20="","",VLOOKUP(AD20,Varsayımlar!$B:$Q,15,0)) -> 30cm Lacivert Koli- Bulgarca TB Etiket | AB20: =IF(B20="","",VLOOKUP(AD20,Varsayımlar!$B:$Q,16,0)) -> 29-31 cm | AC20: =IF(B20="","",VLOOKUP(Sayfa1!AD20,Varsayımlar!B:S,18,0)) -> 95x130cm | AD20: =IF(B20="","",CONCATENATE(B20,E20)) -> TASTE LAND-BULGARİSTANTortillas 30cm Tam Buğday 18pcs 1620g
A21: 18. | B21: TASTE LAND-BULGARİSTAN | C21: =IF(B21="","",VLOOKUP(AD21,Varsayımlar!$B:$Q,3,0)) -> 8698829380698 | D21: 3. ARAÇ | E21: Tortillas 20cm Sade 6pcs 270g | F21: 26042908-2 | H21: =IF(B21="","",VLOOKUP(AD21,Varsayımlar!$B:$Q,5,0)) -> Tortillas 20cm Sade | I21: =IF(B21="","",VLOOKUP(AD21,Varsayımlar!B:T,19,0)) -> Barkod üzerine Barkod Etiketi (104) | J21: =IF(B21="","",VLOOKUP(AD21,Varsayımlar!$B:$Q,6,0)) -> SADE | K21: 120 | M21: =IFERROR(IF(B21="","",K21/VLOOKUP(AD21,Varsayımlar!B:R,17,0)),"") -> 1 | O21: 2 | P21: =IF(B21="","",VLOOKUP(AD21,Varsayımlar!$B:$Q,7,0)*K21) -> 2160 | Q21: =IF(B21="","",VLOOKUP(AD21,Varsayımlar!$B:$Q,8,0)) -> 20 | R21: =IF(B21="","",VLOOKUP(AD21,Varsayımlar!$B:$Q,9,0)) -> Irak Soft | S21: =IF(B21="","",VLOOKUP(AD21,Varsayımlar!$B:$Q,10,0)) -> 6 | T21: =IF(B21="","",VLOOKUP(AD21,Varsayımlar!$B:$Q,11,0)) -> 18 | U21: =IF(B21="","",VLOOKUP(AD21,Varsayımlar!$B:$Q,12,0)) -> 270 | V21: =IF(B21="","",VLOOKUP(AD21,Varsayımlar!$B:$Q,13,0)) -> Yurtdışı | W21: =IF(B21="","",VLOOKUP(AD21,Varsayımlar!$B:$Q,14,0)) -> 9 | AA21: =IF(B21="","",VLOOKUP(AD21,Varsayımlar!$B:$Q,15,0)) -> 20cm Lacivert-Bulgarca Etiket | AB21: =IF(B21="","",VLOOKUP(AD21,Varsayımlar!$B:$Q,16,0)) -> 19-21 cm | AC21: =IF(B21="","",VLOOKUP(Sayfa1!AD21,Varsayımlar!B:S,18,0)) -> 100x120cm-Epal+Epal | AD21: =IF(B21="","",CONCATENATE(B21,E21)) -> TASTE LAND-BULGARİSTANTortillas 20cm Sade 6pcs 270g
A22: 19. | B22: LAIKYUZHN-BELARUS | C22: =IF(B22="","",VLOOKUP(AD22,Varsayımlar!$B:$Q,3,0)) -> 8698829380698 | D22: 1. ARAÇ | E22: Tortillas 25cm Sade 4pcs 240g | F22: 20250825 | G22: KAREKODSUZ ÜRETİLECEK | H22: =IF(B22="","",VLOOKUP(AD22,Varsayımlar!$B:$Q,5,0)) -> Tortillas 25cm Sade | I22: =IF(B22="","",VLOOKUP(AD22,Varsayımlar!B:T,19,0)) -> 0 | J22: =IF(B22="","",VLOOKUP(AD22,Varsayımlar!$B:$Q,6,0)) -> SADE | K22: 672 | M22: =IFERROR(IF(B22="","",K22/VLOOKUP(AD22,Varsayımlar!B:R,17,0)),"") -> 8 | P22: =IF(B22="","",VLOOKUP(AD22,Varsayımlar!$B:$Q,7,0)*K22) -> 20160 | Q22: =IF(B22="","",VLOOKUP(AD22,Varsayımlar!$B:$Q,8,0)) -> 25 | R22: =IF(B22="","",VLOOKUP(AD22,Varsayımlar!$B:$Q,9,0)) -> Soft-PA3 | S22: =IF(B22="","",VLOOKUP(AD22,Varsayımlar!$B:$Q,10,0)) -> 4 | T22: =IF(B22="","",VLOOKUP(AD22,Varsayımlar!$B:$Q,11,0)) -> 30 | U22: =IF(B22="","",VLOOKUP(AD22,Varsayımlar!$B:$Q,12,0)) -> 240 | V22: =IF(B22="","",VLOOKUP(AD22,Varsayımlar!$B:$Q,13,0)) -> Yurtdışı | W22: =IF(B22="","",VLOOKUP(AD22,Varsayımlar!$B:$Q,14,0)) -> 12 | AA22: =IF(B22="","",VLOOKUP(AD22,Varsayımlar!$B:$Q,15,0)) -> 25cm Kolisi-Etiketli | AB22: =IF(B22="","",VLOOKUP(AD22,Varsayımlar!$B:$Q,16,0)) -> 24-26 cm (Macca Hetto Inkjet Uzun Tarih) | AC22: =IF(B22="","",VLOOKUP(Sayfa1!AD22,Varsayımlar!B:S,18,0)) -> 80x120cm | AD22: =IF(B22="","",CONCATENATE(B22,E22)) -> LAIKYUZHN-BELARUSTortillas 25cm Sade 4pcs 240g
A23: 20. | B23: LAIKYUZHN-BELARUS | C23: =IF(B23="","",VLOOKUP(AD23,Varsayımlar!$B:$Q,3,0)) -> 8698829380698 | D23: 1. ARAÇ | E23: Tortillas 25cm Tam buğday 4pcs 240g | F23: 20250825 | G23: KAREKODSUZ ÜRETİLECEK | H23: =IF(B23="","",VLOOKUP(AD23,Varsayımlar!$B:$Q,5,0)) -> Tortillas 25cm Tam Buğday | I23: =IF(B23="","",VLOOKUP(AD23,Varsayımlar!B:T,19,0)) -> 0 | J23: =IF(B23="","",VLOOKUP(AD23,Varsayımlar!$B:$Q,6,0)) -> Tam Buğdaylı | K23: 252 | M23: =IFERROR(IF(B23="","",K23/VLOOKUP(AD23,Varsayımlar!B:R,17,0)),"") -> 3 | P23: =IF(B23="","",VLOOKUP(AD23,Varsayımlar!$B:$Q,7,0)*K23) -> 7560 | Q23: =IF(B23="","",VLOOKUP(AD23,Varsayımlar!$B:$Q,8,0)) -> 25 | R23: =IF(B23="","",VLOOKUP(AD23,Varsayımlar!$B:$Q,9,0)) -> Soft-PA3 | S23: =IF(B23="","",VLOOKUP(AD23,Varsayımlar!$B:$Q,10,0)) -> 4 | T23: =IF(B23="","",VLOOKUP(AD23,Varsayımlar!$B:$Q,11,0)) -> 30 | U23: =IF(B23="","",VLOOKUP(AD23,Varsayımlar!$B:$Q,12,0)) -> 240 | V23: =IF(B23="","",VLOOKUP(AD23,Varsayımlar!$B:$Q,13,0)) -> Yurtdışı | W23: =IF(B23="","",VLOOKUP(AD23,Varsayımlar!$B:$Q,14,0)) -> 12 | AA23: =IF(B23="","",VLOOKUP(AD23,Varsayımlar!$B:$Q,15,0)) -> 25cm Kolisi-Etiketli | AB23: =IF(B23="","",VLOOKUP(AD23,Varsayımlar!$B:$Q,16,0)) -> 24-26 cm (Macca Hetto Inkjet Uzun Tarih) | AC23: =IF(B23="","",VLOOKUP(Sayfa1!AD23,Varsayımlar!B:S,18,0)) -> 80x120cm | AD23: =IF(B23="","",CONCATENATE(B23,E23)) -> LAIKYUZHN-BELARUSTortillas 25cm Tam buğday 4pcs 240g
A24: 21. | B24: LAIKYUZHN-BELARUS | C24: =IF(B24="","",VLOOKUP(AD24,Varsayımlar!$B:$Q,3,0)) -> 8698829380698 | D24: 1. ARAÇ | E24: Tortillas 25cm Domatesli 4pcs 240g | F24: 20250825 | G24: KAREKODSUZ ÜRETİLECEK | H24: =IF(B24="","",VLOOKUP(AD24,Varsayımlar!$B:$Q,5,0)) -> Tortillas 25cm Domatesli | I24: =IF(B24="","",VLOOKUP(AD24,Varsayımlar!B:T,19,0)) -> 0 | J24: =IF(B24="","",VLOOKUP(AD24,Varsayımlar!$B:$Q,6,0)) -> Domatesli | K24: 252 | M24: =IFERROR(IF(B24="","",K24/VLOOKUP(AD24,Varsayımlar!B:R,17,0)),"") -> 3 | P24: =IF(B24="","",VLOOKUP(AD24,Varsayımlar!$B:$Q,7,0)*K24) -> 7560 | Q24: =IF(B24="","",VLOOKUP(AD24,Varsayımlar!$B:$Q,8,0)) -> 25 | R24: =IF(B24="","",VLOOKUP(AD24,Varsayımlar!$B:$Q,9,0)) -> Soft-PA3 | S24: =IF(B24="","",VLOOKUP(AD24,Varsayımlar!$B:$Q,10,0)) -> 4 | T24: =IF(B24="","",VLOOKUP(AD24,Varsayımlar!$B:$Q,11,0)) -> 30 | U24: =IF(B24="","",VLOOKUP(AD24,Varsayımlar!$B:$Q,12,0)) -> 240 | V24: =IF(B24="","",VLOOKUP(AD24,Varsayımlar!$B:$Q,13,0)) -> Yurtdışı | W24: =IF(B24="","",VLOOKUP(AD24,Varsayımlar!$B:$Q,14,0)) -> 12 | AA24: =IF(B24="","",VLOOKUP(AD24,Varsayımlar!$B:$Q,15,0)) -> 25cm Kolisi-Etiketli | AB24: =IF(B24="","",VLOOKUP(AD24,Varsayımlar!$B:$Q,16,0)) -> 24-26 cm (Macca Hetto Inkjet Uzun Tarih) | AC24: =IF(B24="","",VLOOKUP(Sayfa1!AD24,Varsayımlar!B:S,18,0)) -> 80x120cm | AD24: =IF(B24="","",CONCATENATE(B24,E24)) -> LAIKYUZHN-BELARUSTortillas 25cm Domatesli 4pcs 240g
A25: 22. | B25: LAIKYUZHN-BELARUS | C25: =IF(B25="","",VLOOKUP(AD25,Varsayımlar!$B:$Q,3,0)) -> 8698829380698 | D25: 1. ARAÇ | E25: Tortillas 25cm Ispanaklı 4pcs 240g | F25: 20250825 | G25: KAREKODSUZ ÜRETİLECEK | H25: =IF(B25="","",VLOOKUP(AD25,Varsayımlar!$B:$Q,5,0)) -> Tortillas 25cm Ispanaklı | I25: =IF(B25="","",VLOOKUP(AD25,Varsayımlar!B:T,19,0)) -> 0 | J25: =IF(B25="","",VLOOKUP(AD25,Varsayımlar!$B:$Q,6,0)) -> Ispanaklı | K25: 420 | M25: =IFERROR(IF(B25="","",K25/VLOOKUP(AD25,Varsayımlar!B:R,17,0)),"") -> 5 | P25: =IF(B25="","",VLOOKUP(AD25,Varsayımlar!$B:$Q,7,0)*K25) -> 12600 | Q25: =IF(B25="","",VLOOKUP(AD25,Varsayımlar!$B:$Q,8,0)) -> 25 | R25: =IF(B25="","",VLOOKUP(AD25,Varsayımlar!$B:$Q,9,0)) -> Soft-PA3 | S25: =IF(B25="","",VLOOKUP(AD25,Varsayımlar!$B:$Q,10,0)) -> 4 | T25: =IF(B25="","",VLOOKUP(AD25,Varsayımlar!$B:$Q,11,0)) -> 30 | U25: =IF(B25="","",VLOOKUP(AD25,Varsayımlar!$B:$Q,12,0)) -> 240 | V25: =IF(B25="","",VLOOKUP(AD25,Varsayımlar!$B:$Q,13,0)) -> Yurtdışı | W25: =IF(B25="","",VLOOKUP(AD25,Varsayımlar!$B:$Q,14,0)) -> 12 | AA25: =IF(B25="","",VLOOKUP(AD25,Varsayımlar!$B:$Q,15,0)) -> 25cm Kolisi-Etiketli | AB25: =IF(B25="","",VLOOKUP(AD25,Varsayımlar!$B:$Q,16,0)) -> 24-26 cm (Macca Hetto Inkjet Uzun Tarih) | AC25: =IF(B25="","",VLOOKUP(Sayfa1!AD25,Varsayımlar!B:S,18,0)) -> 80x120cm | AD25: =IF(B25="","",CONCATENATE(B25,E25)) -> LAIKYUZHN-BELARUSTortillas 25cm Ispanaklı 4pcs 240g
A26: 23. | B26: LAIKYUZHN-BELARUS | C26: =IF(B26="","",VLOOKUP(AD26,Varsayımlar!$B:$Q,3,0)) -> 8698829380698 | D26: 1. ARAÇ | E26: Magnit Tortillas 25cm Peynirli 4pcs 240g | F26: 20250825 | G26: KAREKODSUZ ÜRETİLECEK | H26: =IF(B26="","",VLOOKUP(AD26,Varsayımlar!$B:$Q,5,0)) -> Magnit Tortillas 25cm Peynirli | I26: =IF(B26="","",VLOOKUP(AD26,Varsayımlar!B:T,19,0)) -> Etiketli | J26: =IF(B26="","",VLOOKUP(AD26,Varsayımlar!$B:$Q,6,0)) -> Peynirli | K26: 420 | M26: =IFERROR(IF(B26="","",K26/VLOOKUP(AD26,Varsayımlar!B:R,17,0)),"") -> 5 | P26: =IF(B26="","",VLOOKUP(AD26,Varsayımlar!$B:$Q,7,0)*K26) -> 12600 | Q26: =IF(B26="","",VLOOKUP(AD26,Varsayımlar!$B:$Q,8,0)) -> 25 | R26: =IF(B26="","",VLOOKUP(AD26,Varsayımlar!$B:$Q,9,0)) -> Soft-PA3-AT | S26: =IF(B26="","",VLOOKUP(AD26,Varsayımlar!$B:$Q,10,0)) -> 4 | T26: =IF(B26="","",VLOOKUP(AD26,Varsayımlar!$B:$Q,11,0)) -> 30 | U26: =IF(B26="","",VLOOKUP(AD26,Varsayımlar!$B:$Q,12,0)) -> 250 | V26: =IF(B26="","",VLOOKUP(AD26,Varsayımlar!$B:$Q,13,0)) -> Yurtdışı | W26: =IF(B26="","",VLOOKUP(AD26,Varsayımlar!$B:$Q,14,0)) -> 9 | AA26: =IF(B26="","",VLOOKUP(AD26,Varsayımlar!$B:$Q,15,0)) -> 25cm Kolisi-Etiketli | AB26: =IF(B26="","",VLOOKUP(AD26,Varsayımlar!$B:$Q,16,0)) -> 24-26 cm (Macca Hetto Inkjet Uzun Tarih) | AC26: =IF(B26="","",VLOOKUP(Sayfa1!AD26,Varsayımlar!B:S,18,0)) -> 80x120cm | AD26: =IF(B26="","",CONCATENATE(B26,E26)) -> LAIKYUZHN-BELARUSMagnit Tortillas 25cm Peynirli 4pcs 240g
A27: 24. | B27: ALDİ - KOSOVA | C27: =IF(B27="","",VLOOKUP(AD27,Varsayımlar!$B:$Q,3,0)) -> 8698829380698 | E27: Tortillove 30cm 10pcs 900g | F27: 26060101 | H27: =IF(B27="","",VLOOKUP(AD27,Varsayımlar!$B:$Q,5,0)) -> Tortillove 30cm | I27: =IF(B27="","",VLOOKUP(AD27,Varsayımlar!B:T,19,0)) -> Arka kısma Arnavutça içerik-Tortillove | J27: =IF(B27="","",VLOOKUP(AD27,Varsayımlar!$B:$Q,6,0)) -> SADE | K27: 100 | M27: =IFERROR(IF(B27="","",K27/VLOOKUP(AD27,Varsayımlar!B:R,17,0)),"") -> 2 | P27: =IF(B27="","",VLOOKUP(AD27,Varsayımlar!$B:$Q,7,0)*K27) -> 1200 | Q27: =IF(B27="","",VLOOKUP(AD27,Varsayımlar!$B:$Q,8,0)) -> 30 | R27: =IF(B27="","",VLOOKUP(AD27,Varsayımlar!$B:$Q,9,0)) -> Irak Soft | S27: =IF(B27="","",VLOOKUP(AD27,Varsayımlar!$B:$Q,10,0)) -> 10 | T27: =IF(B27="","",VLOOKUP(AD27,Varsayımlar!$B:$Q,11,0)) -> 12 | U27: =IF(B27="","",VLOOKUP(AD27,Varsayımlar!$B:$Q,12,0)) -> 900 | V27: =IF(B27="","",VLOOKUP(AD27,Varsayımlar!$B:$Q,13,0)) -> Yurtdışı | W27: =IF(B27="","",VLOOKUP(AD27,Varsayımlar!$B:$Q,14,0)) -> 12 | AA27: =IF(B27="","",VLOOKUP(AD27,Varsayımlar!$B:$Q,15,0)) -> 30cm Koli - Tortillove 900g Etiketli | AB27: =IF(B27="","",VLOOKUP(AD27,Varsayımlar!$B:$Q,16,0)) -> 29-31 cm | AC27: =IF(B27="","",VLOOKUP(Sayfa1!AD27,Varsayımlar!B:S,18,0)) -> 0 | AD27: =IF(B27="","",CONCATENATE(B27,E27)) -> ALDİ - KOSOVATortillove 30cm 10pcs 900g
A28: 25. | B28: ALDİ - KOSOVA | C28: =IF(B28="","",VLOOKUP(AD28,Varsayımlar!$B:$Q,3,0)) -> 8698829380698 | E28: Tortillas 30cm 10pcs 900g | F28: 26060101 | H28: =IF(B28="","",VLOOKUP(AD28,Varsayımlar!$B:$Q,5,0)) -> Tortillas 30cm | I28: =IF(B28="","",VLOOKUP(AD28,Varsayımlar!B:T,19,0)) -> Arka kısma Arnavutça içerik-Tortillas | J28: =IF(B28="","",VLOOKUP(AD28,Varsayımlar!$B:$Q,6,0)) -> SADE | K28: 50 | M28: =IFERROR(IF(B28="","",K28/VLOOKUP(AD28,Varsayımlar!B:R,17,0)),"") -> 1 | P28: =IF(B28="","",VLOOKUP(AD28,Varsayımlar!$B:$Q,7,0)*K28) -> 600 | Q28: =IF(B28="","",VLOOKUP(AD28,Varsayımlar!$B:$Q,8,0)) -> 30 | R28: =IF(B28="","",VLOOKUP(AD28,Varsayımlar!$B:$Q,9,0)) -> Irak Soft | S28: =IF(B28="","",VLOOKUP(AD28,Varsayımlar!$B:$Q,10,0)) -> 10 | T28: =IF(B28="","",VLOOKUP(AD28,Varsayımlar!$B:$Q,11,0)) -> 12 | U28: =IF(B28="","",VLOOKUP(AD28,Varsayımlar!$B:$Q,12,0)) -> 900 | V28: =IF(B28="","",VLOOKUP(AD28,Varsayımlar!$B:$Q,13,0)) -> Yurtdışı | W28: =IF(B28="","",VLOOKUP(AD28,Varsayımlar!$B:$Q,14,0)) -> 12 | AA28: =IF(B28="","",VLOOKUP(AD28,Varsayımlar!$B:$Q,15,0)) -> 30cm Koli - Tortillas 900g Etiketli | AB28: =IF(B28="","",VLOOKUP(AD28,Varsayımlar!$B:$Q,16,0)) -> 29-31 cm | AC28: =IF(B28="","",VLOOKUP(Sayfa1!AD28,Varsayımlar!B:S,18,0)) -> 0 | AD28: =IF(B28="","",CONCATENATE(B28,E28)) -> ALDİ - KOSOVATortillas 30cm 10pcs 900g
A29: 26. | B29: ALDİ - KOSOVA | C29: =IF(B29="","",VLOOKUP(AD29,Varsayımlar!$B:$Q,3,0)) -> 8698829380698 | E29: Tortillove 25cm 6pcs 390g | F29: 26060101 | H29: =IF(B29="","",VLOOKUP(AD29,Varsayımlar!$B:$Q,5,0)) -> Tortillove 25cm | I29: =IF(B29="","",VLOOKUP(AD29,Varsayımlar!B:T,19,0)) -> Barkod üzerine Arnavutça içerik+Barkod-Tortillove | J29: =IF(B29="","",VLOOKUP(AD29,Varsayımlar!$B:$Q,6,0)) -> SADE | K29: 84 | M29: =IFERROR(IF(B29="","",K29/VLOOKUP(AD29,Varsayımlar!B:R,17,0)),"") -> 1 | P29: =IF(B29="","",VLOOKUP(AD29,Varsayımlar!$B:$Q,7,0)*K29) -> 1512 | Q29: =IF(B29="","",VLOOKUP(AD29,Varsayımlar!$B:$Q,8,0)) -> 25 | R29: =IF(B29="","",VLOOKUP(AD29,Varsayımlar!$B:$Q,9,0)) -> Irak Soft | S29: =IF(B29="","",VLOOKUP(AD29,Varsayımlar!$B:$Q,10,0)) -> 6 | T29: =IF(B29="","",VLOOKUP(AD29,Varsayımlar!$B:$Q,11,0)) -> 18 | U29: =IF(B29="","",VLOOKUP(AD29,Varsayımlar!$B:$Q,12,0)) -> 390 | V29: =IF(B29="","",VLOOKUP(AD29,Varsayımlar!$B:$Q,13,0)) -> Yurtdışı | W29: =IF(B29="","",VLOOKUP(AD29,Varsayımlar!$B:$Q,14,0)) -> 12 | AA29: =IF(B29="","",VLOOKUP(AD29,Varsayımlar!$B:$Q,15,0)) -> 25cm Koli - Tortillove 390g Etiketli | AB29: =IF(B29="","",VLOOKUP(AD29,Varsayımlar!$B:$Q,16,0)) -> 24-26 cm | AC29: =IF(B29="","",VLOOKUP(Sayfa1!AD29,Varsayımlar!B:S,18,0)) -> 0 | AD29: =IF(B29="","",CONCATENATE(B29,E29)) -> ALDİ - KOSOVATortillove 25cm 6pcs 390g
A30: 27. | B30: ALDİ - KOSOVA | C30: =IF(B30="","",VLOOKUP(AD30,Varsayımlar!$B:$Q,3,0)) -> 8698829380698 | E30: Tortillas 25cm 6pcs 390g | F30: 26060101 | H30: =IF(B30="","",VLOOKUP(AD30,Varsayımlar!$B:$Q,5,0)) -> Tortillas 25cm | I30: =IF(B30="","",VLOOKUP(AD30,Varsayımlar!B:T,19,0)) -> Barkod üzerine Arnavutça içerik+Barkod-Tortillas | J30: =IF(B30="","",VLOOKUP(AD30,Varsayımlar!$B:$Q,6,0)) -> SADE | K30: 84 | M30: =IFERROR(IF(B30="","",K30/VLOOKUP(AD30,Varsayımlar!B:R,17,0)),"") -> 1 | P30: =IF(B30="","",VLOOKUP(AD30,Varsayımlar!$B:$Q,7,0)*K30) -> 1512 | Q30: =IF(B30="","",VLOOKUP(AD30,Varsayımlar!$B:$Q,8,0)) -> 25 | R30: =IF(B30="","",VLOOKUP(AD30,Varsayımlar!$B:$Q,9,0)) -> Irak Soft | S30: =IF(B30="","",VLOOKUP(AD30,Varsayımlar!$B:$Q,10,0)) -> 6 | T30: =IF(B30="","",VLOOKUP(AD30,Varsayımlar!$B:$Q,11,0)) -> 18 | U30: =IF(B30="","",VLOOKUP(AD30,Varsayımlar!$B:$Q,12,0)) -> 390 | V30: =IF(B30="","",VLOOKUP(AD30,Varsayımlar!$B:$Q,13,0)) -> Yurtdışı | W30: =IF(B30="","",VLOOKUP(AD30,Varsayımlar!$B:$Q,14,0)) -> 12 | AA30: =IF(B30="","",VLOOKUP(AD30,Varsayımlar!$B:$Q,15,0)) -> 25cm Koli - Tortillas 390g Etiketli | AB30: =IF(B30="","",VLOOKUP(AD30,Varsayımlar!$B:$Q,16,0)) -> 24-26 cm | AC30: =IF(B30="","",VLOOKUP(Sayfa1!AD30,Varsayımlar!B:S,18,0)) -> 0 | AD30: =IF(B30="","",CONCATENATE(B30,E30)) -> ALDİ - KOSOVATortillas 25cm 6pcs 390g
A31: 28. | B31: ALDİ - KOSOVA | C31: =IF(B31="","",VLOOKUP(AD31,Varsayımlar!$B:$Q,3,0)) -> 8698829380698 | E31: Tortillove 25cm 6pcs 390g | F31: 26060101 | H31: =IF(B31="","",VLOOKUP(AD31,Varsayımlar!$B:$Q,5,0)) -> Tortillove 25cm | I31: =IF(B31="","",VLOOKUP(AD31,Varsayımlar!B:T,19,0)) -> Barkod üzerine Arnavutça içerik+Barkod-Tortillove | J31: =IF(B31="","",VLOOKUP(AD31,Varsayımlar!$B:$Q,6,0)) -> SADE | K31: 168 | M31: =IFERROR(IF(B31="","",K31/VLOOKUP(AD31,Varsayımlar!B:R,17,0)),"") -> 2 | P31: =IF(B31="","",VLOOKUP(AD31,Varsayımlar!$B:$Q,7,0)*K31) -> 3024 | Q31: =IF(B31="","",VLOOKUP(AD31,Varsayımlar!$B:$Q,8,0)) -> 25 | R31: =IF(B31="","",VLOOKUP(AD31,Varsayımlar!$B:$Q,9,0)) -> Irak Soft | S31: =IF(B31="","",VLOOKUP(AD31,Varsayımlar!$B:$Q,10,0)) -> 6 | T31: =IF(B31="","",VLOOKUP(AD31,Varsayımlar!$B:$Q,11,0)) -> 18 | U31: =IF(B31="","",VLOOKUP(AD31,Varsayımlar!$B:$Q,12,0)) -> 390 | V31: =IF(B31="","",VLOOKUP(AD31,Varsayımlar!$B:$Q,13,0)) -> Yurtdışı | W31: =IF(B31="","",VLOOKUP(AD31,Varsayımlar!$B:$Q,14,0)) -> 12 | AA31: =IF(B31="","",VLOOKUP(AD31,Varsayımlar!$B:$Q,15,0)) -> 25cm Koli - Tortillove 390g Etiketli | AB31: =IF(B31="","",VLOOKUP(AD31,Varsayımlar!$B:$Q,16,0)) -> 24-26 cm | AC31: =IF(B31="","",VLOOKUP(Sayfa1!AD31,Varsayımlar!B:S,18,0)) -> 0 | AD31: =IF(B31="","",CONCATENATE(B31,E31)) -> ALDİ - KOSOVATortillove 25cm 6pcs 390g
A32: 29. | B32: ALDİ - KOSOVA | C32: =IF(B32="","",VLOOKUP(AD32,Varsayımlar!$B:$Q,3,0)) -> 8698829380698 | E32: Tortillas 25cm 6pcs 390g | F32: 26060101 | H32: =IF(B32="","",VLOOKUP(AD32,Varsayımlar!$B:$Q,5,0)) -> Tortillas 25cm | I32: =IF(B32="","",VLOOKUP(AD32,Varsayımlar!B:T,19,0)) -> Barkod üzerine Arnavutça içerik+Barkod-Tortillas | J32: =IF(B32="","",VLOOKUP(AD32,Varsayımlar!$B:$Q,6,0)) -> SADE | K32: 84 | M32: =IFERROR(IF(B32="","",K32/VLOOKUP(AD32,Varsayımlar!B:R,17,0)),"") -> 1 | P32: =IF(B32="","",VLOOKUP(AD32,Varsayımlar!$B:$Q,7,0)*K32) -> 1512 | Q32: =IF(B32="","",VLOOKUP(AD32,Varsayımlar!$B:$Q,8,0)) -> 25 | R32: =IF(B32="","",VLOOKUP(AD32,Varsayımlar!$B:$Q,9,0)) -> Irak Soft | S32: =IF(B32="","",VLOOKUP(AD32,Varsayımlar!$B:$Q,10,0)) -> 6 | T32: =IF(B32="","",VLOOKUP(AD32,Varsayımlar!$B:$Q,11,0)) -> 18 | U32: =IF(B32="","",VLOOKUP(AD32,Varsayımlar!$B:$Q,12,0)) -> 390 | V32: =IF(B32="","",VLOOKUP(AD32,Varsayımlar!$B:$Q,13,0)) -> Yurtdışı | W32: =IF(B32="","",VLOOKUP(AD32,Varsayımlar!$B:$Q,14,0)) -> 12 | AA32: =IF(B32="","",VLOOKUP(AD32,Varsayımlar!$B:$Q,15,0)) -> 25cm Koli - Tortillas 390g Etiketli | AB32: =IF(B32="","",VLOOKUP(AD32,Varsayımlar!$B:$Q,16,0)) -> 24-26 cm | AC32: =IF(B32="","",VLOOKUP(Sayfa1!AD32,Varsayımlar!B:S,18,0)) -> 0 | AD32: =IF(B32="","",CONCATENATE(B32,E32)) -> ALDİ - KOSOVATortillas 25cm 6pcs 390g
A33: 30. | B33: ALDİ - KOSOVA | C33: =IF(B33="","",VLOOKUP(AD33,Varsayımlar!$B:$Q,3,0)) -> 8698829380698 | E33: Tortillove 25cm 10pcs 650g | F33: 26060101 | H33: =IF(B33="","",VLOOKUP(AD33,Varsayımlar!$B:$Q,5,0)) -> Tortillove 25cm | I33: =IF(B33="","",VLOOKUP(AD33,Varsayımlar!B:T,19,0)) -> Arka kısma Arnavutça içerik-Tortillove | J33: =IF(B33="","",VLOOKUP(AD33,Varsayımlar!$B:$Q,6,0)) -> SADE | K33: 168 | M33: =IFERROR(IF(B33="","",K33/VLOOKUP(AD33,Varsayımlar!B:R,17,0)),"") -> 2 | P33: =IF(B33="","",VLOOKUP(AD33,Varsayımlar!$B:$Q,7,0)*K33) -> 2016 | Q33: =IF(B33="","",VLOOKUP(AD33,Varsayımlar!$B:$Q,8,0)) -> 25 | R33: =IF(B33="","",VLOOKUP(AD33,Varsayımlar!$B:$Q,9,0)) -> Irak Soft | S33: =IF(B33="","",VLOOKUP(AD33,Varsayımlar!$B:$Q,10,0)) -> 10 | T33: =IF(B33="","",VLOOKUP(AD33,Varsayımlar!$B:$Q,11,0)) -> 12 | U33: =IF(B33="","",VLOOKUP(AD33,Varsayımlar!$B:$Q,12,0)) -> 650 | V33: =IF(B33="","",VLOOKUP(AD33,Varsayımlar!$B:$Q,13,0)) -> Yurtdışı | W33: =IF(B33="","",VLOOKUP(AD33,Varsayımlar!$B:$Q,14,0)) -> 12 | AA33: =IF(B33="","",VLOOKUP(AD33,Varsayımlar!$B:$Q,15,0)) -> 25cm Koli - Tortillove 650g Etiketli | AB33: =IF(B33="","",VLOOKUP(AD33,Varsayımlar!$B:$Q,16,0)) -> 24-26 cm | AC33: =IF(B33="","",VLOOKUP(Sayfa1!AD33,Varsayımlar!B:S,18,0)) -> 0 | AD33: =IF(B33="","",CONCATENATE(B33,E33)) -> ALDİ - KOSOVATortillove 25cm 10pcs 650g
A34: 31. | B34: ALDİ - KOSOVA | C34: =IF(B34="","",VLOOKUP(AD34,Varsayımlar!$B:$Q,3,0)) -> 8698829380698 | E34: Tortillas 25cm 10pcs 650g | F34: 26060101 | H34: =IF(B34="","",VLOOKUP(AD34,Varsayımlar!$B:$Q,5,0)) -> Tortillas 25cm | I34: =IF(B34="","",VLOOKUP(AD34,Varsayımlar!B:T,19,0)) -> Arka kısma Arnavutça içerik-Tortillas | J34: =IF(B34="","",VLOOKUP(AD34,Varsayımlar!$B:$Q,6,0)) -> SADE | K34: 84 | M34: =IFERROR(IF(B34="","",K34/VLOOKUP(AD34,Varsayımlar!B:R,17,0)),"") -> 1 | P34: =IF(B34="","",VLOOKUP(AD34,Varsayımlar!$B:$Q,7,0)*K34) -> 1008 | Q34: =IF(B34="","",VLOOKUP(AD34,Varsayımlar!$B:$Q,8,0)) -> 25 | R34: =IF(B34="","",VLOOKUP(AD34,Varsayımlar!$B:$Q,9,0)) -> Irak Soft | S34: =IF(B34="","",VLOOKUP(AD34,Varsayımlar!$B:$Q,10,0)) -> 10 | T34: =IF(B34="","",VLOOKUP(AD34,Varsayımlar!$B:$Q,11,0)) -> 12 | U34: =IF(B34="","",VLOOKUP(AD34,Varsayımlar!$B:$Q,12,0)) -> 650 | V34: =IF(B34="","",VLOOKUP(AD34,Varsayımlar!$B:$Q,13,0)) -> Yurtdışı | W34: =IF(B34="","",VLOOKUP(AD34,Varsayımlar!$B:$Q,14,0)) -> 12 | AA34: =IF(B34="","",VLOOKUP(AD34,Varsayımlar!$B:$Q,15,0)) -> 25cm Koli - Tortillas 650g Etiketli | AB34: =IF(B34="","",VLOOKUP(AD34,Varsayımlar!$B:$Q,16,0)) -> 24-26 cm | AC34: =IF(B34="","",VLOOKUP(Sayfa1!AD34,Varsayımlar!B:S,18,0)) -> 0 | AD34: =IF(B34="","",CONCATENATE(B34,E34)) -> ALDİ - KOSOVATortillas 25cm 10pcs 650g
