Workbook

Sheet Bilgiler
B2: Aksiyon Bilgileri | D2: Ambalaj Bilgiler | N2: Analiz
B3: Kalem | D3: Stok Adı | E3: Kod | F3: Giriş | G3: Sayım (kg) | H3: Tedarikçiden Satın Alım | I3: Üretime Teslim Etme | J3: Üretimden Geri Alım | K3: Tedarikçiye Geri İade | L3: Son Durum | N3: Kod | O3: Ürün | P3: Parti Numarası | Q3: Son Kullanma Tarihi | R3: Kalan Süre (gün) | S3: Sayım (kg) | T3: Tedarikçiden Satın Alım | U3: Üretime Teslim Etme | V3: Üretimden Geri Alım | W3: Tedarikçiye Geri İade | X3: Son Durum | Y3: Risk | AA3: Tedarikçi | AC3: Kalite
B4: Tedarikçiden Satın Alım | D4: Poşet- 20 Cm Eyal Berman Tortilla 360 gr. | E4: 150.01.272 | F4: Mevcut | H4: =SUMIFS(Giriş!$J:$J,Giriş!$H:$H,Bilgiler!H$3,Giriş!$C:$C,Bilgiler!$D4) -> 0 | I4: =SUMIFS(Giriş!$J:$J,Giriş!$H:$H,Bilgiler!I$3,Giriş!$C:$C,Bilgiler!$D4) -> 0 | J4: =SUMIFS(Giriş!$J:$J,Giriş!$H:$H,Bilgiler!J$3,Giriş!$C:$C,Bilgiler!$D4) -> 0 | K4: =SUMIFS(Giriş!$J:$J,Giriş!$H:$H,Bilgiler!K$3,Giriş!$C:$C,Bilgiler!$D4) -> 0 | L4: =G4+H4-I4-K4+J4 -> 0 | N4: 1 | O4: =IF($N4="","",VLOOKUP($N4,Giriş!$L:$O,2,0)) -> Poşet-25 cm Mutlukal Tortillas 260 Gr ( Rusca ) | P4: =IF($N4="","",VLOOKUP($N4,Giriş!$L:$O,3,0)) -> MAT007938 | Q4: =IF($N4="","",VLOOKUP($N4,Giriş!$L:$O,4,0)) -> 45401 | R4: =IF(O4="","",IF(X4<=0,"",Q4-TODAY())) -> -181 | S4: =SUMIFS(G:G,D:D,O4,F:F,P4) -> 0 | T4: =SUMIFS(Giriş!$J:$J,Giriş!$H:$H,Bilgiler!T$3,Giriş!$C:$C,Bilgiler!$O4,Giriş!$E:$E,Bilgiler!$P4) -> 3011800 | U4: =SUMIFS(Giriş!$J:$J,Giriş!$H:$H,Bilgiler!U$3,Giriş!$C:$C,Bilgiler!$O4,Giriş!$E:$E,Bilgiler!$P4) -> 0 | V4: =SUMIFS(Giriş!$J:$J,Giriş!$H:$H,Bilgiler!V$3,Giriş!$C:$C,Bilgiler!$O4,Giriş!$E:$E,Bilgiler!$P4) -> 0 | W4: =SUMIFS(Giriş!$J:$J,Giriş!$H:$H,Bilgiler!W$3,Giriş!$C:$C,Bilgiler!$O4,Giriş!$E:$E,Bilgiler!$P4) -> 0 | X4: =S4+T4+V4-W4-U4 -> 3011800 | Y4: =IF(R4<0,IF(X4>0,"Raf Ömrü Geçti",""),IF(R4<=15,IF(X4>0,"Raf Ömrü Bitmek Üzere",""),"")) -> Raf Ömrü Geçti | AA4: Ege Plastik Ambalaj San.ve Tic.A.Ş. | AC4: Uygun
B5: Üretime Teslim Etme | D5: Poşet- 20 Cm Tomer Tortilla 320 gr. | E5: 150.01.319 | F5: Mevcut | H5: =SUMIFS(Giriş!$J:$J,Giriş!$H:$H,Bilgiler!H$3,Giriş!$C:$C,Bilgiler!$D5) -> 0 | I5: =SUMIFS(Giriş!$J:$J,Giriş!$H:$H,Bilgiler!I$3,Giriş!$C:$C,Bilgiler!$D5) -> 0 | J5: =SUMIFS(Giriş!$J:$J,Giriş!$H:$H,Bilgiler!J$3,Giriş!$C:$C,Bilgiler!$D5) -> 0 | K5: =SUMIFS(Giriş!$J:$J,Giriş!$H:$H,Bilgiler!K$3,Giriş!$C:$C,Bilgiler!$D5) -> 0 | L5: =G5+H5-I5-K5+J5 -> 0 | N5: =IFERROR(IF(N4+1>MAX(Giriş!L:L),"",N4+1),"") -> 2 | O5: =IF($N5="","",VLOOKUP($N5,Giriş!$L:$O,2,0)) -> Poşet-25 cm Mutlukal Tortillas Mavi Değişken | P5: =IF($N5="","",VLOOKUP($N5,Giriş!$L:$O,3,0)) -> MAT008069 | Q5: =IF($N5="","",VLOOKUP($N5,Giriş!$L:$O,4,0)) -> 45401 | R5: =IF(O5="","",IF(X5<=0,"",Q5-TODAY())) -> -181 | S5: =SUMIFS(G:G,D:D,O5,F:F,P5) -> 0 | T5: =SUMIFS(Giriş!$J:$J,Giriş!$H:$H,Bilgiler!T$3,Giriş!$C:$C,Bilgiler!$O5,Giriş!$E:$E,Bilgiler!$P5) -> 82600 | U5: =SUMIFS(Giriş!$J:$J,Giriş!$H:$H,Bilgiler!U$3,Giriş!$C:$C,Bilgiler!$O5,Giriş!$E:$E,Bilgiler!$P5) -> 0 | V5: =SUMIFS(Giriş!$J:$J,Giriş!$H:$H,Bilgiler!V$3,Giriş!$C:$C,Bilgiler!$O5,Giriş!$E:$E,Bilgiler!$P5) -> 0 | W5: =SUMIFS(Giriş!$J:$J,Giriş!$H:$H,Bilgiler!W$3,Giriş!$C:$C,Bilgiler!$O5,Giriş!$E:$E,Bilgiler!$P5) -> 0 | X5: =S5+T5+V5-W5-U5 -> 82600 | Y5: =IF(R5<0,IF(X5>0,"Raf Ömrü Geçti",""),IF(R5<=15,IF(X5>0,"Raf Ömrü Bitmek Üzere",""),"")) -> Raf Ömrü Geçti | AA5: Artı Ambalaj ve Gıda Ürünleri Turizm San.Tic.Ltd.Şti. | AC5: Uygun Değil
B6: Üretimden Geri Alım | D6: Poşet- 20 Cm Winfood Yehuda Tortilla 360 gr. | E6: 150.01.317 | F6: Mevcut | H6: =SUMIFS(Giriş!$J:$J,Giriş!$H:$H,Bilgiler!H$3,Giriş!$C:$C,Bilgiler!$D6) -> 0 | I6: =SUMIFS(Giriş!$J:$J,Giriş!$H:$H,Bilgiler!I$3,Giriş!$C:$C,Bilgiler!$D6) -> 0 | J6: =SUMIFS(Giriş!$J:$J,Giriş!$H:$H,Bilgiler!J$3,Giriş!$C:$C,Bilgiler!$D6) -> 0 | K6: =SUMIFS(Giriş!$J:$J,Giriş!$H:$H,Bilgiler!K$3,Giriş!$C:$C,Bilgiler!$D6) -> 0 | L6: =G6+H6-I6-K6+J6 -> 0 | N6: =IFERROR(IF(N5+1>MAX(Giriş!L:L),"",N5+1),"") -> 3 | O6: =IF($N6="","",VLOOKUP($N6,Giriş!$L:$O,2,0)) -> Poşet-30 cm Sofias | P6: =IF($N6="","",VLOOKUP($N6,Giriş!$L:$O,3,0)) -> MAT008034 | Q6: =IF($N6="","",VLOOKUP($N6,Giriş!$L:$O,4,0)) -> 45407 | R6: =IF(O6="","",IF(X6<=0,"",Q6-TODAY())) -> -175 | S6: =SUMIFS(G:G,D:D,O6,F:F,P6) -> 0 | T6: =SUMIFS(Giriş!$J:$J,Giriş!$H:$H,Bilgiler!T$3,Giriş!$C:$C,Bilgiler!$O6,Giriş!$E:$E,Bilgiler!$P6) -> 38400 | U6: =SUMIFS(Giriş!$J:$J,Giriş!$H:$H,Bilgiler!U$3,Giriş!$C:$C,Bilgiler!$O6,Giriş!$E:$E,Bilgiler!$P6) -> 0 | V6: =SUMIFS(Giriş!$J:$J,Giriş!$H:$H,Bilgiler!V$3,Giriş!$C:$C,Bilgiler!$O6,Giriş!$E:$E,Bilgiler!$P6) -> 0 | W6: =SUMIFS(Giriş!$J:$J,Giriş!$H:$H,Bilgiler!W$3,Giriş!$C:$C,Bilgiler!$O6,Giriş!$E:$E,Bilgiler!$P6) -> 0 | X6: =S6+T6+V6-W6-U6 -> 38400 | Y6: =IF(R6<0,IF(X6>0,"Raf Ömrü Geçti",""),IF(R6<=15,IF(X6>0,"Raf Ömrü Bitmek Üzere",""),"")) -> Raf Ömrü Geçti | AA6: Egemen Hediyelik Eşya Oyuncak Züccaciye Elektronik Gıda Tekstil İnş.Ambalaj San.ve Tic.A.Ş.
B7: Tedarikçiye Geri İade | D7: Poşet- 25 Cm Tomer Tortilla 420 gr. | E7: 150.01.318 | F7: Mevcut | H7: =SUMIFS(Giriş!$J:$J,Giriş!$H:$H,Bilgiler!H$3,Giriş!$C:$C,Bilgiler!$D7) -> 0 | I7: =SUMIFS(Giriş!$J:$J,Giriş!$H:$H,Bilgiler!I$3,Giriş!$C:$C,Bilgiler!$D7) -> 0 | J7: =SUMIFS(Giriş!$J:$J,Giriş!$H:$H,Bilgiler!J$3,Giriş!$C:$C,Bilgiler!$D7) -> 0 | K7: =SUMIFS(Giriş!$J:$J,Giriş!$H:$H,Bilgiler!K$3,Giriş!$C:$C,Bilgiler!$D7) -> 0 | L7: =G7+H7-I7-K7+J7 -> 0 | N7: =IFERROR(IF(N6+1>MAX(Giriş!L:L),"",N6+1),"") -> 4 | O7: =IF($N7="","",VLOOKUP($N7,Giriş!$L:$O,2,0)) -> Poşet-30 cm İpek | P7: =IF($N7="","",VLOOKUP($N7,Giriş!$L:$O,3,0)) -> 45231 | Q7: =IF($N7="","",VLOOKUP($N7,Giriş!$L:$O,4,0)) -> 45348 | R7: =IF(O7="","",IF(X7<=0,"",Q7-TODAY())) -> -234 | S7: =SUMIFS(G:G,D:D,O7,F:F,P7) -> 0 | T7: =SUMIFS(Giriş!$J:$J,Giriş!$H:$H,Bilgiler!T$3,Giriş!$C:$C,Bilgiler!$O7,Giriş!$E:$E,Bilgiler!$P7) -> 4000 | U7: =SUMIFS(Giriş!$J:$J,Giriş!$H:$H,Bilgiler!U$3,Giriş!$C:$C,Bilgiler!$O7,Giriş!$E:$E,Bilgiler!$P7) -> 0 | V7: =SUMIFS(Giriş!$J:$J,Giriş!$H:$H,Bilgiler!V$3,Giriş!$C:$C,Bilgiler!$O7,Giriş!$E:$E,Bilgiler!$P7) -> 0 | W7: =SUMIFS(Giriş!$J:$J,Giriş!$H:$H,Bilgiler!W$3,Giriş!$C:$C,Bilgiler!$O7,Giriş!$E:$E,Bilgiler!$P7) -> 0 | X7: =S7+T7+V7-W7-U7 -> 4000 | Y7: =IF(R7<0,IF(X7>0,"Raf Ömrü Geçti",""),IF(R7<=15,IF(X7>0,"Raf Ömrü Bitmek Üzere",""),"")) -> Raf Ömrü Geçti | AA7: Enpak Matbaa ve Ambalaj Sanayi ve Tic.A.Ş. ( Usd )
D8: Poşet- 30 Cm Tomer Tortilla 640 gr. | E8: 150.01.320 | F8: Mevcut | H8: =SUMIFS(Giriş!$J:$J,Giriş!$H:$H,Bilgiler!H$3,Giriş!$C:$C,Bilgiler!$D8) -> 0 | I8: =SUMIFS(Giriş!$J:$J,Giriş!$H:$H,Bilgiler!I$3,Giriş!$C:$C,Bilgiler!$D8) -> 0 | J8: =SUMIFS(Giriş!$J:$J,Giriş!$H:$H,Bilgiler!J$3,Giriş!$C:$C,Bilgiler!$D8) -> 0 | K8: =SUMIFS(Giriş!$J:$J,Giriş!$H:$H,Bilgiler!K$3,Giriş!$C:$C,Bilgiler!$D8) -> 0 | L8: =G8+H8-I8-K8+J8 -> 0 | N8: =IFERROR(IF(N7+1>MAX(Giriş!L:L),"",N7+1),"") -> 5 | O8: =IF($N8="","",VLOOKUP($N8,Giriş!$L:$O,2,0)) -> Poşet-20 cm B.sız Kilitli | P8: =IF($N8="","",VLOOKUP($N8,Giriş!$L:$O,3,0)) -> MAT008070 | Q8: =IF($N8="","",VLOOKUP($N8,Giriş!$L:$O,4,0)) -> 45472 | R8: =IF(O8="","",IF(X8<=0,"",Q8-TODAY())) -> -110 | S8: =SUMIFS(G:G,D:D,O8,F:F,P8) -> 0 | T8: =SUMIFS(Giriş!$J:$J,Giriş!$H:$H,Bilgiler!T$3,Giriş!$C:$C,Bilgiler!$O8,Giriş!$E:$E,Bilgiler!$P8) -> 104400 | U8: =SUMIFS(Giriş!$J:$J,Giriş!$H:$H,Bilgiler!U$3,Giriş!$C:$C,Bilgiler!$O8,Giriş!$E:$E,Bilgiler!$P8) -> 0 | V8: =SUMIFS(Giriş!$J:$J,Giriş!$H:$H,Bilgiler!V$3,Giriş!$C:$C,Bilgiler!$O8,Giriş!$E:$E,Bilgiler!$P8) -> 0 | W8: =SUMIFS(Giriş!$J:$J,Giriş!$H:$H,Bilgiler!W$3,Giriş!$C:$C,Bilgiler!$O8,Giriş!$E:$E,Bilgiler!$P8) -> 0 | X8: =S8+T8+V8-W8-U8 -> 104400 | Y8: =IF(R8<0,IF(X8>0,"Raf Ömrü Geçti",""),IF(R8<=15,IF(X8>0,"Raf Ömrü Bitmek Üzere",""),"")) -> Raf Ömrü Geçti | AA8: Etki Plastik Ambalaj San.Tic.A.Ş. - Usd
D9: Poşet-15 cm 250gr Hessa | E9: 150.01.329 | F9: Mevcut | H9: =SUMIFS(Giriş!$J:$J,Giriş!$H:$H,Bilgiler!H$3,Giriş!$C:$C,Bilgiler!$D9) -> 0 | I9: =SUMIFS(Giriş!$J:$J,Giriş!$H:$H,Bilgiler!I$3,Giriş!$C:$C,Bilgiler!$D9) -> 0 | J9: =SUMIFS(Giriş!$J:$J,Giriş!$H:$H,Bilgiler!J$3,Giriş!$C:$C,Bilgiler!$D9) -> 0 | K9: =SUMIFS(Giriş!$J:$J,Giriş!$H:$H,Bilgiler!K$3,Giriş!$C:$C,Bilgiler!$D9) -> 0 | L9: =G9+H9-I9-K9+J9 -> 0 | N9: =IFERROR(IF(N8+1>MAX(Giriş!L:L),"",N8+1),"") -> 6 | O9: =IF($N9="","",VLOOKUP($N9,Giriş!$L:$O,2,0)) -> Poşet-30 cm Mutlukal Tortillas Değişken | P9: =IF($N9="","",VLOOKUP($N9,Giriş!$L:$O,3,0)) -> 20230038 | Q9: =IF($N9="","",VLOOKUP($N9,Giriş!$L:$O,4,0)) -> 45483 | R9: =IF(O9="","",IF(X9<=0,"",Q9-TODAY())) -> -99 | S9: =SUMIFS(G:G,D:D,O9,F:F,P9) -> 0 | T9: =SUMIFS(Giriş!$J:$J,Giriş!$H:$H,Bilgiler!T$3,Giriş!$C:$C,Bilgiler!$O9,Giriş!$E:$E,Bilgiler!$P9) -> 68160 | U9: =SUMIFS(Giriş!$J:$J,Giriş!$H:$H,Bilgiler!U$3,Giriş!$C:$C,Bilgiler!$O9,Giriş!$E:$E,Bilgiler!$P9) -> 0 | V9: =SUMIFS(Giriş!$J:$J,Giriş!$H:$H,Bilgiler!V$3,Giriş!$C:$C,Bilgiler!$O9,Giriş!$E:$E,Bilgiler!$P9) -> 0 | W9: =SUMIFS(Giriş!$J:$J,Giriş!$H:$H,Bilgiler!W$3,Giriş!$C:$C,Bilgiler!$O9,Giriş!$E:$E,Bilgiler!$P9) -> 0 | X9: =S9+T9+V9-W9-U9 -> 68160 | Y9: =IF(R9<0,IF(X9>0,"Raf Ömrü Geçti",""),IF(R9<=15,IF(X9>0,"Raf Ömrü Bitmek Üzere",""),"")) -> Raf Ömrü Geçti | AA9: Mutlukal Gıda Üretim
D10: Poşet-15 cm Alkafeel 10 Adet | E10: 150.01.255 | F10: Mevcut | H10: =SUMIFS(Giriş!$J:$J,Giriş!$H:$H,Bilgiler!H$3,Giriş!$C:$C,Bilgiler!$D10) -> 112000 | I10: =SUMIFS(Giriş!$J:$J,Giriş!$H:$H,Bilgiler!I$3,Giriş!$C:$C,Bilgiler!$D10) -> 0 | J10: =SUMIFS(Giriş!$J:$J,Giriş!$H:$H,Bilgiler!J$3,Giriş!$C:$C,Bilgiler!$D10) -> 0 | K10: =SUMIFS(Giriş!$J:$J,Giriş!$H:$H,Bilgiler!K$3,Giriş!$C:$C,Bilgiler!$D10) -> 0 | L10: =G10+H10-I10-K10+J10 -> 112000 | N10: =IFERROR(IF(N9+1>MAX(Giriş!L:L),"",N9+1),"") -> 7 | O10: =IF($N10="","",VLOOKUP($N10,Giriş!$L:$O,2,0)) -> Poşet--15 cm Mutlukal Tortillas Mavi Değişken | P10: =IF($N10="","",VLOOKUP($N10,Giriş!$L:$O,3,0)) -> 20230040 | Q10: =IF($N10="","",VLOOKUP($N10,Giriş!$L:$O,4,0)) -> 45492 | R10: =IF(O10="","",IF(X10<=0,"",Q10-TODAY())) -> -90 | S10: =SUMIFS(G:G,D:D,O10,F:F,P10) -> 0 | T10: =SUMIFS(Giriş!$J:$J,Giriş!$H:$H,Bilgiler!T$3,Giriş!$C:$C,Bilgiler!$O10,Giriş!$E:$E,Bilgiler!$P10) -> 182945 | U10: =SUMIFS(Giriş!$J:$J,Giriş!$H:$H,Bilgiler!U$3,Giriş!$C:$C,Bilgiler!$O10,Giriş!$E:$E,Bilgiler!$P10) -> 0 | V10: =SUMIFS(Giriş!$J:$J,Giriş!$H:$H,Bilgiler!V$3,Giriş!$C:$C,Bilgiler!$O10,Giriş!$E:$E,Bilgiler!$P10) -> 0 | W10: =SUMIFS(Giriş!$J:$J,Giriş!$H:$H,Bilgiler!W$3,Giriş!$C:$C,Bilgiler!$O10,Giriş!$E:$E,Bilgiler!$P10) -> 0 | X10: =S10+T10+V10-W10-U10 -> 182945 | Y10: =IF(R10<0,IF(X10>0,"Raf Ömrü Geçti",""),IF(R10<=15,IF(X10>0,"Raf Ömrü Bitmek Üzere",""),"")) -> Raf Ömrü Geçti | AA10: Gaziantepli Habeş Seyidoğlu Baklavaları ve Uluslararası Nakliyat Sanayi Ticaret Ltd.Şti.
D11: Poşet-15 cm B.sız Kilitli | E11: 150.01.032 | F11: Mevcut | H11: =SUMIFS(Giriş!$J:$J,Giriş!$H:$H,Bilgiler!H$3,Giriş!$C:$C,Bilgiler!$D11) -> 0 | I11: =SUMIFS(Giriş!$J:$J,Giriş!$H:$H,Bilgiler!I$3,Giriş!$C:$C,Bilgiler!$D11) -> 0 | J11: =SUMIFS(Giriş!$J:$J,Giriş!$H:$H,Bilgiler!J$3,Giriş!$C:$C,Bilgiler!$D11) -> 0 | K11: =SUMIFS(Giriş!$J:$J,Giriş!$H:$H,Bilgiler!K$3,Giriş!$C:$C,Bilgiler!$D11) -> 0 | L11: =G11+H11-I11-K11+J11 -> 0 | N11: =IFERROR(IF(N10+1>MAX(Giriş!L:L),"",N10+1),"") -> 8 | O11: =IF($N11="","",VLOOKUP($N11,Giriş!$L:$O,2,0)) -> Poşet-25 cm Mutlukal Tortillas Kırmızı Değişken ( Beyaz Rusya ) | P11: =IF($N11="","",VLOOKUP($N11,Giriş!$L:$O,3,0)) -> 20230048 | Q11: =IF($N11="","",VLOOKUP($N11,Giriş!$L:$O,4,0)) -> 45483 | R11: =IF(O11="","",IF(X11<=0,"",Q11-TODAY())) -> -99 | S11: =SUMIFS(G:G,D:D,O11,F:F,P11) -> 0 | T11: =SUMIFS(Giriş!$J:$J,Giriş!$H:$H,Bilgiler!T$3,Giriş!$C:$C,Bilgiler!$O11,Giriş!$E:$E,Bilgiler!$P11) -> 89050 | U11: =SUMIFS(Giriş!$J:$J,Giriş!$H:$H,Bilgiler!U$3,Giriş!$C:$C,Bilgiler!$O11,Giriş!$E:$E,Bilgiler!$P11) -> 0 | V11: =SUMIFS(Giriş!$J:$J,Giriş!$H:$H,Bilgiler!V$3,Giriş!$C:$C,Bilgiler!$O11,Giriş!$E:$E,Bilgiler!$P11) -> 0 | W11: =SUMIFS(Giriş!$J:$J,Giriş!$H:$H,Bilgiler!W$3,Giriş!$C:$C,Bilgiler!$O11,Giriş!$E:$E,Bilgiler!$P11) -> 0 | X11: =S11+T11+V11-W11-U11 -> 89050 | Y11: =IF(R11<0,IF(X11>0,"Raf Ömrü Geçti",""),IF(R11<=15,IF(X11>0,"Raf Ömrü Bitmek Üzere",""),"")) -> Raf Ömrü Geçti | AA11: Uneli Gıda İnşaat Loj.Turizm San.ve Tic.Ltd.Şti.
D12: Poşet-15 cm Batel 250 Gr | E12: 150.01.250 | F12: Mevcut | H12: =SUMIFS(Giriş!$J:$J,Giriş!$H:$H,Bilgiler!H$3,Giriş!$C:$C,Bilgiler!$D12) -> 0 | I12: =SUMIFS(Giriş!$J:$J,Giriş!$H:$H,Bilgiler!I$3,Giriş!$C:$C,Bilgiler!$D12) -> 0 | J12: =SUMIFS(Giriş!$J:$J,Giriş!$H:$H,Bilgiler!J$3,Giriş!$C:$C,Bilgiler!$D12) -> 0 | K12: =SUMIFS(Giriş!$J:$J,Giriş!$H:$H,Bilgiler!K$3,Giriş!$C:$C,Bilgiler!$D12) -> 0 | L12: =G12+H12-I12-K12+J12 -> 0 | N12: =IFERROR(IF(N11+1>MAX(Giriş!L:L),"",N11+1),"") -> 9 | O12: =IF($N12="","",VLOOKUP($N12,Giriş!$L:$O,2,0)) -> Poşet-25 cm Mutlukal Tortillas Tam Buğday | P12: =IF($N12="","",VLOOKUP($N12,Giriş!$L:$O,3,0)) -> 20230042 | Q12: =IF($N12="","",VLOOKUP($N12,Giriş!$L:$O,4,0)) -> 45483 | R12: =IF(O12="","",IF(X12<=0,"",Q12-TODAY())) -> -99 | S12: =SUMIFS(G:G,D:D,O12,F:F,P12) -> 0 | T12: =SUMIFS(Giriş!$J:$J,Giriş!$H:$H,Bilgiler!T$3,Giriş!$C:$C,Bilgiler!$O12,Giriş!$E:$E,Bilgiler!$P12) -> 86730 | U12: =SUMIFS(Giriş!$J:$J,Giriş!$H:$H,Bilgiler!U$3,Giriş!$C:$C,Bilgiler!$O12,Giriş!$E:$E,Bilgiler!$P12) -> 0 | V12: =SUMIFS(Giriş!$J:$J,Giriş!$H:$H,Bilgiler!V$3,Giriş!$C:$C,Bilgiler!$O12,Giriş!$E:$E,Bilgiler!$P12) -> 0 | W12: =SUMIFS(Giriş!$J:$J,Giriş!$H:$H,Bilgiler!W$3,Giriş!$C:$C,Bilgiler!$O12,Giriş!$E:$E,Bilgiler!$P12) -> 0 | X12: =S12+T12+V12-W12-U12 -> 86730 | Y12: =IF(R12<0,IF(X12>0,"Raf Ömrü Geçti",""),IF(R12<=15,IF(X12>0,"Raf Ömrü Bitmek Üzere",""),"")) -> Raf Ömrü Geçti | AA12: ARTSAN
D13: Poşet-15 cm Bonita 250 gr | E13: 150.01.235 | F13: Mevcut | H13: =SUMIFS(Giriş!$J:$J,Giriş!$H:$H,Bilgiler!H$3,Giriş!$C:$C,Bilgiler!$D13) -> 0 | I13: =SUMIFS(Giriş!$J:$J,Giriş!$H:$H,Bilgiler!I$3,Giriş!$C:$C,Bilgiler!$D13) -> 0 | J13: =SUMIFS(Giriş!$J:$J,Giriş!$H:$H,Bilgiler!J$3,Giriş!$C:$C,Bilgiler!$D13) -> 0 | K13: =SUMIFS(Giriş!$J:$J,Giriş!$H:$H,Bilgiler!K$3,Giriş!$C:$C,Bilgiler!$D13) -> 0 | L13: =G13+H13-I13-K13+J13 -> 0 | N13: =IFERROR(IF(N12+1>MAX(Giriş!L:L),"",N12+1),"") -> 10 | O13: =IF($N13="","",VLOOKUP($N13,Giriş!$L:$O,2,0)) -> Poşet-25 cm B.sız Kilitli | P13: =IF($N13="","",VLOOKUP($N13,Giriş!$L:$O,3,0)) -> 20230050 | Q13: =IF($N13="","",VLOOKUP($N13,Giriş!$L:$O,4,0)) -> 45483 | R13: =IF(O13="","",IF(X13<=0,"",Q13-TODAY())) -> -99 | S13: =SUMIFS(G:G,D:D,O13,F:F,P13) -> 0 | T13: =SUMIFS(Giriş!$J:$J,Giriş!$H:$H,Bilgiler!T$3,Giriş!$C:$C,Bilgiler!$O13,Giriş!$E:$E,Bilgiler!$P13) -> 88400 | U13: =SUMIFS(Giriş!$J:$J,Giriş!$H:$H,Bilgiler!U$3,Giriş!$C:$C,Bilgiler!$O13,Giriş!$E:$E,Bilgiler!$P13) -> 0 | V13: =SUMIFS(Giriş!$J:$J,Giriş!$H:$H,Bilgiler!V$3,Giriş!$C:$C,Bilgiler!$O13,Giriş!$E:$E,Bilgiler!$P13) -> 0 | W13: =SUMIFS(Giriş!$J:$J,Giriş!$H:$H,Bilgiler!W$3,Giriş!$C:$C,Bilgiler!$O13,Giriş!$E:$E,Bilgiler!$P13) -> 0 | X13: =S13+T13+V13-W13-U13 -> 88400 | Y13: =IF(R13<0,IF(X13>0,"Raf Ömrü Geçti",""),IF(R13<=15,IF(X13>0,"Raf Ömrü Bitmek Üzere",""),"")) -> Raf Ömrü Geçti
D14: Poşet-15 cm Delight | E14: 150.01.219 | F14: Mevcut | H14: =SUMIFS(Giriş!$J:$J,Giriş!$H:$H,Bilgiler!H$3,Giriş!$C:$C,Bilgiler!$D14) -> 0 | I14: =SUMIFS(Giriş!$J:$J,Giriş!$H:$H,Bilgiler!I$3,Giriş!$C:$C,Bilgiler!$D14) -> 0 | J14: =SUMIFS(Giriş!$J:$J,Giriş!$H:$H,Bilgiler!J$3,Giriş!$C:$C,Bilgiler!$D14) -> 0 | K14: =SUMIFS(Giriş!$J:$J,Giriş!$H:$H,Bilgiler!K$3,Giriş!$C:$C,Bilgiler!$D14) -> 0 | L14: =G14+H14-I14-K14+J14 -> 0 | N14: =IFERROR(IF(N13+1>MAX(Giriş!L:L),"",N13+1),"") -> 11 | O14: =IF($N14="","",VLOOKUP($N14,Giriş!$L:$O,2,0)) -> Poşet-25 cm Tortillove Değişken | P14: =IF($N14="","",VLOOKUP($N14,Giriş!$L:$O,3,0)) -> MAT008095 | Q14: =IF($N14="","",VLOOKUP($N14,Giriş!$L:$O,4,0)) -> 45491 | R14: =IF(O14="","",IF(X14<=0,"",Q14-TODAY())) -> -91 | S14: =SUMIFS(G:G,D:D,O14,F:F,P14) -> 0 | T14: =SUMIFS(Giriş!$J:$J,Giriş!$H:$H,Bilgiler!T$3,Giriş!$C:$C,Bilgiler!$O14,Giriş!$E:$E,Bilgiler!$P14) -> 79800 | U14: =SUMIFS(Giriş!$J:$J,Giriş!$H:$H,Bilgiler!U$3,Giriş!$C:$C,Bilgiler!$O14,Giriş!$E:$E,Bilgiler!$P14) -> 0 | V14: =SUMIFS(Giriş!$J:$J,Giriş!$H:$H,Bilgiler!V$3,Giriş!$C:$C,Bilgiler!$O14,Giriş!$E:$E,Bilgiler!$P14) -> 0 | W14: =SUMIFS(Giriş!$J:$J,Giriş!$H:$H,Bilgiler!W$3,Giriş!$C:$C,Bilgiler!$O14,Giriş!$E:$E,Bilgiler!$P14) -> 0 | X14: =S14+T14+V14-W14-U14 -> 79800 | Y14: =IF(R14<0,IF(X14>0,"Raf Ömrü Geçti",""),IF(R14<=15,IF(X14>0,"Raf Ömrü Bitmek Üzere",""),"")) -> Raf Ömrü Geçti
D15: Poşet-15 cm Happylla Değişken | E15: 150.01.033 | F15: Mevcut | H15: =SUMIFS(Giriş!$J:$J,Giriş!$H:$H,Bilgiler!H$3,Giriş!$C:$C,Bilgiler!$D15) -> 0 | I15: =SUMIFS(Giriş!$J:$J,Giriş!$H:$H,Bilgiler!I$3,Giriş!$C:$C,Bilgiler!$D15) -> 0 | J15: =SUMIFS(Giriş!$J:$J,Giriş!$H:$H,Bilgiler!J$3,Giriş!$C:$C,Bilgiler!$D15) -> 0 | K15: =SUMIFS(Giriş!$J:$J,Giriş!$H:$H,Bilgiler!K$3,Giriş!$C:$C,Bilgiler!$D15) -> 0 | L15: =G15+H15-I15-K15+J15 -> 0 | N15: =IFERROR(IF(N14+1>MAX(Giriş!L:L),"",N14+1),"") -> 12 | O15: =IF($N15="","",VLOOKUP($N15,Giriş!$L:$O,2,0)) -> Poşet-25 cm Wıllı Food 840 gr | P15: =IF($N15="","",VLOOKUP($N15,Giriş!$L:$O,3,0)) -> MAT008124 | Q15: =IF($N15="","",VLOOKUP($N15,Giriş!$L:$O,4,0)) -> 45498 | R15: =IF(O15="","",IF(X15<=0,"",Q15-TODAY())) -> -84 | S15: =SUMIFS(G:G,D:D,O15,F:F,P15) -> 0 | T15: =SUMIFS(Giriş!$J:$J,Giriş!$H:$H,Bilgiler!T$3,Giriş!$C:$C,Bilgiler!$O15,Giriş!$E:$E,Bilgiler!$P15) -> 77300 | U15: =SUMIFS(Giriş!$J:$J,Giriş!$H:$H,Bilgiler!U$3,Giriş!$C:$C,Bilgiler!$O15,Giriş!$E:$E,Bilgiler!$P15) -> 0 | V15: =SUMIFS(Giriş!$J:$J,Giriş!$H:$H,Bilgiler!V$3,Giriş!$C:$C,Bilgiler!$O15,Giriş!$E:$E,Bilgiler!$P15) -> 0 | W15: =SUMIFS(Giriş!$J:$J,Giriş!$H:$H,Bilgiler!W$3,Giriş!$C:$C,Bilgiler!$O15,Giriş!$E:$E,Bilgiler!$P15) -> 0 | X15: =S15+T15+V15-W15-U15 -> 77300 | Y15: =IF(R15<0,IF(X15>0,"Raf Ömrü Geçti",""),IF(R15<=15,IF(X15>0,"Raf Ömrü Bitmek Üzere",""),"")) -> Raf Ömrü Geçti
D16: Poşet-15 cm Jana | E16: LV.AMB.0005 | F16: Mevcut | H16: =SUMIFS(Giriş!$J:$J,Giriş!$H:$H,Bilgiler!H$3,Giriş!$C:$C,Bilgiler!$D16) -> 0 | I16: =SUMIFS(Giriş!$J:$J,Giriş!$H:$H,Bilgiler!I$3,Giriş!$C:$C,Bilgiler!$D16) -> 0 | J16: =SUMIFS(Giriş!$J:$J,Giriş!$H:$H,Bilgiler!J$3,Giriş!$C:$C,Bilgiler!$D16) -> 0 | K16: =SUMIFS(Giriş!$J:$J,Giriş!$H:$H,Bilgiler!K$3,Giriş!$C:$C,Bilgiler!$D16) -> 0 | L16: =G16+H16-I16-K16+J16 -> 0 | N16: =IFERROR(IF(N15+1>MAX(Giriş!L:L),"",N15+1),"") -> 13 | O16: =IF($N16="","",VLOOKUP($N16,Giriş!$L:$O,2,0)) -> Poşet-20 cm Wıllı Food 540 gr | P16: =IF($N16="","",VLOOKUP($N16,Giriş!$L:$O,3,0)) -> MAT008123 | Q16: =IF($N16="","",VLOOKUP($N16,Giriş!$L:$O,4,0)) -> 45500 | R16: =IF(O16="","",IF(X16<=0,"",Q16-TODAY())) -> -82 | S16: =SUMIFS(G:G,D:D,O16,F:F,P16) -> 0 | T16: =SUMIFS(Giriş!$J:$J,Giriş!$H:$H,Bilgiler!T$3,Giriş!$C:$C,Bilgiler!$O16,Giriş!$E:$E,Bilgiler!$P16) -> 104400 | U16: =SUMIFS(Giriş!$J:$J,Giriş!$H:$H,Bilgiler!U$3,Giriş!$C:$C,Bilgiler!$O16,Giriş!$E:$E,Bilgiler!$P16) -> 0 | V16: =SUMIFS(Giriş!$J:$J,Giriş!$H:$H,Bilgiler!V$3,Giriş!$C:$C,Bilgiler!$O16,Giriş!$E:$E,Bilgiler!$P16) -> 0 | W16: =SUMIFS(Giriş!$J:$J,Giriş!$H:$H,Bilgiler!W$3,Giriş!$C:$C,Bilgiler!$O16,Giriş!$E:$E,Bilgiler!$P16) -> 0 | X16: =S16+T16+V16-W16-U16 -> 104400 | Y16: =IF(R16<0,IF(X16>0,"Raf Ömrü Geçti",""),IF(R16<=15,IF(X16>0,"Raf Ömrü Bitmek Üzere",""),"")) -> Raf Ömrü Geçti
D17: Poşet-15 cm Komagene Tako Lavaşı | E17: 150.01.291 | F17: Mevcut | H17: =SUMIFS(Giriş!$J:$J,Giriş!$H:$H,Bilgiler!H$3,Giriş!$C:$C,Bilgiler!$D17) -> 264150 | I17: =SUMIFS(Giriş!$J:$J,Giriş!$H:$H,Bilgiler!I$3,Giriş!$C:$C,Bilgiler!$D17) -> 0 | J17: =SUMIFS(Giriş!$J:$J,Giriş!$H:$H,Bilgiler!J$3,Giriş!$C:$C,Bilgiler!$D17) -> 0 | K17: =SUMIFS(Giriş!$J:$J,Giriş!$H:$H,Bilgiler!K$3,Giriş!$C:$C,Bilgiler!$D17) -> 0 | L17: =G17+H17-I17-K17+J17 -> 264150 | N17: =IFERROR(IF(N16+1>MAX(Giriş!L:L),"",N16+1),"") -> 14 | O17: =IF($N17="","",VLOOKUP($N17,Giriş!$L:$O,2,0)) -> Poşet-25 cm Nimet (Lam.Baskılı Zıp.Vakum ) | P17: =IF($N17="","",VLOOKUP($N17,Giriş!$L:$O,3,0)) -> 20230043 | Q17: =IF($N17="","",VLOOKUP($N17,Giriş!$L:$O,4,0)) -> 45641 | R17: =IF(O17="","",IF(X17<=0,"",Q17-TODAY())) -> 59 | S17: =SUMIFS(G:G,D:D,O17,F:F,P17) -> 0 | T17: =SUMIFS(Giriş!$J:$J,Giriş!$H:$H,Bilgiler!T$3,Giriş!$C:$C,Bilgiler!$O17,Giriş!$E:$E,Bilgiler!$P17) -> 249900 | U17: =SUMIFS(Giriş!$J:$J,Giriş!$H:$H,Bilgiler!U$3,Giriş!$C:$C,Bilgiler!$O17,Giriş!$E:$E,Bilgiler!$P17) -> 0 | V17: =SUMIFS(Giriş!$J:$J,Giriş!$H:$H,Bilgiler!V$3,Giriş!$C:$C,Bilgiler!$O17,Giriş!$E:$E,Bilgiler!$P17) -> 0 | W17: =SUMIFS(Giriş!$J:$J,Giriş!$H:$H,Bilgiler!W$3,Giriş!$C:$C,Bilgiler!$O17,Giriş!$E:$E,Bilgiler!$P17) -> 0 | X17: =S17+T17+V17-W17-U17 -> 249900 | Y17: =IF(R17<0,IF(X17>0,"Raf Ömrü Geçti",""),IF(R17<=15,IF(X17>0,"Raf Ömrü Bitmek Üzere",""),""))
D18: Poşet-15 cm Mutlukal Taco | E18: 150.01.301 | F18: Mevcut | H18: =SUMIFS(Giriş!$J:$J,Giriş!$H:$H,Bilgiler!H$3,Giriş!$C:$C,Bilgiler!$D18) -> 787266 | I18: =SUMIFS(Giriş!$J:$J,Giriş!$H:$H,Bilgiler!I$3,Giriş!$C:$C,Bilgiler!$D18) -> 0 | J18: =SUMIFS(Giriş!$J:$J,Giriş!$H:$H,Bilgiler!J$3,Giriş!$C:$C,Bilgiler!$D18) -> 0 | K18: =SUMIFS(Giriş!$J:$J,Giriş!$H:$H,Bilgiler!K$3,Giriş!$C:$C,Bilgiler!$D18) -> 0 | L18: =G18+H18-I18-K18+J18 -> 787266 | N18: =IFERROR(IF(N17+1>MAX(Giriş!L:L),"",N17+1),"") -> 15 | O18: =IF($N18="","",VLOOKUP($N18,Giriş!$L:$O,2,0)) -> Poşet--20 cm Mutlukal Tortillas Mavi Değişken | P18: =IF($N18="","",VLOOKUP($N18,Giriş!$L:$O,3,0)) -> 20230046 | Q18: =IF($N18="","",VLOOKUP($N18,Giriş!$L:$O,4,0)) -> 45646 | R18: =IF(O18="","",IF(X18<=0,"",Q18-TODAY())) -> 64 | S18: =SUMIFS(G:G,D:D,O18,F:F,P18) -> 0 | T18: =SUMIFS(Giriş!$J:$J,Giriş!$H:$H,Bilgiler!T$3,Giriş!$C:$C,Bilgiler!$O18,Giriş!$E:$E,Bilgiler!$P18) -> 158720 | U18: =SUMIFS(Giriş!$J:$J,Giriş!$H:$H,Bilgiler!U$3,Giriş!$C:$C,Bilgiler!$O18,Giriş!$E:$E,Bilgiler!$P18) -> 0 | V18: =SUMIFS(Giriş!$J:$J,Giriş!$H:$H,Bilgiler!V$3,Giriş!$C:$C,Bilgiler!$O18,Giriş!$E:$E,Bilgiler!$P18) -> 0 | W18: =SUMIFS(Giriş!$J:$J,Giriş!$H:$H,Bilgiler!W$3,Giriş!$C:$C,Bilgiler!$O18,Giriş!$E:$E,Bilgiler!$P18) -> 0 | X18: =S18+T18+V18-W18-U18 -> 158720 | Y18: =IF(R18<0,IF(X18>0,"Raf Ömrü Geçti",""),IF(R18<=15,IF(X18>0,"Raf Ömrü Bitmek Üzere",""),""))
D19: Poşet--15 cm Mutlukal Tortillas Mavi Değişken | E19: 150.01.305 | F19: Mevcut | H19: =SUMIFS(Giriş!$J:$J,Giriş!$H:$H,Bilgiler!H$3,Giriş!$C:$C,Bilgiler!$D19) -> 617832 | I19: =SUMIFS(Giriş!$J:$J,Giriş!$H:$H,Bilgiler!I$3,Giriş!$C:$C,Bilgiler!$D19) -> 0 | J19: =SUMIFS(Giriş!$J:$J,Giriş!$H:$H,Bilgiler!J$3,Giriş!$C:$C,Bilgiler!$D19) -> 0 | K19: =SUMIFS(Giriş!$J:$J,Giriş!$H:$H,Bilgiler!K$3,Giriş!$C:$C,Bilgiler!$D19) -> 0 | L19: =G19+H19-I19-K19+J19 -> 617832 | N19: =IFERROR(IF(N18+1>MAX(Giriş!L:L),"",N18+1),"") -> 16 | O19: =IF($N19="","",VLOOKUP($N19,Giriş!$L:$O,2,0)) -> Poşet-30 cm B.sız Kilitli | P19: =IF($N19="","",VLOOKUP($N19,Giriş!$L:$O,3,0)) -> 20230049 | Q19: =IF($N19="","",VLOOKUP($N19,Giriş!$L:$O,4,0)) -> 45641 | R19: =IF(O19="","",IF(X19<=0,"",Q19-TODAY())) -> 59 | S19: =SUMIFS(G:G,D:D,O19,F:F,P19) -> 0 | T19: =SUMIFS(Giriş!$J:$J,Giriş!$H:$H,Bilgiler!T$3,Giriş!$C:$C,Bilgiler!$O19,Giriş!$E:$E,Bilgiler!$P19) -> 66530 | U19: =SUMIFS(Giriş!$J:$J,Giriş!$H:$H,Bilgiler!U$3,Giriş!$C:$C,Bilgiler!$O19,Giriş!$E:$E,Bilgiler!$P19) -> 0 | V19: =SUMIFS(Giriş!$J:$J,Giriş!$H:$H,Bilgiler!V$3,Giriş!$C:$C,Bilgiler!$O19,Giriş!$E:$E,Bilgiler!$P19) -> 0 | W19: =SUMIFS(Giriş!$J:$J,Giriş!$H:$H,Bilgiler!W$3,Giriş!$C:$C,Bilgiler!$O19,Giriş!$E:$E,Bilgiler!$P19) -> 0 | X19: =S19+T19+V19-W19-U19 -> 66530 | Y19: =IF(R19<0,IF(X19>0,"Raf Ömrü Geçti",""),IF(R19<=15,IF(X19>0,"Raf Ömrü Bitmek Üzere",""),""))
D20: Poşet-15 cm Soor 300 gr | E20: 150.01.125 | F20: Mevcut | H20: =SUMIFS(Giriş!$J:$J,Giriş!$H:$H,Bilgiler!H$3,Giriş!$C:$C,Bilgiler!$D20) -> 0 | I20: =SUMIFS(Giriş!$J:$J,Giriş!$H:$H,Bilgiler!I$3,Giriş!$C:$C,Bilgiler!$D20) -> 0 | J20: =SUMIFS(Giriş!$J:$J,Giriş!$H:$H,Bilgiler!J$3,Giriş!$C:$C,Bilgiler!$D20) -> 0 | K20: =SUMIFS(Giriş!$J:$J,Giriş!$H:$H,Bilgiler!K$3,Giriş!$C:$C,Bilgiler!$D20) -> 0 | L20: =G20+H20-I20-K20+J20 -> 0 | N20: =IFERROR(IF(N19+1>MAX(Giriş!L:L),"",N19+1),"") -> 17 | O20: =IF($N20="","",VLOOKUP($N20,Giriş!$L:$O,2,0)) -> Poşet-25 cm Gazelle Gurme | P20: =IF($N20="","",VLOOKUP($N20,Giriş!$L:$O,3,0)) -> MAT008153 | Q20: =IF($N20="","",VLOOKUP($N20,Giriş!$L:$O,4,0)) -> 45632 | R20: =IF(O20="","",IF(X20<=0,"",Q20-TODAY())) -> 50 | S20: =SUMIFS(G:G,D:D,O20,F:F,P20) -> 0 | T20: =SUMIFS(Giriş!$J:$J,Giriş!$H:$H,Bilgiler!T$3,Giriş!$C:$C,Bilgiler!$O20,Giriş!$E:$E,Bilgiler!$P20) -> 82600 | U20: =SUMIFS(Giriş!$J:$J,Giriş!$H:$H,Bilgiler!U$3,Giriş!$C:$C,Bilgiler!$O20,Giriş!$E:$E,Bilgiler!$P20) -> 0 | V20: =SUMIFS(Giriş!$J:$J,Giriş!$H:$H,Bilgiler!V$3,Giriş!$C:$C,Bilgiler!$O20,Giriş!$E:$E,Bilgiler!$P20) -> 0 | W20: =SUMIFS(Giriş!$J:$J,Giriş!$H:$H,Bilgiler!W$3,Giriş!$C:$C,Bilgiler!$O20,Giriş!$E:$E,Bilgiler!$P20) -> 0 | X20: =S20+T20+V20-W20-U20 -> 82600 | Y20: =IF(R20<0,IF(X20>0,"Raf Ömrü Geçti",""),IF(R20<=15,IF(X20>0,"Raf Ömrü Bitmek Üzere",""),""))
D21: Poşet-15 cm Tortillove Değişken | E21: 150.01.164 | F21: Mevcut | H21: =SUMIFS(Giriş!$J:$J,Giriş!$H:$H,Bilgiler!H$3,Giriş!$C:$C,Bilgiler!$D21) -> 152000 | I21: =SUMIFS(Giriş!$J:$J,Giriş!$H:$H,Bilgiler!I$3,Giriş!$C:$C,Bilgiler!$D21) -> 0 | J21: =SUMIFS(Giriş!$J:$J,Giriş!$H:$H,Bilgiler!J$3,Giriş!$C:$C,Bilgiler!$D21) -> 0 | K21: =SUMIFS(Giriş!$J:$J,Giriş!$H:$H,Bilgiler!K$3,Giriş!$C:$C,Bilgiler!$D21) -> 0 | L21: =G21+H21-I21-K21+J21 -> 152000 | N21: =IFERROR(IF(N20+1>MAX(Giriş!L:L),"",N20+1),"") -> 18 | O21: =IF($N21="","",VLOOKUP($N21,Giriş!$L:$O,2,0)) -> Poşet-26 cm Unebella | P21: =IF($N21="","",VLOOKUP($N21,Giriş!$L:$O,3,0)) -> MAT000712 | Q21: =IF($N21="","",VLOOKUP($N21,Giriş!$L:$O,4,0)) -> 45443 | R21: =IF(O21="","",IF(X21<=0,"",Q21-TODAY())) -> -139 | S21: =SUMIFS(G:G,D:D,O21,F:F,P21) -> 0 | T21: =SUMIFS(Giriş!$J:$J,Giriş!$H:$H,Bilgiler!T$3,Giriş!$C:$C,Bilgiler!$O21,Giriş!$E:$E,Bilgiler!$P21) -> 39200 | U21: =SUMIFS(Giriş!$J:$J,Giriş!$H:$H,Bilgiler!U$3,Giriş!$C:$C,Bilgiler!$O21,Giriş!$E:$E,Bilgiler!$P21) -> 0 | V21: =SUMIFS(Giriş!$J:$J,Giriş!$H:$H,Bilgiler!V$3,Giriş!$C:$C,Bilgiler!$O21,Giriş!$E:$E,Bilgiler!$P21) -> 0 | W21: =SUMIFS(Giriş!$J:$J,Giriş!$H:$H,Bilgiler!W$3,Giriş!$C:$C,Bilgiler!$O21,Giriş!$E:$E,Bilgiler!$P21) -> 0 | X21: =S21+T21+V21-W21-U21 -> 39200 | Y21: =IF(R21<0,IF(X21>0,"Raf Ömrü Geçti",""),IF(R21<=15,IF(X21>0,"Raf Ömrü Bitmek Üzere",""),"")) -> Raf Ömrü Geçti
D22: Poşet-15 cm Unabella Sade 330 gr | E22: 150.01.034 | F22: Mevcut | H22: =SUMIFS(Giriş!$J:$J,Giriş!$H:$H,Bilgiler!H$3,Giriş!$C:$C,Bilgiler!$D22) -> 0 | I22: =SUMIFS(Giriş!$J:$J,Giriş!$H:$H,Bilgiler!I$3,Giriş!$C:$C,Bilgiler!$D22) -> 0 | J22: =SUMIFS(Giriş!$J:$J,Giriş!$H:$H,Bilgiler!J$3,Giriş!$C:$C,Bilgiler!$D22) -> 0 | K22: =SUMIFS(Giriş!$J:$J,Giriş!$H:$H,Bilgiler!K$3,Giriş!$C:$C,Bilgiler!$D22) -> 0 | L22: =G22+H22-I22-K22+J22 -> 0 | N22: =IFERROR(IF(N21+1>MAX(Giriş!L:L),"",N21+1),"") -> 19 | O22: =IF($N22="","",VLOOKUP($N22,Giriş!$L:$O,2,0)) -> Poşet-30 cm Tortillove Değişken | P22: =IF($N22="","",VLOOKUP($N22,Giriş!$L:$O,3,0)) -> MAT008141 | Q22: =IF($N22="","",VLOOKUP($N22,Giriş!$L:$O,4,0)) -> 45647 | R22: =IF(O22="","",IF(X22<=0,"",Q22-TODAY())) -> 65 | S22: =SUMIFS(G:G,D:D,O22,F:F,P22) -> 0 | T22: =SUMIFS(Giriş!$J:$J,Giriş!$H:$H,Bilgiler!T$3,Giriş!$C:$C,Bilgiler!$O22,Giriş!$E:$E,Bilgiler!$P22) -> 56400 | U22: =SUMIFS(Giriş!$J:$J,Giriş!$H:$H,Bilgiler!U$3,Giriş!$C:$C,Bilgiler!$O22,Giriş!$E:$E,Bilgiler!$P22) -> 0 | V22: =SUMIFS(Giriş!$J:$J,Giriş!$H:$H,Bilgiler!V$3,Giriş!$C:$C,Bilgiler!$O22,Giriş!$E:$E,Bilgiler!$P22) -> 0 | W22: =SUMIFS(Giriş!$J:$J,Giriş!$H:$H,Bilgiler!W$3,Giriş!$C:$C,Bilgiler!$O22,Giriş!$E:$E,Bilgiler!$P22) -> 0 | X22: =S22+T22+V22-W22-U22 -> 56400 | Y22: =IF(R22<0,IF(X22>0,"Raf Ömrü Geçti",""),IF(R22<=15,IF(X22>0,"Raf Ömrü Bitmek Üzere",""),""))
D23: Poşet-15 cm Unistanbul 330 Gr | E23: 150.01.192 | F23: Mevcut | H23: =SUMIFS(Giriş!$J:$J,Giriş!$H:$H,Bilgiler!H$3,Giriş!$C:$C,Bilgiler!$D23) -> 0 | I23: =SUMIFS(Giriş!$J:$J,Giriş!$H:$H,Bilgiler!I$3,Giriş!$C:$C,Bilgiler!$D23) -> 0 | J23: =SUMIFS(Giriş!$J:$J,Giriş!$H:$H,Bilgiler!J$3,Giriş!$C:$C,Bilgiler!$D23) -> 0 | K23: =SUMIFS(Giriş!$J:$J,Giriş!$H:$H,Bilgiler!K$3,Giriş!$C:$C,Bilgiler!$D23) -> 0 | L23: =G23+H23-I23-K23+J23 -> 0 | N23: =IFERROR(IF(N22+1>MAX(Giriş!L:L),"",N22+1),"") -> 20 | O23: =IF($N23="","",VLOOKUP($N23,Giriş!$L:$O,2,0)) -> Poşet-15 cm Komagene Tako Lavaşı | P23: =IF($N23="","",VLOOKUP($N23,Giriş!$L:$O,3,0)) -> MAT008140 | Q23: =IF($N23="","",VLOOKUP($N23,Giriş!$L:$O,4,0)) -> 45645 | R23: =IF(O23="","",IF(X23<=0,"",Q23-TODAY())) -> 63 | S23: =SUMIFS(G:G,D:D,O23,F:F,P23) -> 0 | T23: =SUMIFS(Giriş!$J:$J,Giriş!$H:$H,Bilgiler!T$3,Giriş!$C:$C,Bilgiler!$O23,Giriş!$E:$E,Bilgiler!$P23) -> 148000 | U23: =SUMIFS(Giriş!$J:$J,Giriş!$H:$H,Bilgiler!U$3,Giriş!$C:$C,Bilgiler!$O23,Giriş!$E:$E,Bilgiler!$P23) -> 0 | V23: =SUMIFS(Giriş!$J:$J,Giriş!$H:$H,Bilgiler!V$3,Giriş!$C:$C,Bilgiler!$O23,Giriş!$E:$E,Bilgiler!$P23) -> 0 | W23: =SUMIFS(Giriş!$J:$J,Giriş!$H:$H,Bilgiler!W$3,Giriş!$C:$C,Bilgiler!$O23,Giriş!$E:$E,Bilgiler!$P23) -> 0 | X23: =S23+T23+V23-W23-U23 -> 148000 | Y23: =IF(R23<0,IF(X23>0,"Raf Ömrü Geçti",""),IF(R23<=15,IF(X23>0,"Raf Ömrü Bitmek Üzere",""),""))
D24: Poşet-19 cm Bonita Pizza ( 340 gr ) | E24: 150.01.267 | F24: Mevcut | H24: =SUMIFS(Giriş!$J:$J,Giriş!$H:$H,Bilgiler!H$3,Giriş!$C:$C,Bilgiler!$D24) -> 0 | I24: =SUMIFS(Giriş!$J:$J,Giriş!$H:$H,Bilgiler!I$3,Giriş!$C:$C,Bilgiler!$D24) -> 0 | J24: =SUMIFS(Giriş!$J:$J,Giriş!$H:$H,Bilgiler!J$3,Giriş!$C:$C,Bilgiler!$D24) -> 0 | K24: =SUMIFS(Giriş!$J:$J,Giriş!$H:$H,Bilgiler!K$3,Giriş!$C:$C,Bilgiler!$D24) -> 0 | L24: =G24+H24-I24-K24+J24 -> 0 | N24: =IFERROR(IF(N23+1>MAX(Giriş!L:L),"",N23+1),"") -> 21 | O24: =IF($N24="","",VLOOKUP($N24,Giriş!$L:$O,2,0)) -> Poşet-25 cm Nimet (Lam.Baskılı Zıp.Vakum ) | P24: =IF($N24="","",VLOOKUP($N24,Giriş!$L:$O,3,0)) -> 20230057 | Q24: =IF($N24="","",VLOOKUP($N24,Giriş!$L:$O,4,0)) -> 45632 | R24: =IF(O24="","",IF(X24<=0,"",Q24-TODAY())) -> 50 | S24: =SUMIFS(G:G,D:D,O24,F:F,P24) -> 0 | T24: =SUMIFS(Giriş!$J:$J,Giriş!$H:$H,Bilgiler!T$3,Giriş!$C:$C,Bilgiler!$O24,Giriş!$E:$E,Bilgiler!$P24) -> 191510 | U24: =SUMIFS(Giriş!$J:$J,Giriş!$H:$H,Bilgiler!U$3,Giriş!$C:$C,Bilgiler!$O24,Giriş!$E:$E,Bilgiler!$P24) -> 0 | V24: =SUMIFS(Giriş!$J:$J,Giriş!$H:$H,Bilgiler!V$3,Giriş!$C:$C,Bilgiler!$O24,Giriş!$E:$E,Bilgiler!$P24) -> 0 | W24: =SUMIFS(Giriş!$J:$J,Giriş!$H:$H,Bilgiler!W$3,Giriş!$C:$C,Bilgiler!$O24,Giriş!$E:$E,Bilgiler!$P24) -> 0 | X24: =S24+T24+V24-W24-U24 -> 191510 | Y24: =IF(R24<0,IF(X24>0,"Raf Ömrü Geçti",""),IF(R24<=15,IF(X24>0,"Raf Ömrü Bitmek Üzere",""),""))
D25: Poşet-20 cm 450gr Hessa | E25: 150.01.330 | F25: Mevcut | H25: =SUMIFS(Giriş!$J:$J,Giriş!$H:$H,Bilgiler!H$3,Giriş!$C:$C,Bilgiler!$D25) -> 0 | I25: =SUMIFS(Giriş!$J:$J,Giriş!$H:$H,Bilgiler!I$3,Giriş!$C:$C,Bilgiler!$D25) -> 0 | J25: =SUMIFS(Giriş!$J:$J,Giriş!$H:$H,Bilgiler!J$3,Giriş!$C:$C,Bilgiler!$D25) -> 0 | K25: =SUMIFS(Giriş!$J:$J,Giriş!$H:$H,Bilgiler!K$3,Giriş!$C:$C,Bilgiler!$D25) -> 0 | L25: =G25+H25-I25-K25+J25 -> 0 | N25: =IFERROR(IF(N24+1>MAX(Giriş!L:L),"",N24+1),"") -> 22 | O25: =IF($N25="","",VLOOKUP($N25,Giriş!$L:$O,2,0)) -> Poşet--15 cm Mutlukal Tortillas Mavi Değişken | P25: =IF($N25="","",VLOOKUP($N25,Giriş!$L:$O,3,0)) -> 20230047 | Q25: =IF($N25="","",VLOOKUP($N25,Giriş!$L:$O,4,0)) -> 45632 | R25: =IF(O25="","",IF(X25<=0,"",Q25-TODAY())) -> 50 | S25: =SUMIFS(G:G,D:D,O25,F:F,P25) -> 0 | T25: =SUMIFS(Giriş!$J:$J,Giriş!$H:$H,Bilgiler!T$3,Giriş!$C:$C,Bilgiler!$O25,Giriş!$E:$E,Bilgiler!$P25) -> 176785 | U25: =SUMIFS(Giriş!$J:$J,Giriş!$H:$H,Bilgiler!U$3,Giriş!$C:$C,Bilgiler!$O25,Giriş!$E:$E,Bilgiler!$P25) -> 0 | V25: =SUMIFS(Giriş!$J:$J,Giriş!$H:$H,Bilgiler!V$3,Giriş!$C:$C,Bilgiler!$O25,Giriş!$E:$E,Bilgiler!$P25) -> 0 | W25: =SUMIFS(Giriş!$J:$J,Giriş!$H:$H,Bilgiler!W$3,Giriş!$C:$C,Bilgiler!$O25,Giriş!$E:$E,Bilgiler!$P25) -> 0 | X25: =S25+T25+V25-W25-U25 -> 176785 | Y25: =IF(R25<0,IF(X25>0,"Raf Ömrü Geçti",""),IF(R25<=15,IF(X25>0,"Raf Ömrü Bitmek Üzere",""),""))
D26: Poşet-20 cm Alkafeel 10 Adet | E26: 150.01.256 | F26: Mevcut | H26: =SUMIFS(Giriş!$J:$J,Giriş!$H:$H,Bilgiler!H$3,Giriş!$C:$C,Bilgiler!$D26) -> 70200 | I26: =SUMIFS(Giriş!$J:$J,Giriş!$H:$H,Bilgiler!I$3,Giriş!$C:$C,Bilgiler!$D26) -> 0 | J26: =SUMIFS(Giriş!$J:$J,Giriş!$H:$H,Bilgiler!J$3,Giriş!$C:$C,Bilgiler!$D26) -> 0 | K26: =SUMIFS(Giriş!$J:$J,Giriş!$H:$H,Bilgiler!K$3,Giriş!$C:$C,Bilgiler!$D26) -> 0 | L26: =G26+H26-I26-K26+J26 -> 70200 | P26: =IF($N26="","",VLOOKUP($N26,Giriş!$L:$O,3,0)) | Q26: =IF($N26="","",VLOOKUP($N26,Giriş!$L:$O,4,0)) | R26: =IF(O26="","",IF(X26<=0,"",Q26-TODAY())) | S26: =SUMIFS(G:G,D:D,O26,F:F,P26) -> 0 | T26: =SUMIFS(Giriş!$J:$J,Giriş!$H:$H,Bilgiler!T$3,Giriş!$C:$C,Bilgiler!$O26,Giriş!$E:$E,Bilgiler!$P26) -> 0 | U26: =SUMIFS(Giriş!$J:$J,Giriş!$H:$H,Bilgiler!U$3,Giriş!$C:$C,Bilgiler!$O26,Giriş!$E:$E,Bilgiler!$P26) -> 0 | V26: =SUMIFS(Giriş!$J:$J,Giriş!$H:$H,Bilgiler!V$3,Giriş!$C:$C,Bilgiler!$O26,Giriş!$E:$E,Bilgiler!$P26) -> 0 | W26: =SUMIFS(Giriş!$J:$J,Giriş!$H:$H,Bilgiler!W$3,Giriş!$C:$C,Bilgiler!$O26,Giriş!$E:$E,Bilgiler!$P26) -> 0 | X26: =S26+T26+V26-W26-U26 -> 0 | Y26: =IF(R26<0,IF(X26>0,"Raf Ömrü Geçti",""),IF(R26<=15,IF(X26>0,"Raf Ömrü Bitmek Üzere",""),""))
D27: Poşet-20 cm B.sız Alüminyum | E27: 150.01.036 | F27: Mevcut | H27: =SUMIFS(Giriş!$J:$J,Giriş!$H:$H,Bilgiler!H$3,Giriş!$C:$C,Bilgiler!$D27) -> 0 | I27: =SUMIFS(Giriş!$J:$J,Giriş!$H:$H,Bilgiler!I$3,Giriş!$C:$C,Bilgiler!$D27) -> 0 | J27: =SUMIFS(Giriş!$J:$J,Giriş!$H:$H,Bilgiler!J$3,Giriş!$C:$C,Bilgiler!$D27) -> 0 | K27: =SUMIFS(Giriş!$J:$J,Giriş!$H:$H,Bilgiler!K$3,Giriş!$C:$C,Bilgiler!$D27) -> 0 | L27: =G27+H27-I27-K27+J27 -> 0 | N27: =IFERROR(IF(N26+1>MAX(Giriş!L:L),"",N26+1),"") -> 1 | O27: =IF($N27="","",VLOOKUP($N27,Giriş!$L:$O,2,0)) -> Poşet-25 cm Mutlukal Tortillas 260 Gr ( Rusca ) | P27: =IF($N27="","",VLOOKUP($N27,Giriş!$L:$O,3,0)) -> MAT007938 | Q27: =IF($N27="","",VLOOKUP($N27,Giriş!$L:$O,4,0)) -> 45401 | R27: =IF(O27="","",IF(X27<=0,"",Q27-TODAY())) -> -181 | S27: =SUMIFS(G:G,D:D,O27,F:F,P27) -> 0 | T27: =SUMIFS(Giriş!$J:$J,Giriş!$H:$H,Bilgiler!T$3,Giriş!$C:$C,Bilgiler!$O27,Giriş!$E:$E,Bilgiler!$P27) -> 3011800 | U27: =SUMIFS(Giriş!$J:$J,Giriş!$H:$H,Bilgiler!U$3,Giriş!$C:$C,Bilgiler!$O27,Giriş!$E:$E,Bilgiler!$P27) -> 0 | V27: =SUMIFS(Giriş!$J:$J,Giriş!$H:$H,Bilgiler!V$3,Giriş!$C:$C,Bilgiler!$O27,Giriş!$E:$E,Bilgiler!$P27) -> 0 | W27: =SUMIFS(Giriş!$J:$J,Giriş!$H:$H,Bilgiler!W$3,Giriş!$C:$C,Bilgiler!$O27,Giriş!$E:$E,Bilgiler!$P27) -> 0 | X27: =S27+T27+V27-W27-U27 -> 3011800 | Y27: =IF(R27<0,IF(X27>0,"Raf Ömrü Geçti",""),IF(R27<=15,IF(X27>0,"Raf Ömrü Bitmek Üzere",""),"")) -> Raf Ömrü Geçti
D28: Poşet-20 cm B.sız Kilitli | E28: 150.01.037 | F28: Mevcut | H28: =SUMIFS(Giriş!$J:$J,Giriş!$H:$H,Bilgiler!H$3,Giriş!$C:$C,Bilgiler!$D28) -> 229200 | I28: =SUMIFS(Giriş!$J:$J,Giriş!$H:$H,Bilgiler!I$3,Giriş!$C:$C,Bilgiler!$D28) -> 0 | J28: =SUMIFS(Giriş!$J:$J,Giriş!$H:$H,Bilgiler!J$3,Giriş!$C:$C,Bilgiler!$D28) -> 0 | K28: =SUMIFS(Giriş!$J:$J,Giriş!$H:$H,Bilgiler!K$3,Giriş!$C:$C,Bilgiler!$D28) -> 0 | L28: =G28+H28-I28-K28+J28 -> 229200 | N28: =IFERROR(IF(N27+1>MAX(Giriş!L:L),"",N27+1),"") -> 2 | O28: =IF($N28="","",VLOOKUP($N28,Giriş!$L:$O,2,0)) -> Poşet-25 cm Mutlukal Tortillas Mavi Değişken | P28: =IF($N28="","",VLOOKUP($N28,Giriş!$L:$O,3,0)) -> MAT008069 | Q28: =IF($N28="","",VLOOKUP($N28,Giriş!$L:$O,4,0)) -> 45401 | R28: =IF(O28="","",IF(X28<=0,"",Q28-TODAY())) -> -181 | S28: =SUMIFS(G:G,D:D,O28,F:F,P28) -> 0 | T28: =SUMIFS(Giriş!$J:$J,Giriş!$H:$H,Bilgiler!T$3,Giriş!$C:$C,Bilgiler!$O28,Giriş!$E:$E,Bilgiler!$P28) -> 82600 | U28: =SUMIFS(Giriş!$J:$J,Giriş!$H:$H,Bilgiler!U$3,Giriş!$C:$C,Bilgiler!$O28,Giriş!$E:$E,Bilgiler!$P28) -> 0 | V28: =SUMIFS(Giriş!$J:$J,Giriş!$H:$H,Bilgiler!V$3,Giriş!$C:$C,Bilgiler!$O28,Giriş!$E:$E,Bilgiler!$P28) -> 0 | W28: =SUMIFS(Giriş!$J:$J,Giriş!$H:$H,Bilgiler!W$3,Giriş!$C:$C,Bilgiler!$O28,Giriş!$E:$E,Bilgiler!$P28) -> 0 | X28: =S28+T28+V28-W28-U28 -> 82600 | Y28: =IF(R28<0,IF(X28>0,"Raf Ömrü Geçti",""),IF(R28<=15,IF(X28>0,"Raf Ömrü Bitmek Üzere",""),"")) -> Raf Ömrü Geçti
D29: Poşet-20 cm Batel 450 Gr | E29: 150.01.249 | F29: Mevcut | H29: =SUMIFS(Giriş!$J:$J,Giriş!$H:$H,Bilgiler!H$3,Giriş!$C:$C,Bilgiler!$D29) -> 0 | I29: =SUMIFS(Giriş!$J:$J,Giriş!$H:$H,Bilgiler!I$3,Giriş!$C:$C,Bilgiler!$D29) -> 0 | J29: =SUMIFS(Giriş!$J:$J,Giriş!$H:$H,Bilgiler!J$3,Giriş!$C:$C,Bilgiler!$D29) -> 0 | K29: =SUMIFS(Giriş!$J:$J,Giriş!$H:$H,Bilgiler!K$3,Giriş!$C:$C,Bilgiler!$D29) -> 0 | L29: =G29+H29-I29-K29+J29 -> 0 | N29: =IFERROR(IF(N28+1>MAX(Giriş!L:L),"",N28+1),"") -> 3 | O29: =IF($N29="","",VLOOKUP($N29,Giriş!$L:$O,2,0)) -> Poşet-30 cm Sofias | P29: =IF($N29="","",VLOOKUP($N29,Giriş!$L:$O,3,0)) -> MAT008034 | Q29: =IF($N29="","",VLOOKUP($N29,Giriş!$L:$O,4,0)) -> 45407 | R29: =IF(O29="","",IF(X29<=0,"",Q29-TODAY())) -> -175 | S29: =SUMIFS(G:G,D:D,O29,F:F,P29) -> 0 | T29: =SUMIFS(Giriş!$J:$J,Giriş!$H:$H,Bilgiler!T$3,Giriş!$C:$C,Bilgiler!$O29,Giriş!$E:$E,Bilgiler!$P29) -> 38400 | U29: =SUMIFS(Giriş!$J:$J,Giriş!$H:$H,Bilgiler!U$3,Giriş!$C:$C,Bilgiler!$O29,Giriş!$E:$E,Bilgiler!$P29) -> 0 | V29: =SUMIFS(Giriş!$J:$J,Giriş!$H:$H,Bilgiler!V$3,Giriş!$C:$C,Bilgiler!$O29,Giriş!$E:$E,Bilgiler!$P29) -> 0 | W29: =SUMIFS(Giriş!$J:$J,Giriş!$H:$H,Bilgiler!W$3,Giriş!$C:$C,Bilgiler!$O29,Giriş!$E:$E,Bilgiler!$P29) -> 0 | X29: =S29+T29+V29-W29-U29 -> 38400 | Y29: =IF(R29<0,IF(X29>0,"Raf Ömrü Geçti",""),IF(R29<=15,IF(X29>0,"Raf Ömrü Bitmek Üzere",""),"")) -> Raf Ömrü Geçti
D30: Poşet-20 cm Bonita 450 gr | E30: 150.01.236 | F30: Mevcut | H30: =SUMIFS(Giriş!$J:$J,Giriş!$H:$H,Bilgiler!H$3,Giriş!$C:$C,Bilgiler!$D30) -> 0 | I30: =SUMIFS(Giriş!$J:$J,Giriş!$H:$H,Bilgiler!I$3,Giriş!$C:$C,Bilgiler!$D30) -> 0 | J30: =SUMIFS(Giriş!$J:$J,Giriş!$H:$H,Bilgiler!J$3,Giriş!$C:$C,Bilgiler!$D30) -> 0 | K30: =SUMIFS(Giriş!$J:$J,Giriş!$H:$H,Bilgiler!K$3,Giriş!$C:$C,Bilgiler!$D30) -> 0 | L30: =G30+H30-I30-K30+J30 -> 0 | N30: =IFERROR(IF(N29+1>MAX(Giriş!L:L),"",N29+1),"") -> 4 | O30: =IF($N30="","",VLOOKUP($N30,Giriş!$L:$O,2,0)) -> Poşet-30 cm İpek | P30: =IF($N30="","",VLOOKUP($N30,Giriş!$L:$O,3,0)) -> 45231 | Q30: =IF($N30="","",VLOOKUP($N30,Giriş!$L:$O,4,0)) -> 45348 | R30: =IF(O30="","",IF(X30<=0,"",Q30-TODAY())) -> -234 | S30: =SUMIFS(G:G,D:D,O30,F:F,P30) -> 0 | T30: =SUMIFS(Giriş!$J:$J,Giriş!$H:$H,Bilgiler!T$3,Giriş!$C:$C,Bilgiler!$O30,Giriş!$E:$E,Bilgiler!$P30) -> 4000 | U30: =SUMIFS(Giriş!$J:$J,Giriş!$H:$H,Bilgiler!U$3,Giriş!$C:$C,Bilgiler!$O30,Giriş!$E:$E,Bilgiler!$P30) -> 0 | V30: =SUMIFS(Giriş!$J:$J,Giriş!$H:$H,Bilgiler!V$3,Giriş!$C:$C,Bilgiler!$O30,Giriş!$E:$E,Bilgiler!$P30) -> 0 | W30: =SUMIFS(Giriş!$J:$J,Giriş!$H:$H,Bilgiler!W$3,Giriş!$C:$C,Bilgiler!$O30,Giriş!$E:$E,Bilgiler!$P30) -> 0 | X30: =S30+T30+V30-W30-U30 -> 4000 | Y30: =IF(R30<0,IF(X30>0,"Raf Ömrü Geçti",""),IF(R30<=15,IF(X30>0,"Raf Ömrü Bitmek Üzere",""),"")) -> Raf Ömrü Geçti
D31: Poşet-20 cm Delight Sade | E31: 150.01.220 | F31: Mevcut | H31: =SUMIFS(Giriş!$J:$J,Giriş!$H:$H,Bilgiler!H$3,Giriş!$C:$C,Bilgiler!$D31) -> 0 | I31: =SUMIFS(Giriş!$J:$J,Giriş!$H:$H,Bilgiler!I$3,Giriş!$C:$C,Bilgiler!$D31) -> 0 | J31: =SUMIFS(Giriş!$J:$J,Giriş!$H:$H,Bilgiler!J$3,Giriş!$C:$C,Bilgiler!$D31) -> 0 | K31: =SUMIFS(Giriş!$J:$J,Giriş!$H:$H,Bilgiler!K$3,Giriş!$C:$C,Bilgiler!$D31) -> 0 | L31: =G31+H31-I31-K31+J31 -> 0 | N31: =IFERROR(IF(N30+1>MAX(Giriş!L:L),"",N30+1),"") -> 5 | O31: =IF($N31="","",VLOOKUP($N31,Giriş!$L:$O,2,0)) -> Poşet-20 cm B.sız Kilitli | P31: =IF($N31="","",VLOOKUP($N31,Giriş!$L:$O,3,0)) -> MAT008070 | Q31: =IF($N31="","",VLOOKUP($N31,Giriş!$L:$O,4,0)) -> 45472 | R31: =IF(O31="","",IF(X31<=0,"",Q31-TODAY())) -> -110 | S31: =SUMIFS(G:G,D:D,O31,F:F,P31) -> 0 | T31: =SUMIFS(Giriş!$J:$J,Giriş!$H:$H,Bilgiler!T$3,Giriş!$C:$C,Bilgiler!$O31,Giriş!$E:$E,Bilgiler!$P31) -> 104400 | U31: =SUMIFS(Giriş!$J:$J,Giriş!$H:$H,Bilgiler!U$3,Giriş!$C:$C,Bilgiler!$O31,Giriş!$E:$E,Bilgiler!$P31) -> 0 | V31: =SUMIFS(Giriş!$J:$J,Giriş!$H:$H,Bilgiler!V$3,Giriş!$C:$C,Bilgiler!$O31,Giriş!$E:$E,Bilgiler!$P31) -> 0 | W31: =SUMIFS(Giriş!$J:$J,Giriş!$H:$H,Bilgiler!W$3,Giriş!$C:$C,Bilgiler!$O31,Giriş!$E:$E,Bilgiler!$P31) -> 0 | X31: =S31+T31+V31-W31-U31 -> 104400 | Y31: =IF(R31<0,IF(X31>0,"Raf Ömrü Geçti",""),IF(R31<=15,IF(X31>0,"Raf Ömrü Bitmek Üzere",""),"")) -> Raf Ömrü Geçti
D32: Poşet-20 cm Delight Tam Buğday | E32: 150.01.224 | F32: Mevcut | H32: =SUMIFS(Giriş!$J:$J,Giriş!$H:$H,Bilgiler!H$3,Giriş!$C:$C,Bilgiler!$D32) -> 0 | I32: =SUMIFS(Giriş!$J:$J,Giriş!$H:$H,Bilgiler!I$3,Giriş!$C:$C,Bilgiler!$D32) -> 0 | J32: =SUMIFS(Giriş!$J:$J,Giriş!$H:$H,Bilgiler!J$3,Giriş!$C:$C,Bilgiler!$D32) -> 0 | K32: =SUMIFS(Giriş!$J:$J,Giriş!$H:$H,Bilgiler!K$3,Giriş!$C:$C,Bilgiler!$D32) -> 0 | L32: =G32+H32-I32-K32+J32 -> 0 | N32: =IFERROR(IF(N31+1>MAX(Giriş!L:L),"",N31+1),"") -> 6 | O32: =IF($N32="","",VLOOKUP($N32,Giriş!$L:$O,2,0)) -> Poşet-30 cm Mutlukal Tortillas Değişken | P32: =IF($N32="","",VLOOKUP($N32,Giriş!$L:$O,3,0)) -> 20230038 | Q32: =IF($N32="","",VLOOKUP($N32,Giriş!$L:$O,4,0)) -> 45483 | R32: =IF(O32="","",IF(X32<=0,"",Q32-TODAY())) -> -99 | S32: =SUMIFS(G:G,D:D,O32,F:F,P32) -> 0 | T32: =SUMIFS(Giriş!$J:$J,Giriş!$H:$H,Bilgiler!T$3,Giriş!$C:$C,Bilgiler!$O32,Giriş!$E:$E,Bilgiler!$P32) -> 68160 | U32: =SUMIFS(Giriş!$J:$J,Giriş!$H:$H,Bilgiler!U$3,Giriş!$C:$C,Bilgiler!$O32,Giriş!$E:$E,Bilgiler!$P32) -> 0 | V32: =SUMIFS(Giriş!$J:$J,Giriş!$H:$H,Bilgiler!V$3,Giriş!$C:$C,Bilgiler!$O32,Giriş!$E:$E,Bilgiler!$P32) -> 0 | W32: =SUMIFS(Giriş!$J:$J,Giriş!$H:$H,Bilgiler!W$3,Giriş!$C:$C,Bilgiler!$O32,Giriş!$E:$E,Bilgiler!$P32) -> 0 | X32: =S32+T32+V32-W32-U32 -> 68160 | Y32: =IF(R32<0,IF(X32>0,"Raf Ömrü Geçti",""),IF(R32<=15,IF(X32>0,"Raf Ömrü Bitmek Üzere",""),"")) -> Raf Ömrü Geçti
D33: Poşet-20 cm Din Marketing 810 Gr | E33: 150.01.338 | F33: Mevcut | H33: =SUMIFS(Giriş!$J:$J,Giriş!$H:$H,Bilgiler!H$3,Giriş!$C:$C,Bilgiler!$D33) -> 0 | I33: =SUMIFS(Giriş!$J:$J,Giriş!$H:$H,Bilgiler!I$3,Giriş!$C:$C,Bilgiler!$D33) -> 0 | J33: =SUMIFS(Giriş!$J:$J,Giriş!$H:$H,Bilgiler!J$3,Giriş!$C:$C,Bilgiler!$D33) -> 0 | K33: =SUMIFS(Giriş!$J:$J,Giriş!$H:$H,Bilgiler!K$3,Giriş!$C:$C,Bilgiler!$D33) -> 0 | L33: =G33+H33-I33-K33+J33 -> 0 | N33: =IFERROR(IF(N32+1>MAX(Giriş!L:L),"",N32+1),"") -> 7 | O33: =IF($N33="","",VLOOKUP($N33,Giriş!$L:$O,2,0)) -> Poşet--15 cm Mutlukal Tortillas Mavi Değişken | P33: =IF($N33="","",VLOOKUP($N33,Giriş!$L:$O,3,0)) -> 20230040 | Q33: =IF($N33="","",VLOOKUP($N33,Giriş!$L:$O,4,0)) -> 45492 | R33: =IF(O33="","",IF(X33<=0,"",Q33-TODAY())) -> -90 | S33: =SUMIFS(G:G,D:D,O33,F:F,P33) -> 0 | T33: =SUMIFS(Giriş!$J:$J,Giriş!$H:$H,Bilgiler!T$3,Giriş!$C:$C,Bilgiler!$O33,Giriş!$E:$E,Bilgiler!$P33) -> 182945 | U33: =SUMIFS(Giriş!$J:$J,Giriş!$H:$H,Bilgiler!U$3,Giriş!$C:$C,Bilgiler!$O33,Giriş!$E:$E,Bilgiler!$P33) -> 0 | V33: =SUMIFS(Giriş!$J:$J,Giriş!$H:$H,Bilgiler!V$3,Giriş!$C:$C,Bilgiler!$O33,Giriş!$E:$E,Bilgiler!$P33) -> 0 | W33: =SUMIFS(Giriş!$J:$J,Giriş!$H:$H,Bilgiler!W$3,Giriş!$C:$C,Bilgiler!$O33,Giriş!$E:$E,Bilgiler!$P33) -> 0 | X33: =S33+T33+V33-W33-U33 -> 182945 | Y33: =IF(R33<0,IF(X33>0,"Raf Ömrü Geçti",""),IF(R33<=15,IF(X33>0,"Raf Ömrü Bitmek Üzere",""),"")) -> Raf Ömrü Geçti
D34: Poşet-20 cm Eyal 540 gr ( İç ) | E34: 150.01.146 | F34: Mevcut | H34: =SUMIFS(Giriş!$J:$J,Giriş!$H:$H,Bilgiler!H$3,Giriş!$C:$C,Bilgiler!$D34) -> 77400 | I34: =SUMIFS(Giriş!$J:$J,Giriş!$H:$H,Bilgiler!I$3,Giriş!$C:$C,Bilgiler!$D34) -> 0 | J34: =SUMIFS(Giriş!$J:$J,Giriş!$H:$H,Bilgiler!J$3,Giriş!$C:$C,Bilgiler!$D34) -> 0 | K34: =SUMIFS(Giriş!$J:$J,Giriş!$H:$H,Bilgiler!K$3,Giriş!$C:$C,Bilgiler!$D34) -> 0 | L34: =G34+H34-I34-K34+J34 -> 77400 | N34: =IFERROR(IF(N33+1>MAX(Giriş!L:L),"",N33+1),"") -> 8 | O34: =IF($N34="","",VLOOKUP($N34,Giriş!$L:$O,2,0)) -> Poşet-25 cm Mutlukal Tortillas Kırmızı Değişken ( Beyaz Rusya ) | P34: =IF($N34="","",VLOOKUP($N34,Giriş!$L:$O,3,0)) -> 20230048 | Q34: =IF($N34="","",VLOOKUP($N34,Giriş!$L:$O,4,0)) -> 45483 | R34: =IF(O34="","",IF(X34<=0,"",Q34-TODAY())) -> -99 | S34: =SUMIFS(G:G,D:D,O34,F:F,P34) -> 0 | T34: =SUMIFS(Giriş!$J:$J,Giriş!$H:$H,Bilgiler!T$3,Giriş!$C:$C,Bilgiler!$O34,Giriş!$E:$E,Bilgiler!$P34) -> 89050 | U34: =SUMIFS(Giriş!$J:$J,Giriş!$H:$H,Bilgiler!U$3,Giriş!$C:$C,Bilgiler!$O34,Giriş!$E:$E,Bilgiler!$P34) -> 0 | V34: =SUMIFS(Giriş!$J:$J,Giriş!$H:$H,Bilgiler!V$3,Giriş!$C:$C,Bilgiler!$O34,Giriş!$E:$E,Bilgiler!$P34) -> 0 | W34: =SUMIFS(Giriş!$J:$J,Giriş!$H:$H,Bilgiler!W$3,Giriş!$C:$C,Bilgiler!$O34,Giriş!$E:$E,Bilgiler!$P34) -> 0 | X34: =S34+T34+V34-W34-U34 -> 89050 | Y34: =IF(R34<0,IF(X34>0,"Raf Ömrü Geçti",""),IF(R34<=15,IF(X34>0,"Raf Ömrü Bitmek Üzere",""),"")) -> Raf Ömrü Geçti
D35: Poşet-20 Cm Eyal Avel Tam Buğdaylı Tortilla | E35: 150.01.335 | F35: Mevcut | H35: =SUMIFS(Giriş!$J:$J,Giriş!$H:$H,Bilgiler!H$3,Giriş!$C:$C,Bilgiler!$D35) -> 0 | I35: =SUMIFS(Giriş!$J:$J,Giriş!$H:$H,Bilgiler!I$3,Giriş!$C:$C,Bilgiler!$D35) -> 0 | J35: =SUMIFS(Giriş!$J:$J,Giriş!$H:$H,Bilgiler!J$3,Giriş!$C:$C,Bilgiler!$D35) -> 0 | K35: =SUMIFS(Giriş!$J:$J,Giriş!$H:$H,Bilgiler!K$3,Giriş!$C:$C,Bilgiler!$D35) -> 0 | L35: =G35+H35-I35-K35+J35 -> 0 | N35: =IFERROR(IF(N34+1>MAX(Giriş!L:L),"",N34+1),"") -> 9 | O35: =IF($N35="","",VLOOKUP($N35,Giriş!$L:$O,2,0)) -> Poşet-25 cm Mutlukal Tortillas Tam Buğday | P35: =IF($N35="","",VLOOKUP($N35,Giriş!$L:$O,3,0)) -> 20230042 | Q35: =IF($N35="","",VLOOKUP($N35,Giriş!$L:$O,4,0)) -> 45483 | R35: =IF(O35="","",IF(X35<=0,"",Q35-TODAY())) -> -99 | S35: =SUMIFS(G:G,D:D,O35,F:F,P35) -> 0 | T35: =SUMIFS(Giriş!$J:$J,Giriş!$H:$H,Bilgiler!T$3,Giriş!$C:$C,Bilgiler!$O35,Giriş!$E:$E,Bilgiler!$P35) -> 86730 | U35: =SUMIFS(Giriş!$J:$J,Giriş!$H:$H,Bilgiler!U$3,Giriş!$C:$C,Bilgiler!$O35,Giriş!$E:$E,Bilgiler!$P35) -> 0 | V35: =SUMIFS(Giriş!$J:$J,Giriş!$H:$H,Bilgiler!V$3,Giriş!$C:$C,Bilgiler!$O35,Giriş!$E:$E,Bilgiler!$P35) -> 0 | W35: =SUMIFS(Giriş!$J:$J,Giriş!$H:$H,Bilgiler!W$3,Giriş!$C:$C,Bilgiler!$O35,Giriş!$E:$E,Bilgiler!$P35) -> 0 | X35: =S35+T35+V35-W35-U35 -> 86730 | Y35: =IF(R35<0,IF(X35>0,"Raf Ömrü Geçti",""),IF(R35<=15,IF(X35>0,"Raf Ömrü Bitmek Üzere",""),"")) -> Raf Ömrü Geçti
D36: Poşet-20 Cm Eyal Avel Tortilla | E36: 150.01.251 | F36: Mevcut | H36: =SUMIFS(Giriş!$J:$J,Giriş!$H:$H,Bilgiler!H$3,Giriş!$C:$C,Bilgiler!$D36) -> 0 | I36: =SUMIFS(Giriş!$J:$J,Giriş!$H:$H,Bilgiler!I$3,Giriş!$C:$C,Bilgiler!$D36) -> 0 | J36: =SUMIFS(Giriş!$J:$J,Giriş!$H:$H,Bilgiler!J$3,Giriş!$C:$C,Bilgiler!$D36) -> 0 | K36: =SUMIFS(Giriş!$J:$J,Giriş!$H:$H,Bilgiler!K$3,Giriş!$C:$C,Bilgiler!$D36) -> 0 | L36: =G36+H36-I36-K36+J36 -> 0 | N36: =IFERROR(IF(N35+1>MAX(Giriş!L:L),"",N35+1),"") -> 10 | O36: =IF($N36="","",VLOOKUP($N36,Giriş!$L:$O,2,0)) -> Poşet-25 cm B.sız Kilitli | P36: =IF($N36="","",VLOOKUP($N36,Giriş!$L:$O,3,0)) -> 20230050 | Q36: =IF($N36="","",VLOOKUP($N36,Giriş!$L:$O,4,0)) -> 45483 | R36: =IF(O36="","",IF(X36<=0,"",Q36-TODAY())) -> -99 | S36: =SUMIFS(G:G,D:D,O36,F:F,P36) -> 0 | T36: =SUMIFS(Giriş!$J:$J,Giriş!$H:$H,Bilgiler!T$3,Giriş!$C:$C,Bilgiler!$O36,Giriş!$E:$E,Bilgiler!$P36) -> 88400 | U36: =SUMIFS(Giriş!$J:$J,Giriş!$H:$H,Bilgiler!U$3,Giriş!$C:$C,Bilgiler!$O36,Giriş!$E:$E,Bilgiler!$P36) -> 0 | V36: =SUMIFS(Giriş!$J:$J,Giriş!$H:$H,Bilgiler!V$3,Giriş!$C:$C,Bilgiler!$O36,Giriş!$E:$E,Bilgiler!$P36) -> 0 | W36: =SUMIFS(Giriş!$J:$J,Giriş!$H:$H,Bilgiler!W$3,Giriş!$C:$C,Bilgiler!$O36,Giriş!$E:$E,Bilgiler!$P36) -> 0 | X36: =S36+T36+V36-W36-U36 -> 88400 | Y36: =IF(R36<0,IF(X36>0,"Raf Ömrü Geçti",""),IF(R36<=15,IF(X36>0,"Raf Ömrü Bitmek Üzere",""),"")) -> Raf Ömrü Geçti
D37: Poşet-20 cm Eyal Durum 540 gr ( İç ) Tam Buğday | E37: 150.01.310 | F37: Mevcut | H37: =SUMIFS(Giriş!$J:$J,Giriş!$H:$H,Bilgiler!H$3,Giriş!$C:$C,Bilgiler!$D37) -> 77400 | I37: =SUMIFS(Giriş!$J:$J,Giriş!$H:$H,Bilgiler!I$3,Giriş!$C:$C,Bilgiler!$D37) -> 0 | J37: =SUMIFS(Giriş!$J:$J,Giriş!$H:$H,Bilgiler!J$3,Giriş!$C:$C,Bilgiler!$D37) -> 0 | K37: =SUMIFS(Giriş!$J:$J,Giriş!$H:$H,Bilgiler!K$3,Giriş!$C:$C,Bilgiler!$D37) -> 0 | L37: =G37+H37-I37-K37+J37 -> 77400 | N37: =IFERROR(IF(N36+1>MAX(Giriş!L:L),"",N36+1),"") -> 11 | O37: =IF($N37="","",VLOOKUP($N37,Giriş!$L:$O,2,0)) -> Poşet-25 cm Tortillove Değişken | P37: =IF($N37="","",VLOOKUP($N37,Giriş!$L:$O,3,0)) -> MAT008095 | Q37: =IF($N37="","",VLOOKUP($N37,Giriş!$L:$O,4,0)) -> 45491 | R37: =IF(O37="","",IF(X37<=0,"",Q37-TODAY())) -> -91 | S37: =SUMIFS(G:G,D:D,O37,F:F,P37) -> 0 | T37: =SUMIFS(Giriş!$J:$J,Giriş!$H:$H,Bilgiler!T$3,Giriş!$C:$C,Bilgiler!$O37,Giriş!$E:$E,Bilgiler!$P37) -> 79800 | U37: =SUMIFS(Giriş!$J:$J,Giriş!$H:$H,Bilgiler!U$3,Giriş!$C:$C,Bilgiler!$O37,Giriş!$E:$E,Bilgiler!$P37) -> 0 | V37: =SUMIFS(Giriş!$J:$J,Giriş!$H:$H,Bilgiler!V$3,Giriş!$C:$C,Bilgiler!$O37,Giriş!$E:$E,Bilgiler!$P37) -> 0 | W37: =SUMIFS(Giriş!$J:$J,Giriş!$H:$H,Bilgiler!W$3,Giriş!$C:$C,Bilgiler!$O37,Giriş!$E:$E,Bilgiler!$P37) -> 0 | X37: =S37+T37+V37-W37-U37 -> 79800 | Y37: =IF(R37<0,IF(X37>0,"Raf Ömrü Geçti",""),IF(R37<=15,IF(X37>0,"Raf Ömrü Bitmek Üzere",""),"")) -> Raf Ömrü Geçti
D38: Poşet-20 cm Happylla Değişken | E38: 150.01.038 | F38: Mevcut | H38: =SUMIFS(Giriş!$J:$J,Giriş!$H:$H,Bilgiler!H$3,Giriş!$C:$C,Bilgiler!$D38) -> 0 | I38: =SUMIFS(Giriş!$J:$J,Giriş!$H:$H,Bilgiler!I$3,Giriş!$C:$C,Bilgiler!$D38) -> 0 | J38: =SUMIFS(Giriş!$J:$J,Giriş!$H:$H,Bilgiler!J$3,Giriş!$C:$C,Bilgiler!$D38) -> 0 | K38: =SUMIFS(Giriş!$J:$J,Giriş!$H:$H,Bilgiler!K$3,Giriş!$C:$C,Bilgiler!$D38) -> 0 | L38: =G38+H38-I38-K38+J38 -> 0 | N38: =IFERROR(IF(N37+1>MAX(Giriş!L:L),"",N37+1),"") -> 12 | O38: =IF($N38="","",VLOOKUP($N38,Giriş!$L:$O,2,0)) -> Poşet-25 cm Wıllı Food 840 gr | P38: =IF($N38="","",VLOOKUP($N38,Giriş!$L:$O,3,0)) -> MAT008124 | Q38: =IF($N38="","",VLOOKUP($N38,Giriş!$L:$O,4,0)) -> 45498 | R38: =IF(O38="","",IF(X38<=0,"",Q38-TODAY())) -> -84 | S38: =SUMIFS(G:G,D:D,O38,F:F,P38) -> 0 | T38: =SUMIFS(Giriş!$J:$J,Giriş!$H:$H,Bilgiler!T$3,Giriş!$C:$C,Bilgiler!$O38,Giriş!$E:$E,Bilgiler!$P38) -> 77300 | U38: =SUMIFS(Giriş!$J:$J,Giriş!$H:$H,Bilgiler!U$3,Giriş!$C:$C,Bilgiler!$O38,Giriş!$E:$E,Bilgiler!$P38) -> 0 | V38: =SUMIFS(Giriş!$J:$J,Giriş!$H:$H,Bilgiler!V$3,Giriş!$C:$C,Bilgiler!$O38,Giriş!$E:$E,Bilgiler!$P38) -> 0 | W38: =SUMIFS(Giriş!$J:$J,Giriş!$H:$H,Bilgiler!W$3,Giriş!$C:$C,Bilgiler!$O38,Giriş!$E:$E,Bilgiler!$P38) -> 0 | X38: =S38+T38+V38-W38-U38 -> 77300 | Y38: =IF(R38<0,IF(X38>0,"Raf Ömrü Geçti",""),IF(R38<=15,IF(X38>0,"Raf Ömrü Bitmek Üzere",""),"")) -> Raf Ömrü Geçti
... D110: Poşet-30 cm Diyos 900 gr. | E110: 150.01.293 | F110: Mevcut | H110: =SUMIFS(Giriş!$J:$J,Giriş!$H:$H,Bilgiler!H$3,Giriş!$C:$C,Bilgiler!$D110) -> 0 | I110: =SUMIFS(Giriş!$J:$J,Giriş!$H:$H,Bilgiler!I$3,Giriş!$C:$C,Bilgiler!$D110) -> 0 | J110: =SUMIFS(Giriş!$J:$J,Giriş!$H:$H,Bilgiler!J$3,Giriş!$C:$C,Bilgiler!$D110) -> 0 | K110: =SUMIFS(Giriş!$J:$J,Giriş!$H:$H,Bilgiler!K$3,Giriş!$C:$C,Bilgiler!$D110) -> 0 | L110: =G110+H110-I110-K110+J110 -> 0 | N110: =IFERROR(IF(N109+1>MAX(Giriş!L:L),"",N109+1),"") -> 84 | O110: =IF($N110="","",VLOOKUP($N110,Giriş!$L:$O,2,0)) -> 30CM BUENA COMIDA | P110: =IF($N110="","",VLOOKUP($N110,Giriş!$L:$O,3,0)) -> MAT008558 | Q110: =IF($N110="","",VLOOKUP($N110,Giriş!$L:$O,4,0)) -> 45469 | R110: =IF(O110="","",IF(X110<=0,"",Q110-TODAY())) -> -113 | S110: =SUMIFS(G:G,D:D,O110,F:F,P110) -> 0 | T110: =SUMIFS(Giriş!$J:$J,Giriş!$H:$H,Bilgiler!T$3,Giriş!$C:$C,Bilgiler!$O110,Giriş!$E:$E,Bilgiler!$P110) -> 125000 | U110: =SUMIFS(Giriş!$J:$J,Giriş!$H:$H,Bilgiler!U$3,Giriş!$C:$C,Bilgiler!$O110,Giriş!$E:$E,Bilgiler!$P110) -> 0 | V110: =SUMIFS(Giriş!$J:$J,Giriş!$H:$H,Bilgiler!V$3,Giriş!$C:$C,Bilgiler!$O110,Giriş!$E:$E,Bilgiler!$P110) -> 0 | W110: =SUMIFS(Giriş!$J:$J,Giriş!$H:$H,Bilgiler!W$3,Giriş!$C:$C,Bilgiler!$O110,Giriş!$E:$E,Bilgiler!$P110) -> 0 | X110: =S110+T110+V110-W110-U110 -> 125000 | Y110: =IF(R110<0,IF(X110>0,"Raf Ömrü Geçti",""),IF(R110<=15,IF(X110>0,"Raf Ömrü Bitmek Üzere",""),"")) -> Raf Ömrü Geçti
D111: Poşet-30 cm Eyal Durum 1620 gr | E111: 150.01.312 | F111: Mevcut | H111: =SUMIFS(Giriş!$J:$J,Giriş!$H:$H,Bilgiler!H$3,Giriş!$C:$C,Bilgiler!$D111) -> 0 | I111: =SUMIFS(Giriş!$J:$J,Giriş!$H:$H,Bilgiler!I$3,Giriş!$C:$C,Bilgiler!$D111) -> 0 | J111: =SUMIFS(Giriş!$J:$J,Giriş!$H:$H,Bilgiler!J$3,Giriş!$C:$C,Bilgiler!$D111) -> 0 | K111: =SUMIFS(Giriş!$J:$J,Giriş!$H:$H,Bilgiler!K$3,Giriş!$C:$C,Bilgiler!$D111) -> 0 | L111: =G111+H111-I111-K111+J111 -> 0
D112: Poşet-30 cm Farina | E112: 150.01.205 | F112: Mevcut | H112: =SUMIFS(Giriş!$J:$J,Giriş!$H:$H,Bilgiler!H$3,Giriş!$C:$C,Bilgiler!$D112) -> 0 | I112: =SUMIFS(Giriş!$J:$J,Giriş!$H:$H,Bilgiler!I$3,Giriş!$C:$C,Bilgiler!$D112) -> 0 | J112: =SUMIFS(Giriş!$J:$J,Giriş!$H:$H,Bilgiler!J$3,Giriş!$C:$C,Bilgiler!$D112) -> 0 | K112: =SUMIFS(Giriş!$J:$J,Giriş!$H:$H,Bilgiler!K$3,Giriş!$C:$C,Bilgiler!$D112) -> 0 | L112: =G112+H112-I112-K112+J112 -> 0
...

Sheet Giriş
B2: Tarih | C2: Ürün | D2: Stok Kodu | E2: Parti Numarası | F2: Son Kullanma Tarihi | G2: Açıklama | H2: Aksiyon | I2: Tedarikçi/Bölüm | J2: Miktar (kg) | K2: Birleştir | L2: Parti Kod | M2: Ürün | N2: Parti Numarası | O2: Son Kullanma Tarihi
B3: 45222 | C3: Poşet-25 cm Mutlukal Tortillas 260 Gr ( Rusca ) | D3: =IF(C3="","",VLOOKUP(C3,Bilgiler!D:E,2,0)) -> 150.01.295 | E3: MAT007938 | F3: 45401 | G3: Uygun | H3: Tedarikçiden Satın Alım | I3: Ege Plastik Ambalaj San.ve Tic.A.Ş. | J3: 203000 | K3: =IF(C3="","",CONCATENATE(C3,E3)) -> Poşet-25 cm Mutlukal Tortillas 260 Gr ( Rusca )MAT007938 | L3: =IF(K3="","",IFERROR(VLOOKUP(K3,$K$2:L2,2,0),MAX($L$2:L2)+1)) -> 1 | M3: =IF(K3="","",C3) -> Poşet-25 cm Mutlukal Tortillas 260 Gr ( Rusca ) | N3: =IF(K3="","",E3) -> MAT007938 | O3: =IF(K3="","",F3) -> 45401
B4: 45222 | C4: Poşet-25 cm Mutlukal Tortillas Mavi Değişken | D4: =IF(C4="","",VLOOKUP(C4,Bilgiler!D:E,2,0)) -> 150.01.307 | E4: MAT008069 | F4: 45401 | G4: Uygun | H4: Tedarikçiden Satın Alım | I4: Ege Plastik Ambalaj San.ve Tic.A.Ş. | J4: 16800 | K4: =IF(C4="","",CONCATENATE(C4,E4)) -> Poşet-25 cm Mutlukal Tortillas Mavi DeğişkenMAT008069 | L4: =IF(K4="","",IFERROR(VLOOKUP(K4,$K$2:L3,2,0),MAX($L$2:L3)+1)) -> 2 | M4: =IF(K4="","",C4) -> Poşet-25 cm Mutlukal Tortillas Mavi Değişken | N4: =IF(K4="","",E4) -> MAT008069 | O4: =IF(K4="","",F4) -> 45401
B5: 45224 | C5: Poşet-30 cm Sofias | D5: =IF(C5="","",VLOOKUP(C5,Bilgiler!D:E,2,0)) -> 150.01.277 | E5: MAT008034 | F5: 45407 | G5: Uygun | H5: Tedarikçiden Satın Alım | I5: Ege Plastik Ambalaj San.ve Tic.A.Ş. | J5: 38400 | K5: =IF(C5="","",CONCATENATE(C5,E5)) -> Poşet-30 cm SofiasMAT008034 | L5: =IF(K5="","",IFERROR(VLOOKUP(K5,$K$2:L4,2,0),MAX($L$2:L4)+1)) -> 3 | M5: =IF(K5="","",C5) -> Poşet-30 cm Sofias | N5: =IF(K5="","",E5) -> MAT008034 | O5: =IF(K5="","",F5) -> 45407
B6: 45231 | C6: Poşet-30 cm İpek | D6: =IF(C6="","",VLOOKUP(C6,Bilgiler!D:E,2,0)) -> İpek | E6: 45231 | F6: 45348 | G6: Uygun | H6: Tedarikçiden Satın Alım | I6: Gaziantepli Habeş Seyidoğlu Baklavaları ve Uluslararası Nakliyat Sanayi Ticaret Ltd.Şti. | J6: 4000 | K6: =IF(C6="","",CONCATENATE(C6,E6)) -> Poşet-30 cm İpek45231 | L6: =IF(K6="","",IFERROR(VLOOKUP(K6,$K$2:L5,2,0),MAX($L$2:L5)+1)) -> 4 | M6: =IF(K6="","",C6) -> Poşet-30 cm İpek | N6: =IF(K6="","",E6) -> 45231 | O6: =IF(K6="","",F6) -> 45348
B7: 45237 | C7: Poşet-20 cm B.sız Kilitli | D7: =IF(C7="","",VLOOKUP(C7,Bilgiler!D:E,2,0)) -> 150.01.037 | E7: MAT008070 | F7: 45472 | G7: Uygun | H7: Tedarikçiden Satın Alım | I7: Ege Plastik Ambalaj San.ve Tic.A.Ş. | J7: 104400 | K7: =IF(C7="","",CONCATENATE(C7,E7)) -> Poşet-20 cm B.sız KilitliMAT008070 | L7: =IF(K7="","",IFERROR(VLOOKUP(K7,$K$2:L6,2,0),MAX($L$2:L6)+1)) -> 5 | M7: =IF(K7="","",C7) -> Poşet-20 cm B.sız Kilitli | N7: =IF(K7="","",E7) -> MAT008070 | O7: =IF(K7="","",F7) -> 45472
B8: 45237 | C8: Poşet-25 cm Mutlukal Tortillas Mavi Değişken | D8: =IF(C8="","",VLOOKUP(C8,Bilgiler!D:E,2,0)) -> 150.01.307 | E8: MAT008069 | F8: 45473 | G8: Uygun | H8: Tedarikçiden Satın Alım | I8: Ege Plastik Ambalaj San.ve Tic.A.Ş. | J8: 65800 | K8: =IF(C8="","",CONCATENATE(C8,E8)) -> Poşet-25 cm Mutlukal Tortillas Mavi DeğişkenMAT008069 | L8: =IF(K8="","",IFERROR(VLOOKUP(K8,$K$2:L7,2,0),MAX($L$2:L7)+1)) -> 2 | M8: =IF(K8="","",C8) -> Poşet-25 cm Mutlukal Tortillas Mavi Değişken | N8: =IF(K8="","",E8) -> MAT008069 | O8: =IF(K8="","",F8) -> 45473
B9: 45237 | C9: Poşet-25 cm Mutlukal Tortillas 260 Gr ( Rusca ) | D9: =IF(C9="","",VLOOKUP(C9,Bilgiler!D:E,2,0)) -> 150.01.295 | E9: MAT007938 | F9: 45479 | G9: Uygun | H9: Tedarikçiden Satın Alım | I9: Ege Plastik Ambalaj San.ve Tic.A.Ş. | J9: 145600 | K9: =IF(C9="","",CONCATENATE(C9,E9)) -> Poşet-25 cm Mutlukal Tortillas 260 Gr ( Rusca )MAT007938 | L9: =IF(K9="","",IFERROR(VLOOKUP(K9,$K$2:L8,2,0),MAX($L$2:L8)+1)) -> 1 | M9: =IF(K9="","",C9) -> Poşet-25 cm Mutlukal Tortillas 260 Gr ( Rusca ) | N9: =IF(K9="","",E9) -> MAT007938 | O9: =IF(K9="","",F9) -> 45479
B10: 45239 | C10: Poşet-25 cm Mutlukal Tortillas 260 Gr ( Rusca ) | D10: =IF(C10="","",VLOOKUP(C10,Bilgiler!D:E,2,0)) -> 150.01.295 | E10: MAT007938 | F10: 45482 | G10: Uygun | H10: Tedarikçiden Satın Alım | I10: Ege Plastik Ambalaj San.ve Tic.A.Ş. | J10: 99400 | K10: =IF(C10="","",CONCATENATE(C10,E10)) -> Poşet-25 cm Mutlukal Tortillas 260 Gr ( Rusca )MAT007938 | L10: =IF(K10="","",IFERROR(VLOOKUP(K10,$K$2:L9,2,0),MAX($L$2:L9)+1)) -> 1 | M10: =IF(K10="","",C10) -> Poşet-25 cm Mutlukal Tortillas 260 Gr ( Rusca ) | N10: =IF(K10="","",E10) -> MAT007938 | O10: =IF(K10="","",F10) -> 45482
B11: 45240 | C11: Poşet-30 cm Mutlukal Tortillas Değişken | D11: =IF(C11="","",VLOOKUP(C11,Bilgiler!D:E,2,0)) -> 150.01.284 | E11: 20230038 | F11: 45483 | G11: Uygun | H11: Tedarikçiden Satın Alım | I11: Enpak Matbaa ve Ambalaj Sanayi ve Tic.A.Ş. ( Usd ) | J11: 68160 | K11: =IF(C11="","",CONCATENATE(C11,E11)) -> Poşet-30 cm Mutlukal Tortillas Değişken20230038 | L11: =IF(K11="","",IFERROR(VLOOKUP(K11,$K$2:L10,2,0),MAX($L$2:L10)+1)) -> 6 | M11: =IF(K11="","",C11) -> Poşet-30 cm Mutlukal Tortillas Değişken | N11: =IF(K11="","",E11) -> 20230038 | O11: =IF(K11="","",F11) -> 45483
B12: 45240 | C12: Poşet--15 cm Mutlukal Tortillas Mavi Değişken | D12: =IF(C12="","",VLOOKUP(C12,Bilgiler!D:E,2,0)) -> 150.01.305 | E12: 20230040 | F12: 45492 | G12: Uygun | H12: Tedarikçiden Satın Alım | I12: Enpak Matbaa ve Ambalaj Sanayi ve Tic.A.Ş. ( Usd ) | J12: 182945 | K12: =IF(C12="","",CONCATENATE(C12,E12)) -> Poşet--15 cm Mutlukal Tortillas Mavi Değişken20230040 | L12: =IF(K12="","",IFERROR(VLOOKUP(K12,$K$2:L11,2,0),MAX($L$2:L11)+1)) -> 7 | M12: =IF(K12="","",C12) -> Poşet--15 cm Mutlukal Tortillas Mavi Değişken | N12: =IF(K12="","",E12) -> 20230040 | O12: =IF(K12="","",F12) -> 45492
B13: 45240 | C13: Poşet-25 cm Mutlukal Tortillas Kırmızı Değişken ( Beyaz Rusya ) | D13: =IF(C13="","",VLOOKUP(C13,Bilgiler!D:E,2,0)) -> 150.01.292 | E13: 20230048 | F13: 45483 | G13: Uygun | H13: Tedarikçiden Satın Alım | I13: Enpak Matbaa ve Ambalaj Sanayi ve Tic.A.Ş. ( Usd ) | J13: 89050 | K13: =IF(C13="","",CONCATENATE(C13,E13)) -> Poşet-25 cm Mutlukal Tortillas Kırmızı Değişken ( Beyaz Rusya )20230048 | L13: =IF(K13="","",IFERROR(VLOOKUP(K13,$K$2:L12,2,0),MAX($L$2:L12)+1)) -> 8 | M13: =IF(K13="","",C13) -> Poşet-25 cm Mutlukal Tortillas Kırmızı Değişken ( Beyaz Rusya ) | N13: =IF(K13="","",E13) -> 20230048 | O13: =IF(K13="","",F13) -> 45483
B14: 45240 | C14: Poşet-25 cm Mutlukal Tortillas Tam Buğday | D14: =IF(C14="","",VLOOKUP(C14,Bilgiler!D:E,2,0)) -> 150.01.315 | E14: 20230042 | F14: 45483 | G14: Uygun | H14: Tedarikçiden Satın Alım | I14: Enpak Matbaa ve Ambalaj Sanayi ve Tic.A.Ş. ( Usd ) | J14: 86730 | K14: =IF(C14="","",CONCATENATE(C14,E14)) -> Poşet-25 cm Mutlukal Tortillas Tam Buğday20230042 | L14: =IF(K14="","",IFERROR(VLOOKUP(K14,$K$2:L13,2,0),MAX($L$2:L13)+1)) -> 9 | M14: =IF(K14="","",C14) -> Poşet-25 cm Mutlukal Tortillas Tam Buğday | N14: =IF(K14="","",E14) -> 20230042 | O14: =IF(K14="","",F14) -> 45483
B15: 45240 | C15: Poşet-25 cm B.sız Kilitli | D15: =IF(C15="","",VLOOKUP(C15,Bilgiler!D:E,2,0)) -> 150.01.044 | E15: 20230050 | F15: 45483 | G15: Uygun | H15: Tedarikçiden Satın Alım | I15: Enpak Matbaa ve Ambalaj Sanayi ve Tic.A.Ş. ( Usd ) | J15: 88400 | K15: =IF(C15="","",CONCATENATE(C15,E15)) -> Poşet-25 cm B.sız Kilitli20230050 | L15: =IF(K15="","",IFERROR(VLOOKUP(K15,$K$2:L14,2,0),MAX($L$2:L14)+1)) -> 10 | M15: =IF(K15="","",C15) -> Poşet-25 cm B.sız Kilitli | N15: =IF(K15="","",E15) -> 20230050 | O15: =IF(K15="","",F15) -> 45483
